//Schematic to java Structure by jajo_11 | inspired by "MITHION'S .SCHEMATIC TO JAVA CONVERTINGTOOL"

package com.hbm_m.world.dungeon;

import java.util.Arrays;
import java.util.List;
import java.util.Random;

import com.hbm_m.config.GeneralConfig;
import com.hbm_m.itempool.ItemPool;
import com.hbm_m.main.MainRegistry;
import com.hbm_m.itempool.ItemPoolsComponent;
import com.hbm_m.itempool.ItemPoolsLegacy;
import com.hbm_m.itempool.ItemPoolsSingle;
import com.hbm_m.itempool.ItemPoolsPile;
import com.hbm_m.world.gen.legacy.L;
import com.hbm_m.world.gen.legacy.LB;
import com.hbm_m.world.gen.legacy.LMaterial;
import com.hbm_m.world.gen.legacy.MB;
import com.hbm_m.world.gen.legacy.MetaBlock;
import com.hbm_m.world.generator.DungeonToolbox;
import com.hbm_m.util.Vec3NT;
import com.hbm_m.world.gen.legacy.VB;

import net.minecraft.world.Container;
import net.minecraft.world.level.LevelAccessor;





/**
 * 1:1 {@code com.hbm.world.dungeon.DesertAtom001} (Original-Weltgen-Klasse, zeilengetreu auf die Port-Hilfen {@code L}/{@code MB}/{@code VB} umgesetzt).
 */
public class DesertAtom001 {
	LB Block2 = MB.yellow_barrel;
	LB Block3 = MB.reinforced_sand;
	LB Block4 = MB.crashed_balefire;
	LB Block7 = MB.deco_tungsten;
	
	protected LB[] GetValidSpawnBlocks()
	{
		return new LB[]
		{
			VB.grass,
			VB.dirt,
			VB.sand,
			VB.sandstone,
			VB.stone,
			VB.hardened_clay,
			VB.stained_hardened_clay,
		};
	}

	public boolean LocationIsValidSpawn(LevelAccessor world, int x, int y, int z)
 {

		LB checkBlock = L.getBlock(world, x, y - 1, z);
		LB blockAbove = L.getBlock(world, x, y , z);
		LB blockBelow = L.getBlock(world, x, y - 2, z);

		for (LB i : GetValidSpawnBlocks())
		{
			if (blockAbove != VB.air)
			{
				return false;
			}
			if (checkBlock == i)
			{
				return true;
			}
			else if (checkBlock == VB.snow_layer && blockBelow == i)
			{
				return true;
			}
			else if (checkBlock.getMaterial() == LMaterial.plants && blockBelow == i)
			{
				return true;
			}
		}
		return false;
	}

		public boolean generate(LevelAccessor world, Random rand, int x, int y, int z)
	{
		int i = rand.nextInt(1);

		if(i == 0)
		{
		    generate_r0(world, rand, x, y, z);
		}

       return true;

	}

	public boolean generate_r0(LevelAccessor world, Random rand, int x, int y, int z)
	{
		if(!LocationIsValidSpawn(world, x + 20, y, z + 16))
		{
			return false;
		}

		L.setBlock(world, x + 6, y + -5, z + 9, L.getRandomConcrete(), 0, 3);
		L.setBlock(world, x + 7, y + -5, z + 9, L.getRandomConcrete(), 0, 3);
		L.setBlock(world, x + 8, y + -5, z + 9, L.getRandomConcrete(), 0, 3);
		L.setBlock(world, x + 9, y + -5, z + 9, L.getRandomConcrete(), 0, 3);
		L.setBlock(world, x + 10, y + -5, z + 9, L.getRandomConcrete(), 0, 3);
		L.setBlock(world, x + 5, y + -5, z + 10, L.getRandomConcrete(), 0, 3);
		L.setBlock(world, x + 6, y + -5, z + 10, L.getRandomConcrete(), 0, 3);
		L.setBlock(world, x + 7, y + -5, z + 10, L.getRandomConcrete(), 0, 3);
		L.setBlock(world, x + 8, y + -5, z + 10, L.getRandomConcrete(), 0, 3);
		L.setBlock(world, x + 9, y + -5, z + 10, L.getRandomConcrete(), 0, 3);
		L.setBlock(world, x + 10, y + -5, z + 10, L.getRandomConcrete(), 0, 3);
		L.setBlock(world, x + 11, y + -5, z + 10, L.getRandomConcrete(), 0, 3);
		L.setBlock(world, x + 5, y + -5, z + 11, L.getRandomConcrete(), 0, 3);
		L.setBlock(world, x + 6, y + -5, z + 11, L.getRandomConcrete(), 0, 3);
		L.setBlock(world, x + 7, y + -5, z + 11, L.getRandomConcrete(), 0, 3);
		L.setBlock(world, x + 8, y + -5, z + 11, L.getRandomConcrete(), 0, 3);
		L.setBlock(world, x + 9, y + -5, z + 11, L.getRandomConcrete(), 0, 3);
		L.setBlock(world, x + 10, y + -5, z + 11, L.getRandomConcrete(), 0, 3);
		L.setBlock(world, x + 11, y + -5, z + 11, L.getRandomConcrete(), 0, 3);
		L.setBlock(world, x + 5, y + -5, z + 12, L.getRandomConcrete(), 0, 3);
		L.setBlock(world, x + 6, y + -5, z + 12, L.getRandomConcrete(), 0, 3);
		L.setBlock(world, x + 7, y + -5, z + 12, L.getRandomConcrete(), 0, 3);
		L.setBlock(world, x + 8, y + -5, z + 12, L.getRandomConcrete(), 0, 3);
		L.setBlock(world, x + 9, y + -5, z + 12, L.getRandomConcrete(), 0, 3);
		L.setBlock(world, x + 10, y + -5, z + 12, L.getRandomConcrete(), 0, 3);
		L.setBlock(world, x + 11, y + -5, z + 12, L.getRandomConcrete(), 0, 3);
		L.setBlock(world, x + 5, y + -5, z + 13, L.getRandomConcrete(), 0, 3);
		L.setBlock(world, x + 6, y + -5, z + 13, L.getRandomConcrete(), 0, 3);
		L.setBlock(world, x + 7, y + -5, z + 13, L.getRandomConcrete(), 0, 3);
		L.setBlock(world, x + 8, y + -5, z + 13, L.getRandomConcrete(), 0, 3);
		L.setBlock(world, x + 9, y + -5, z + 13, L.getRandomConcrete(), 0, 3);
		L.setBlock(world, x + 10, y + -5, z + 13, L.getRandomConcrete(), 0, 3);
		L.setBlock(world, x + 11, y + -5, z + 13, L.getRandomConcrete(), 0, 3);
		L.setBlock(world, x + 5, y + -5, z + 14, L.getRandomConcrete(), 0, 3);
		L.setBlock(world, x + 6, y + -5, z + 14, L.getRandomConcrete(), 0, 3);
		L.setBlock(world, x + 7, y + -5, z + 14, L.getRandomConcrete(), 0, 3);
		L.setBlock(world, x + 8, y + -5, z + 14, L.getRandomConcrete(), 0, 3);
		L.setBlock(world, x + 9, y + -5, z + 14, L.getRandomConcrete(), 0, 3);
		L.setBlock(world, x + 10, y + -5, z + 14, L.getRandomConcrete(), 0, 3);
		L.setBlock(world, x + 11, y + -5, z + 14, L.getRandomConcrete(), 0, 3);
		L.setBlock(world, x + 6, y + -5, z + 15, L.getRandomConcrete(), 0, 3);
		L.setBlock(world, x + 7, y + -5, z + 15, L.getRandomConcrete(), 0, 3);
		L.setBlock(world, x + 8, y + -5, z + 15, L.getRandomConcrete(), 0, 3);
		L.setBlock(world, x + 9, y + -5, z + 15, L.getRandomConcrete(), 0, 3);
		L.setBlock(world, x + 10, y + -5, z + 15, L.getRandomConcrete(), 0, 3);
		L.setBlock(world, x + 7, y + -5, z + 16, L.getRandomConcrete(), 0, 3);
		L.setBlock(world, x + 8, y + -5, z + 16, L.getRandomConcrete(), 0, 3);
		L.setBlock(world, x + 9, y + -5, z + 16, L.getRandomConcrete(), 0, 3);
		L.setBlock(world, x + 7, y + -5, z + 17, L.getRandomConcrete(), 0, 3);
		L.setBlock(world, x + 8, y + -5, z + 17, L.getRandomConcrete(), 0, 3);
		L.setBlock(world, x + 9, y + -5, z + 17, L.getRandomConcrete(), 0, 3);
		L.setBlock(world, x + 7, y + -5, z + 18, L.getRandomConcrete(), 0, 3);
		L.setBlock(world, x + 8, y + -5, z + 18, L.getRandomConcrete(), 0, 3);
		L.setBlock(world, x + 9, y + -5, z + 18, L.getRandomConcrete(), 0, 3);
		L.setBlock(world, x + 7, y + -5, z + 19, L.getRandomConcrete(), 0, 3);
		L.setBlock(world, x + 8, y + -5, z + 19, L.getRandomConcrete(), 0, 3);
		L.setBlock(world, x + 9, y + -5, z + 19, L.getRandomConcrete(), 0, 3);
		L.setBlock(world, x + 7, y + -5, z + 20, L.getRandomConcrete(), 0, 3);
		L.setBlock(world, x + 8, y + -5, z + 20, L.getRandomConcrete(), 0, 3);
		L.setBlock(world, x + 9, y + -5, z + 20, L.getRandomConcrete(), 0, 3);
		L.setBlock(world, x + 7, y + -5, z + 21, L.getRandomConcrete(), 0, 3);
		L.setBlock(world, x + 8, y + -5, z + 21, L.getRandomConcrete(), 0, 3);
		L.setBlock(world, x + 9, y + -5, z + 21, L.getRandomConcrete(), 0, 3);
		L.setBlock(world, x + 6, y + -4, z + 9, L.getRandomConcrete(), 0, 3);
		L.setBlock(world, x + 7, y + -4, z + 9, L.getRandomConcrete(), 0, 3);
		L.setBlock(world, x + 8, y + -4, z + 9, L.getRandomConcrete(), 0, 3);
		L.setBlock(world, x + 9, y + -4, z + 9, L.getRandomConcrete(), 0, 3);
		L.setBlock(world, x + 10, y + -4, z + 9, L.getRandomConcrete(), 0, 3);
		L.setBlock(world, x + 5, y + -4, z + 10, L.getRandomConcrete(), 0, 3);
		L.setBlock(world, x + 6, y + -4, z + 10, L.getRandomConcrete(), 0, 3);
		L.setBlock(world, x + 7, y + -4, z + 10, Block2, 0, 3);
		L.setBlock(world, x + 8, y + -4, z + 10, Block2, 0, 3);
		L.setBlock(world, x + 9, y + -4, z + 10, Block2, 0, 3);
		L.setBlock(world, x + 10, y + -4, z + 10, L.getRandomConcrete(), 0, 3);
		L.setBlock(world, x + 11, y + -4, z + 10, L.getRandomConcrete(), 0, 3);
		L.setBlock(world, x + 5, y + -4, z + 11, L.getRandomConcrete(), 0, 3);
		L.setBlock(world, x + 6, y + -4, z + 11, Block2, 0, 3);
		L.setBlock(world, x + 7, y + -4, z + 11, Block2, 0, 3);
		L.setBlock(world, x + 8, y + -4, z + 11, VB.water, 0, 3);
		L.setBlock(world, x + 9, y + -4, z + 11, VB.water, 0, 3);
		L.setBlock(world, x + 10, y + -4, z + 11, Block2, 0, 3);
		L.setBlock(world, x + 11, y + -4, z + 11, L.getRandomConcrete(), 0, 3);
		L.setBlock(world, x + 5, y + -4, z + 12, L.getRandomConcrete(), 0, 3);
		L.setBlock(world, x + 6, y + -4, z + 12, Block2, 0, 3);
		L.setBlock(world, x + 7, y + -4, z + 12, VB.water, 0, 3);
		L.setBlock(world, x + 8, y + -4, z + 12, VB.water, 0, 3);
		L.setBlock(world, x + 9, y + -4, z + 12, VB.water, 0, 3);
		L.setBlock(world, x + 10, y + -4, z + 12, VB.water, 0, 3);
		L.setBlock(world, x + 11, y + -4, z + 12, L.getRandomConcrete(), 0, 3);
		L.setBlock(world, x + 5, y + -4, z + 13, L.getRandomConcrete(), 0, 3);
		L.setBlock(world, x + 6, y + -4, z + 13, VB.water, 0, 3);
		L.setBlock(world, x + 7, y + -4, z + 13, VB.water, 0, 3);
		L.setBlock(world, x + 8, y + -4, z + 13, VB.water, 0, 3);
		L.setBlock(world, x + 9, y + -4, z + 13, VB.water, 0, 3);
		L.setBlock(world, x + 10, y + -4, z + 13, VB.water, 0, 3);
		L.setBlock(world, x + 11, y + -4, z + 13, L.getRandomConcrete(), 0, 3);
		L.setBlock(world, x + 5, y + -4, z + 14, L.getRandomConcrete(), 0, 3);
		L.setBlock(world, x + 6, y + -4, z + 14, L.getRandomConcrete(), 0, 3);
		L.setBlock(world, x + 7, y + -4, z + 14, Block2, 0, 3);
		L.setBlock(world, x + 8, y + -4, z + 14, VB.water, 0, 3);
		L.setBlock(world, x + 9, y + -4, z + 14, VB.chest, 2, 3);
		if(L.getBlock(world, x + 9, y + -4, z + 14) == VB.chest)
		{
			ItemPool.generateChestContents(rand, ItemPool.getPool(ItemPoolsLegacy.POOL_NUKE_MISC), L.getTileEntity(world, x + 9, y + -4, z + 14), 10);
		}
        L.setBlock(world, x + 10, y + -4, z + 14, L.getRandomConcrete(), 0, 3);
		L.setBlock(world, x + 11, y + -4, z + 14, L.getRandomConcrete(), 0, 3);
		L.setBlock(world, x + 6, y + -4, z + 15, L.getRandomConcrete(), 0, 3);
		L.setBlock(world, x + 7, y + -4, z + 15, L.getRandomConcrete(), 0, 3);
		L.setBlock(world, x + 8, y + -4, z + 15, VB.water, 8, 3);
		L.setBlock(world, x + 9, y + -4, z + 15, L.getRandomConcrete(), 0, 3);
		L.setBlock(world, x + 10, y + -4, z + 15, L.getRandomConcrete(), 0, 3);
		L.setBlock(world, x + 7, y + -4, z + 16, L.getRandomConcrete(), 0, 3);
		L.setBlock(world, x + 8, y + -4, z + 16, VB.water, 8, 3);
		L.setBlock(world, x + 9, y + -4, z + 16, L.getRandomConcrete(), 0, 3);
		L.setBlock(world, x + 7, y + -4, z + 17, L.getRandomConcrete(), 0, 3);
		L.setBlock(world, x + 8, y + -4, z + 17, VB.water, 8, 3);
		L.setBlock(world, x + 9, y + -4, z + 17, L.getRandomConcrete(), 0, 3);
		L.setBlock(world, x + 7, y + -4, z + 18, L.getRandomConcrete(), 0, 3);
		L.setBlock(world, x + 8, y + -4, z + 18, VB.water, 8, 3);
		L.setBlock(world, x + 9, y + -4, z + 18, L.getRandomConcrete(), 0, 3);
		L.setBlock(world, x + 7, y + -4, z + 19, L.getRandomConcrete(), 0, 3);
		L.setBlock(world, x + 8, y + -4, z + 19, VB.water, 8, 3);
		L.setBlock(world, x + 9, y + -4, z + 19, L.getRandomConcrete(), 0, 3);
		L.setBlock(world, x + 6, y + -4, z + 20, Block3, 0, 3);
		L.setBlock(world, x + 7, y + -4, z + 20, Block3, 0, 3);
		L.setBlock(world, x + 8, y + -4, z + 20, VB.water, 0, 3);
		L.setBlock(world, x + 9, y + -4, z + 20, Block3, 0, 3);
		L.setBlock(world, x + 10, y + -4, z + 20, Block3, 0, 3);
		L.setBlock(world, x + 4, y + -4, z + 21, Block3, 0, 3);
		L.setBlock(world, x + 5, y + -4, z + 21, Block3, 0, 3);
		L.setBlock(world, x + 6, y + -4, z + 21, Block3, 0, 3);
		L.setBlock(world, x + 7, y + -4, z + 21, Block3, 0, 3);
		L.setBlock(world, x + 8, y + -4, z + 21, VB.water, 8, 3);
		L.setBlock(world, x + 9, y + -4, z + 21, Block3, 0, 3);
		L.setBlock(world, x + 10, y + -4, z + 21, Block3, 0, 3);
		L.setBlock(world, x + 11, y + -4, z + 21, Block3, 0, 3);
		L.setBlock(world, x + 12, y + -4, z + 21, Block3, 0, 3);
		L.setBlock(world, x + 4, y + -4, z + 22, Block3, 0, 3);
		L.setBlock(world, x + 5, y + -4, z + 22, Block3, 0, 3);
		L.setBlock(world, x + 6, y + -4, z + 22, Block3, 0, 3);
		L.setBlock(world, x + 7, y + -4, z + 22, Block3, 0, 3);
		L.setBlock(world, x + 8, y + -4, z + 22, Block3, 0, 3);
		L.setBlock(world, x + 9, y + -4, z + 22, Block3, 0, 3);
		L.setBlock(world, x + 10, y + -4, z + 22, Block3, 0, 3);
		L.setBlock(world, x + 11, y + -4, z + 22, Block3, 0, 3);
		L.setBlock(world, x + 12, y + -4, z + 22, Block3, 0, 3);
		L.setBlock(world, x + 3, y + -4, z + 23, Block3, 0, 3);
		L.setBlock(world, x + 4, y + -4, z + 23, Block3, 0, 3);
		L.setBlock(world, x + 5, y + -4, z + 23, Block3, 0, 3);
		L.setBlock(world, x + 6, y + -4, z + 23, Block3, 0, 3);
		L.setBlock(world, x + 7, y + -4, z + 23, Block3, 0, 3);
		L.setBlock(world, x + 8, y + -4, z + 23, Block3, 0, 3);
		L.setBlock(world, x + 9, y + -4, z + 23, Block3, 0, 3);
		L.setBlock(world, x + 10, y + -4, z + 23, Block3, 0, 3);
		L.setBlock(world, x + 11, y + -4, z + 23, Block3, 0, 3);
		L.setBlock(world, x + 12, y + -4, z + 23, Block3, 0, 3);
		L.setBlock(world, x + 13, y + -4, z + 23, Block3, 0, 3);
		L.setBlock(world, x + 3, y + -4, z + 24, Block3, 0, 3);
		L.setBlock(world, x + 4, y + -4, z + 24, Block3, 0, 3);
		L.setBlock(world, x + 5, y + -4, z + 24, Block3, 0, 3);
		L.setBlock(world, x + 6, y + -4, z + 24, Block3, 0, 3);
		L.setBlock(world, x + 7, y + -4, z + 24, Block3, 0, 3);
		L.setBlock(world, x + 8, y + -4, z + 24, Block3, 0, 3);
		L.setBlock(world, x + 9, y + -4, z + 24, Block3, 0, 3);
		L.setBlock(world, x + 10, y + -4, z + 24, Block3, 0, 3);
		L.setBlock(world, x + 11, y + -4, z + 24, Block3, 0, 3);
		L.setBlock(world, x + 12, y + -4, z + 24, Block3, 0, 3);
		L.setBlock(world, x + 13, y + -4, z + 24, Block3, 0, 3);
		L.setBlock(world, x + 3, y + -4, z + 25, Block3, 0, 3);
		L.setBlock(world, x + 4, y + -4, z + 25, Block3, 0, 3);
		L.setBlock(world, x + 5, y + -4, z + 25, Block3, 0, 3);
		L.setBlock(world, x + 6, y + -4, z + 25, Block3, 0, 3);
		L.setBlock(world, x + 7, y + -4, z + 25, Block3, 0, 3);
		L.setBlock(world, x + 8, y + -4, z + 25, Block3, 0, 3);
		L.setBlock(world, x + 9, y + -4, z + 25, Block3, 0, 3);
		L.setBlock(world, x + 10, y + -4, z + 25, Block3, 0, 3);
		L.setBlock(world, x + 11, y + -4, z + 25, Block3, 0, 3);
		L.setBlock(world, x + 12, y + -4, z + 25, Block3, 0, 3);
		L.setBlock(world, x + 13, y + -4, z + 25, Block3, 0, 3);
		L.setBlock(world, x + 3, y + -4, z + 26, Block3, 0, 3);
		L.setBlock(world, x + 4, y + -4, z + 26, Block3, 0, 3);
		L.setBlock(world, x + 5, y + -4, z + 26, Block3, 0, 3);
		L.setBlock(world, x + 6, y + -4, z + 26, Block3, 0, 3);
		L.setBlock(world, x + 7, y + -4, z + 26, Block3, 0, 3);
		L.setBlock(world, x + 8, y + -4, z + 26, Block3, 0, 3);
		L.setBlock(world, x + 9, y + -4, z + 26, Block3, 0, 3);
		L.setBlock(world, x + 10, y + -4, z + 26, Block3, 0, 3);
		L.setBlock(world, x + 11, y + -4, z + 26, Block3, 0, 3);
		L.setBlock(world, x + 12, y + -4, z + 26, Block3, 0, 3);
		L.setBlock(world, x + 13, y + -4, z + 26, Block3, 0, 3);
		L.setBlock(world, x + 3, y + -4, z + 27, Block3, 0, 3);
		L.setBlock(world, x + 4, y + -4, z + 27, Block3, 0, 3);
		L.setBlock(world, x + 5, y + -4, z + 27, Block3, 0, 3);
		L.setBlock(world, x + 6, y + -4, z + 27, Block3, 0, 3);
		L.setBlock(world, x + 7, y + -4, z + 27, Block3, 0, 3);
		L.setBlock(world, x + 8, y + -4, z + 27, Block3, 0, 3);
		L.setBlock(world, x + 9, y + -4, z + 27, Block3, 0, 3);
		L.setBlock(world, x + 10, y + -4, z + 27, Block3, 0, 3);
		L.setBlock(world, x + 11, y + -4, z + 27, Block3, 0, 3);
		L.setBlock(world, x + 12, y + -4, z + 27, Block3, 0, 3);
		L.setBlock(world, x + 13, y + -4, z + 27, Block3, 0, 3);
		L.setBlock(world, x + 4, y + -4, z + 28, Block3, 0, 3);
		L.setBlock(world, x + 5, y + -4, z + 28, Block3, 0, 3);
		L.setBlock(world, x + 6, y + -4, z + 28, Block3, 0, 3);
		L.setBlock(world, x + 7, y + -4, z + 28, Block3, 0, 3);
		L.setBlock(world, x + 8, y + -4, z + 28, Block3, 0, 3);
		L.setBlock(world, x + 9, y + -4, z + 28, Block3, 0, 3);
		L.setBlock(world, x + 10, y + -4, z + 28, Block3, 0, 3);
		L.setBlock(world, x + 11, y + -4, z + 28, Block3, 0, 3);
		L.setBlock(world, x + 12, y + -4, z + 28, Block3, 0, 3);
		L.setBlock(world, x + 4, y + -4, z + 29, Block3, 0, 3);
		L.setBlock(world, x + 5, y + -4, z + 29, Block3, 0, 3);
		L.setBlock(world, x + 6, y + -4, z + 29, Block3, 0, 3);
		L.setBlock(world, x + 7, y + -4, z + 29, Block3, 0, 3);
		L.setBlock(world, x + 8, y + -4, z + 29, Block3, 0, 3);
		L.setBlock(world, x + 9, y + -4, z + 29, Block3, 0, 3);
		L.setBlock(world, x + 10, y + -4, z + 29, Block3, 0, 3);
		L.setBlock(world, x + 11, y + -4, z + 29, Block3, 0, 3);
		L.setBlock(world, x + 12, y + -4, z + 29, Block3, 0, 3);
		L.setBlock(world, x + 6, y + -4, z + 30, Block3, 0, 3);
		L.setBlock(world, x + 7, y + -4, z + 30, Block3, 0, 3);
		L.setBlock(world, x + 8, y + -4, z + 30, Block3, 0, 3);
		L.setBlock(world, x + 9, y + -4, z + 30, Block3, 0, 3);
		L.setBlock(world, x + 10, y + -4, z + 30, Block3, 0, 3);
		L.setBlock(world, x + 6, y + -3, z + 9, L.getRandomConcrete(), 0, 3);
		L.setBlock(world, x + 7, y + -3, z + 9, L.getRandomConcrete(), 0, 3);
		L.setBlock(world, x + 8, y + -3, z + 9, L.getRandomConcrete(), 0, 3);
		L.setBlock(world, x + 9, y + -3, z + 9, L.getRandomConcrete(), 0, 3);
		L.setBlock(world, x + 10, y + -3, z + 9, L.getRandomConcrete(), 0, 3);
		L.setBlock(world, x + 5, y + -3, z + 10, L.getRandomConcrete(), 0, 3);
		L.setBlock(world, x + 6, y + -3, z + 10, L.getRandomConcrete(), 0, 3);
		L.setBlock(world, x + 7, y + -3, z + 10, Block2, 0, 3);
		L.setBlock(world, x + 8, y + -3, z + 10, VB.water, 0, 3);
		L.setBlock(world, x + 9, y + -3, z + 10, VB.water, 0, 3);
		L.setBlock(world, x + 10, y + -3, z + 10, L.getRandomConcrete(), 0, 3);
		L.setBlock(world, x + 11, y + -3, z + 10, L.getRandomConcrete(), 0, 3);
		L.setBlock(world, x + 5, y + -3, z + 11, L.getRandomConcrete(), 0, 3);
		L.setBlock(world, x + 6, y + -3, z + 11, VB.water, 0, 3);
		L.setBlock(world, x + 7, y + -3, z + 11, VB.water, 0, 3);
		L.setBlock(world, x + 8, y + -3, z + 11, VB.water, 0, 3);
		L.setBlock(world, x + 9, y + -3, z + 11, VB.water, 0, 3);
		L.setBlock(world, x + 10, y + -3, z + 11, VB.water, 0, 3);
		L.setBlock(world, x + 11, y + -3, z + 11, L.getRandomConcrete(), 0, 3);
		L.setBlock(world, x + 5, y + -3, z + 12, L.getRandomConcrete(), 0, 3);
		L.setBlock(world, x + 6, y + -3, z + 12, VB.water, 0, 3);
		L.setBlock(world, x + 7, y + -3, z + 12, VB.water, 0, 3);
		L.setBlock(world, x + 8, y + -3, z + 12, VB.water, 0, 3);
		L.setBlock(world, x + 9, y + -3, z + 12, VB.water, 0, 3);
		L.setBlock(world, x + 10, y + -3, z + 12, VB.water, 0, 3);
		L.setBlock(world, x + 11, y + -3, z + 12, L.getRandomConcrete(), 0, 3);
		L.setBlock(world, x + 5, y + -3, z + 13, L.getRandomConcrete(), 0, 3);
		L.setBlock(world, x + 6, y + -3, z + 13, VB.water, 0, 3);
		L.setBlock(world, x + 7, y + -3, z + 13, VB.water, 0, 3);
		L.setBlock(world, x + 8, y + -3, z + 13, VB.water, 0, 3);
		L.setBlock(world, x + 9, y + -3, z + 13, VB.water, 0, 3);
		L.setBlock(world, x + 10, y + -3, z + 13, VB.water, 0, 3);
		L.setBlock(world, x + 11, y + -3, z + 13, L.getRandomConcrete(), 0, 3);
		L.setBlock(world, x + 5, y + -3, z + 14, L.getRandomConcrete(), 0, 3);
		L.setBlock(world, x + 6, y + -3, z + 14, L.getRandomConcrete(), 0, 3);
		L.setBlock(world, x + 7, y + -3, z + 14, VB.water, 0, 3);
		L.setBlock(world, x + 8, y + -3, z + 14, VB.water, 0, 3);
		L.setBlock(world, x + 9, y + -3, z + 14, VB.water, 0, 3);
		L.setBlock(world, x + 10, y + -3, z + 14, L.getRandomConcrete(), 0, 3);
		L.setBlock(world, x + 11, y + -3, z + 14, L.getRandomConcrete(), 0, 3);
		L.setBlock(world, x + 6, y + -3, z + 15, L.getRandomConcrete(), 0, 3);
		L.setBlock(world, x + 7, y + -3, z + 15, L.getRandomConcrete(), 0, 3);
		L.setBlock(world, x + 8, y + -3, z + 15, VB.water, 0, 3);
		L.setBlock(world, x + 9, y + -3, z + 15, L.getRandomConcrete(), 0, 3);
		L.setBlock(world, x + 10, y + -3, z + 15, L.getRandomConcrete(), 0, 3);
		L.setBlock(world, x + 7, y + -3, z + 16, L.getRandomConcrete(), 0, 3);
		L.setBlock(world, x + 8, y + -3, z + 16, VB.water, 0, 3);
		L.setBlock(world, x + 9, y + -3, z + 16, L.getRandomConcrete(), 0, 3);
		L.setBlock(world, x + 7, y + -3, z + 17, L.getRandomConcrete(), 0, 3);
		L.setBlock(world, x + 8, y + -3, z + 17, VB.water, 0, 3);
		L.setBlock(world, x + 9, y + -3, z + 17, L.getRandomConcrete(), 0, 3);
		L.setBlock(world, x + 7, y + -3, z + 18, L.getRandomConcrete(), 0, 3);
		L.setBlock(world, x + 8, y + -3, z + 18, VB.water, 0, 3);
		L.setBlock(world, x + 9, y + -3, z + 18, L.getRandomConcrete(), 0, 3);
		L.setBlock(world, x + 7, y + -3, z + 19, L.getRandomConcrete(), 0, 3);
		L.setBlock(world, x + 8, y + -3, z + 19, VB.water, 0, 3);
		L.setBlock(world, x + 9, y + -3, z + 19, L.getRandomConcrete(), 0, 3);
		L.setBlock(world, x + 6, y + -3, z + 20, Block3, 0, 3);
		L.setBlock(world, x + 7, y + -3, z + 20, Block3, 0, 3);
		L.setBlock(world, x + 8, y + -3, z + 20, VB.water, 0, 3);
		L.setBlock(world, x + 9, y + -3, z + 20, Block3, 0, 3);
		L.setBlock(world, x + 10, y + -3, z + 20, Block3, 0, 3);
		L.setBlock(world, x + 4, y + -3, z + 21, Block3, 0, 3);
		L.setBlock(world, x + 5, y + -3, z + 21, Block3, 0, 3);
		L.setBlock(world, x + 6, y + -3, z + 21, VB.water, 0, 3);
		L.setBlock(world, x + 7, y + -3, z + 21, VB.water, 0, 3);
		L.setBlock(world, x + 8, y + -3, z + 21, VB.water, 0, 3);
		L.setBlock(world, x + 9, y + -3, z + 21, VB.water, 0, 3);
		L.setBlock(world, x + 10, y + -3, z + 21, VB.water, 0, 3);
		L.setBlock(world, x + 11, y + -3, z + 21, Block3, 0, 3);
		L.setBlock(world, x + 12, y + -3, z + 21, Block3, 0, 3);
		L.setBlock(world, x + 4, y + -3, z + 22, Block3, 0, 3);
		L.setBlock(world, x + 5, y + -3, z + 22, VB.water, 0, 3);
		L.setBlock(world, x + 6, y + -3, z + 22, VB.water, 0, 3);
		L.setBlock(world, x + 7, y + -3, z + 22, VB.water, 0, 3);
		L.setBlock(world, x + 8, y + -3, z + 22, VB.water, 0, 3);
		L.setBlock(world, x + 9, y + -3, z + 22, VB.water, 0, 3);
		L.setBlock(world, x + 10, y + -3, z + 22, VB.water, 0, 3);
		L.setBlock(world, x + 11, y + -3, z + 22, VB.water, 0, 3);
		L.setBlock(world, x + 12, y + -3, z + 22, Block3, 0, 3);
		L.setBlock(world, x + 3, y + -3, z + 23, Block3, 0, 3);
		L.setBlock(world, x + 4, y + -3, z + 23, VB.water, 0, 3);
		L.setBlock(world, x + 5, y + -3, z + 23, VB.water, 0, 3);
		L.setBlock(world, x + 6, y + -3, z + 23, VB.water, 0, 3);
		L.setBlock(world, x + 7, y + -3, z + 23, VB.water, 0, 3);
		L.setBlock(world, x + 8, y + -3, z + 23, VB.water, 0, 3);
		L.setBlock(world, x + 9, y + -3, z + 23, VB.water, 0, 3);
		L.setBlock(world, x + 10, y + -3, z + 23, VB.water, 0, 3);
		L.setBlock(world, x + 11, y + -3, z + 23, VB.water, 0, 3);
		L.setBlock(world, x + 12, y + -3, z + 23, VB.water, 0, 3);
		L.setBlock(world, x + 13, y + -3, z + 23, Block3, 0, 3);
		L.setBlock(world, x + 3, y + -3, z + 24, Block3, 0, 3);
		L.setBlock(world, x + 4, y + -3, z + 24, VB.water, 0, 3);
		L.setBlock(world, x + 5, y + -3, z + 24, VB.water, 0, 3);
		L.setBlock(world, x + 6, y + -3, z + 24, VB.water, 0, 3);
		L.setBlock(world, x + 7, y + -3, z + 24, VB.water, 0, 3);
		L.setBlock(world, x + 8, y + -3, z + 24, VB.water, 0, 3);
		L.setBlock(world, x + 9, y + -3, z + 24, VB.water, 0, 3);
		L.setBlock(world, x + 10, y + -3, z + 24, VB.water, 0, 3);
		L.setBlock(world, x + 11, y + -3, z + 24, VB.water, 0, 3);
		L.setBlock(world, x + 12, y + -3, z + 24, VB.water, 0, 3);
		L.setBlock(world, x + 13, y + -3, z + 24, Block3, 0, 3);
		L.setBlock(world, x + 3, y + -3, z + 25, Block3, 0, 3);
		L.setBlock(world, x + 4, y + -3, z + 25, VB.water, 0, 3);
		L.setBlock(world, x + 5, y + -3, z + 25, VB.water, 0, 3);
		L.setBlock(world, x + 6, y + -3, z + 25, VB.water, 0, 3);
		L.setBlock(world, x + 7, y + -3, z + 25, VB.water, 0, 3);
		L.setBlock(world, x + 8, y + -3, z + 25, Block4, 2, 3);
		L.setBlock(world, x + 9, y + -3, z + 25, VB.water, 0, 3);
		L.setBlock(world, x + 10, y + -3, z + 25, VB.water, 0, 3);
		L.setBlock(world, x + 11, y + -3, z + 25, VB.water, 0, 3);
		L.setBlock(world, x + 12, y + -3, z + 25, VB.water, 0, 3);
		L.setBlock(world, x + 13, y + -3, z + 25, Block3, 0, 3);
		L.setBlock(world, x + 3, y + -3, z + 26, Block3, 0, 3);
		L.setBlock(world, x + 4, y + -3, z + 26, VB.water, 0, 3);
		L.setBlock(world, x + 5, y + -3, z + 26, VB.water, 0, 3);
		L.setBlock(world, x + 6, y + -3, z + 26, VB.water, 0, 3);
		L.setBlock(world, x + 7, y + -3, z + 26, VB.water, 0, 3);
		L.setBlock(world, x + 8, y + -3, z + 26, VB.water, 0, 3);
		L.setBlock(world, x + 9, y + -3, z + 26, VB.water, 0, 3);
		L.setBlock(world, x + 10, y + -3, z + 26, VB.water, 0, 3);
		L.setBlock(world, x + 11, y + -3, z + 26, VB.water, 0, 3);
		L.setBlock(world, x + 12, y + -3, z + 26, VB.water, 0, 3);
		L.setBlock(world, x + 13, y + -3, z + 26, Block3, 0, 3);
		L.setBlock(world, x + 3, y + -3, z + 27, Block3, 0, 3);
		L.setBlock(world, x + 4, y + -3, z + 27, VB.water, 0, 3);
		L.setBlock(world, x + 5, y + -3, z + 27, VB.water, 0, 3);
		L.setBlock(world, x + 6, y + -3, z + 27, VB.water, 0, 3);
		L.setBlock(world, x + 7, y + -3, z + 27, VB.water, 0, 3);
		L.setBlock(world, x + 8, y + -3, z + 27, VB.water, 0, 3);
		L.setBlock(world, x + 9, y + -3, z + 27, VB.water, 0, 3);
		L.setBlock(world, x + 10, y + -3, z + 27, VB.water, 0, 3);
		L.setBlock(world, x + 11, y + -3, z + 27, VB.water, 0, 3);
		L.setBlock(world, x + 12, y + -3, z + 27, VB.water, 0, 3);
		L.setBlock(world, x + 13, y + -3, z + 27, Block3, 0, 3);
		L.setBlock(world, x + 4, y + -3, z + 28, Block3, 0, 3);
		L.setBlock(world, x + 5, y + -3, z + 28, VB.water, 0, 3);
		L.setBlock(world, x + 6, y + -3, z + 28, VB.water, 0, 3);
		L.setBlock(world, x + 7, y + -3, z + 28, VB.water, 0, 3);
		L.setBlock(world, x + 8, y + -3, z + 28, VB.water, 0, 3);
		L.setBlock(world, x + 9, y + -3, z + 28, VB.water, 0, 3);
		L.setBlock(world, x + 10, y + -3, z + 28, VB.water, 0, 3);
		L.setBlock(world, x + 11, y + -3, z + 28, VB.water, 0, 3);
		L.setBlock(world, x + 12, y + -3, z + 28, Block3, 0, 3);
		L.setBlock(world, x + 4, y + -3, z + 29, Block3, 0, 3);
		L.setBlock(world, x + 5, y + -3, z + 29, Block3, 0, 3);
		L.setBlock(world, x + 6, y + -3, z + 29, VB.water, 0, 3);
		L.setBlock(world, x + 7, y + -3, z + 29, VB.water, 0, 3);
		L.setBlock(world, x + 8, y + -3, z + 29, VB.water, 0, 3);
		L.setBlock(world, x + 9, y + -3, z + 29, VB.water, 0, 3);
		L.setBlock(world, x + 10, y + -3, z + 29, VB.water, 0, 3);
		L.setBlock(world, x + 11, y + -3, z + 29, Block3, 0, 3);
		L.setBlock(world, x + 12, y + -3, z + 29, Block3, 0, 3);
		L.setBlock(world, x + 6, y + -3, z + 30, Block3, 0, 3);
		L.setBlock(world, x + 7, y + -3, z + 30, Block3, 0, 3);
		L.setBlock(world, x + 8, y + -3, z + 30, Block3, 0, 3);
		L.setBlock(world, x + 9, y + -3, z + 30, Block3, 0, 3);
		L.setBlock(world, x + 10, y + -3, z + 30, Block3, 0, 3);
		L.setBlock(world, x + 0, y + -2, z + 0, Block3, 0, 3);
		L.setBlock(world, x + 1, y + -2, z + 0, Block3, 0, 3);
		L.setBlock(world, x + 2, y + -2, z + 0, Block3, 0, 3);
		L.setBlock(world, x + 3, y + -2, z + 0, Block3, 0, 3);
		L.setBlock(world, x + 4, y + -2, z + 0, Block3, 0, 3);
		L.setBlock(world, x + 5, y + -2, z + 0, Block3, 0, 3);
		L.setBlock(world, x + 6, y + -2, z + 0, Block3, 0, 3);
		L.setBlock(world, x + 7, y + -2, z + 0, Block3, 0, 3);
		L.setBlock(world, x + 8, y + -2, z + 0, Block3, 0, 3);
		L.setBlock(world, x + 9, y + -2, z + 0, Block3, 0, 3);
		L.setBlock(world, x + 10, y + -2, z + 0, Block3, 0, 3);
		L.setBlock(world, x + 11, y + -2, z + 0, Block3, 0, 3);
		L.setBlock(world, x + 12, y + -2, z + 0, Block3, 0, 3);
		L.setBlock(world, x + 13, y + -2, z + 0, Block3, 0, 3);
		L.setBlock(world, x + 14, y + -2, z + 0, Block3, 0, 3);
		L.setBlock(world, x + 15, y + -2, z + 0, Block3, 0, 3);
		L.setBlock(world, x + 16, y + -2, z + 0, Block3, 0, 3);
		L.setBlock(world, x + 17, y + -2, z + 0, Block3, 0, 3);
		L.setBlock(world, x + 18, y + -2, z + 0, Block3, 0, 3);
		L.setBlock(world, x + 19, y + -2, z + 0, Block3, 0, 3);
		L.setBlock(world, x + 20, y + -2, z + 0, Block3, 0, 3);
		L.setBlock(world, x + 21, y + -2, z + 0, Block3, 0, 3);
		L.setBlock(world, x + 22, y + -2, z + 0, Block3, 0, 3);
		L.setBlock(world, x + 23, y + -2, z + 0, Block3, 0, 3);
		L.setBlock(world, x + 24, y + -2, z + 0, Block3, 0, 3);
		L.setBlock(world, x + 25, y + -2, z + 0, Block3, 0, 3);
		L.setBlock(world, x + 26, y + -2, z + 0, Block3, 0, 3);
		L.setBlock(world, x + 27, y + -2, z + 0, Block3, 0, 3);
		L.setBlock(world, x + 28, y + -2, z + 0, Block3, 0, 3);
		L.setBlock(world, x + 29, y + -2, z + 0, Block3, 0, 3);
		L.setBlock(world, x + 30, y + -2, z + 0, Block3, 0, 3);
		L.setBlock(world, x + 31, y + -2, z + 0, Block3, 0, 3);
		L.setBlock(world, x + 32, y + -2, z + 0, Block3, 0, 3);
		L.setBlock(world, x + 33, y + -2, z + 0, Block3, 0, 3);
		L.setBlock(world, x + 34, y + -2, z + 0, Block3, 0, 3);
		L.setBlock(world, x + 35, y + -2, z + 0, Block3, 0, 3);
		L.setBlock(world, x + 36, y + -2, z + 0, Block3, 0, 3);
		L.setBlock(world, x + 37, y + -2, z + 0, Block3, 0, 3);
		L.setBlock(world, x + 38, y + -2, z + 0, Block3, 0, 3);
		L.setBlock(world, x + 39, y + -2, z + 0, Block3, 0, 3);
		L.setBlock(world, x + 40, y + -2, z + 0, Block3, 0, 3);
		L.setBlock(world, x + 0, y + -2, z + 1, Block3, 0, 3);
		L.setBlock(world, x + 40, y + -2, z + 1, Block3, 0, 3);
		L.setBlock(world, x + 0, y + -2, z + 2, Block3, 0, 3);
		L.setBlock(world, x + 40, y + -2, z + 2, Block3, 0, 3);
		L.setBlock(world, x + 0, y + -2, z + 3, Block3, 0, 3);
		L.setBlock(world, x + 8, y + -2, z + 3, Block3, 0, 3);
		L.setBlock(world, x + 9, y + -2, z + 3, Block3, 0, 3);
		L.setBlock(world, x + 10, y + -2, z + 3, Block3, 0, 3);
		L.setBlock(world, x + 11, y + -2, z + 3, Block3, 0, 3);
		L.setBlock(world, x + 12, y + -2, z + 3, Block3, 0, 3);
		L.setBlock(world, x + 13, y + -2, z + 3, Block3, 0, 3);
		L.setBlock(world, x + 14, y + -2, z + 3, Block3, 0, 3);
		L.setBlock(world, x + 15, y + -2, z + 3, Block3, 0, 3);
		L.setBlock(world, x + 16, y + -2, z + 3, Block3, 0, 3);
		L.setBlock(world, x + 17, y + -2, z + 3, Block3, 0, 3);
		L.setBlock(world, x + 18, y + -2, z + 3, Block3, 0, 3);
		L.setBlock(world, x + 19, y + -2, z + 3, Block3, 0, 3);
		L.setBlock(world, x + 20, y + -2, z + 3, Block3, 0, 3);
		L.setBlock(world, x + 21, y + -2, z + 3, Block3, 0, 3);
		L.setBlock(world, x + 22, y + -2, z + 3, Block3, 0, 3);
		L.setBlock(world, x + 23, y + -2, z + 3, Block3, 0, 3);
		L.setBlock(world, x + 24, y + -2, z + 3, Block3, 0, 3);
		L.setBlock(world, x + 25, y + -2, z + 3, Block3, 0, 3);
		L.setBlock(world, x + 26, y + -2, z + 3, Block3, 0, 3);
		L.setBlock(world, x + 27, y + -2, z + 3, Block3, 0, 3);
		L.setBlock(world, x + 28, y + -2, z + 3, Block3, 0, 3);
		L.setBlock(world, x + 29, y + -2, z + 3, Block3, 0, 3);
		L.setBlock(world, x + 30, y + -2, z + 3, Block3, 0, 3);
		L.setBlock(world, x + 31, y + -2, z + 3, Block3, 0, 3);
		L.setBlock(world, x + 32, y + -2, z + 3, Block3, 0, 3);
		L.setBlock(world, x + 33, y + -2, z + 3, Block3, 0, 3);
		L.setBlock(world, x + 34, y + -2, z + 3, Block3, 0, 3);
		L.setBlock(world, x + 35, y + -2, z + 3, Block3, 0, 3);
		L.setBlock(world, x + 36, y + -2, z + 3, Block3, 0, 3);
		L.setBlock(world, x + 37, y + -2, z + 3, Block3, 0, 3);
		L.setBlock(world, x + 38, y + -2, z + 3, Block3, 0, 3);
		L.setBlock(world, x + 39, y + -2, z + 3, Block3, 0, 3);
		L.setBlock(world, x + 40, y + -2, z + 3, Block3, 0, 3);
		L.setBlock(world, x + 0, y + -2, z + 4, Block3, 0, 3);
		L.setBlock(world, x + 8, y + -2, z + 4, Block3, 0, 3);
		L.setBlock(world, x + 9, y + -2, z + 4, Block3, 0, 3);
		L.setBlock(world, x + 10, y + -2, z + 4, Block3, 0, 3);
		L.setBlock(world, x + 11, y + -2, z + 4, Block3, 0, 3);
		L.setBlock(world, x + 12, y + -2, z + 4, Block3, 0, 3);
		L.setBlock(world, x + 13, y + -2, z + 4, Block3, 0, 3);
		L.setBlock(world, x + 14, y + -2, z + 4, Block3, 0, 3);
		L.setBlock(world, x + 15, y + -2, z + 4, Block3, 0, 3);
		L.setBlock(world, x + 16, y + -2, z + 4, Block3, 0, 3);
		L.setBlock(world, x + 17, y + -2, z + 4, Block3, 0, 3);
		L.setBlock(world, x + 18, y + -2, z + 4, Block3, 0, 3);
		L.setBlock(world, x + 19, y + -2, z + 4, Block3, 0, 3);
		L.setBlock(world, x + 20, y + -2, z + 4, Block3, 0, 3);
		L.setBlock(world, x + 21, y + -2, z + 4, Block3, 0, 3);
		L.setBlock(world, x + 22, y + -2, z + 4, Block3, 0, 3);
		L.setBlock(world, x + 23, y + -2, z + 4, Block3, 0, 3);
		L.setBlock(world, x + 24, y + -2, z + 4, Block3, 0, 3);
		L.setBlock(world, x + 25, y + -2, z + 4, Block3, 0, 3);
		L.setBlock(world, x + 26, y + -2, z + 4, Block3, 0, 3);
		L.setBlock(world, x + 27, y + -2, z + 4, Block3, 0, 3);
		L.setBlock(world, x + 28, y + -2, z + 4, Block3, 0, 3);
		L.setBlock(world, x + 29, y + -2, z + 4, Block3, 0, 3);
		L.setBlock(world, x + 30, y + -2, z + 4, Block3, 0, 3);
		L.setBlock(world, x + 31, y + -2, z + 4, Block3, 0, 3);
		L.setBlock(world, x + 32, y + -2, z + 4, Block3, 0, 3);
		L.setBlock(world, x + 33, y + -2, z + 4, Block3, 0, 3);
		L.setBlock(world, x + 34, y + -2, z + 4, Block3, 0, 3);
		L.setBlock(world, x + 35, y + -2, z + 4, Block3, 0, 3);
		L.setBlock(world, x + 36, y + -2, z + 4, Block3, 0, 3);
		L.setBlock(world, x + 37, y + -2, z + 4, Block3, 0, 3);
		L.setBlock(world, x + 38, y + -2, z + 4, Block3, 0, 3);
		L.setBlock(world, x + 39, y + -2, z + 4, Block3, 0, 3);
		L.setBlock(world, x + 40, y + -2, z + 4, Block3, 0, 3);
		L.setBlock(world, x + 0, y + -2, z + 5, Block3, 0, 3);
		L.setBlock(world, x + 8, y + -2, z + 5, Block3, 0, 3);
		L.setBlock(world, x + 38, y + -2, z + 5, Block3, 0, 3);
		L.setBlock(world, x + 39, y + -2, z + 5, Block3, 0, 3);
		L.setBlock(world, x + 40, y + -2, z + 5, Block3, 0, 3);
		L.setBlock(world, x + 0, y + -2, z + 6, Block3, 0, 3);
		L.setBlock(world, x + 38, y + -2, z + 6, Block3, 0, 3);
		L.setBlock(world, x + 39, y + -2, z + 6, Block3, 0, 3);
		L.setBlock(world, x + 40, y + -2, z + 6, Block3, 0, 3);
		L.setBlock(world, x + 0, y + -2, z + 7, Block3, 0, 3);
		L.setBlock(world, x + 38, y + -2, z + 7, Block3, 0, 3);
		L.setBlock(world, x + 39, y + -2, z + 7, Block3, 0, 3);
		L.setBlock(world, x + 40, y + -2, z + 7, Block3, 0, 3);
		L.setBlock(world, x + 0, y + -2, z + 8, Block3, 0, 3);
		L.setBlock(world, x + 6, y + -2, z + 8, L.getRandomConcrete(), 0, 3);
		L.setBlock(world, x + 7, y + -2, z + 8, L.getRandomConcrete(), 0, 3);
		L.setBlock(world, x + 8, y + -2, z + 8, L.getRandomConcrete(), 0, 3);
		L.setBlock(world, x + 9, y + -2, z + 8, L.getRandomConcrete(), 0, 3);
		L.setBlock(world, x + 10, y + -2, z + 8, L.getRandomConcrete(), 0, 3);
		L.setBlock(world, x + 38, y + -2, z + 8, Block3, 0, 3);
		L.setBlock(world, x + 39, y + -2, z + 8, Block3, 0, 3);
		L.setBlock(world, x + 40, y + -2, z + 8, Block3, 0, 3);
		L.setBlock(world, x + 0, y + -2, z + 9, Block3, 0, 3);
		L.setBlock(world, x + 5, y + -2, z + 9, L.getRandomConcrete(), 0, 3);
		L.setBlock(world, x + 6, y + -2, z + 9, L.getRandomConcrete(), 0, 3);
		L.setBlock(world, x + 7, y + -2, z + 9, L.getRandomConcrete(), 0, 3);
		L.setBlock(world, x + 8, y + -2, z + 9, L.getRandomConcrete(), 0, 3);
		L.setBlock(world, x + 9, y + -2, z + 9, L.getRandomConcrete(), 0, 3);
		L.setBlock(world, x + 10, y + -2, z + 9, L.getRandomConcrete(), 0, 3);
		L.setBlock(world, x + 11, y + -2, z + 9, L.getRandomConcrete(), 0, 3);
		L.setBlock(world, x + 38, y + -2, z + 9, Block3, 0, 3);
		L.setBlock(world, x + 39, y + -2, z + 9, Block3, 0, 3);
		L.setBlock(world, x + 40, y + -2, z + 9, Block3, 0, 3);
		L.setBlock(world, x + 0, y + -2, z + 10, Block3, 0, 3);
		L.setBlock(world, x + 4, y + -2, z + 10, L.getRandomConcrete(), 0, 3);
		L.setBlock(world, x + 5, y + -2, z + 10, L.getRandomConcrete(), 0, 3);
		L.setBlock(world, x + 6, y + -2, z + 10, L.getRandomConcrete(), 0, 3);
		L.setBlock(world, x + 7, y + -2, z + 10, VB.water, 0, 3);
		L.setBlock(world, x + 8, y + -2, z + 10, VB.water, 0, 3);
		L.setBlock(world, x + 9, y + -2, z + 10, VB.water, 0, 3);
		L.setBlock(world, x + 10, y + -2, z + 10, L.getRandomConcrete(), 0, 3);
		L.setBlock(world, x + 11, y + -2, z + 10, L.getRandomConcrete(), 0, 3);
		L.setBlock(world, x + 12, y + -2, z + 10, L.getRandomConcrete(), 0, 3);
		L.setBlock(world, x + 38, y + -2, z + 10, Block3, 0, 3);
		L.setBlock(world, x + 39, y + -2, z + 10, Block3, 0, 3);
		L.setBlock(world, x + 40, y + -2, z + 10, Block3, 0, 3);
		L.setBlock(world, x + 0, y + -2, z + 11, Block3, 0, 3);
		L.setBlock(world, x + 4, y + -2, z + 11, L.getRandomConcrete(), 0, 3);
		L.setBlock(world, x + 5, y + -2, z + 11, L.getRandomConcrete(), 0, 3);
		L.setBlock(world, x + 6, y + -2, z + 11, VB.water, 0, 3);
		L.setBlock(world, x + 7, y + -2, z + 11, VB.water, 0, 3);
		L.setBlock(world, x + 8, y + -2, z + 11, VB.water, 0, 3);
		L.setBlock(world, x + 9, y + -2, z + 11, VB.water, 0, 3);
		L.setBlock(world, x + 10, y + -2, z + 11, VB.water, 0, 3);
		L.setBlock(world, x + 11, y + -2, z + 11, L.getRandomConcrete(), 0, 3);
		L.setBlock(world, x + 12, y + -2, z + 11, L.getRandomConcrete(), 0, 3);
		L.setBlock(world, x + 38, y + -2, z + 11, Block3, 0, 3);
		L.setBlock(world, x + 39, y + -2, z + 11, Block3, 0, 3);
		L.setBlock(world, x + 40, y + -2, z + 11, Block3, 0, 3);
		L.setBlock(world, x + 0, y + -2, z + 12, Block3, 0, 3);
		L.setBlock(world, x + 4, y + -2, z + 12, L.getRandomConcrete(), 0, 3);
		L.setBlock(world, x + 5, y + -2, z + 12, L.getRandomConcrete(), 0, 3);
		L.setBlock(world, x + 6, y + -2, z + 12, VB.water, 0, 3);
		L.setBlock(world, x + 7, y + -2, z + 12, VB.water, 0, 3);
		L.setBlock(world, x + 8, y + -2, z + 12, VB.water, 0, 3);
		L.setBlock(world, x + 9, y + -2, z + 12, VB.water, 0, 3);
		L.setBlock(world, x + 10, y + -2, z + 12, VB.water, 0, 3);
		L.setBlock(world, x + 11, y + -2, z + 12, L.getRandomConcrete(), 0, 3);
		L.setBlock(world, x + 12, y + -2, z + 12, L.getRandomConcrete(), 0, 3);
		L.setBlock(world, x + 38, y + -2, z + 12, Block3, 0, 3);
		L.setBlock(world, x + 39, y + -2, z + 12, Block3, 0, 3);
		L.setBlock(world, x + 40, y + -2, z + 12, Block3, 0, 3);
		L.setBlock(world, x + 0, y + -2, z + 13, Block3, 0, 3);
		L.setBlock(world, x + 4, y + -2, z + 13, L.getRandomConcrete(), 0, 3);
		L.setBlock(world, x + 5, y + -2, z + 13, L.getRandomConcrete(), 0, 3);
		L.setBlock(world, x + 6, y + -2, z + 13, VB.water, 0, 3);
		L.setBlock(world, x + 7, y + -2, z + 13, VB.water, 0, 3);
		L.setBlock(world, x + 8, y + -2, z + 13, VB.water, 0, 3);
		L.setBlock(world, x + 9, y + -2, z + 13, VB.water, 0, 3);
		L.setBlock(world, x + 10, y + -2, z + 13, VB.water, 0, 3);
		L.setBlock(world, x + 11, y + -2, z + 13, L.getRandomConcrete(), 0, 3);
		L.setBlock(world, x + 12, y + -2, z + 13, L.getRandomConcrete(), 0, 3);
		L.setBlock(world, x + 38, y + -2, z + 13, Block3, 0, 3);
		L.setBlock(world, x + 39, y + -2, z + 13, Block3, 0, 3);
		L.setBlock(world, x + 40, y + -2, z + 13, Block3, 0, 3);
		L.setBlock(world, x + 0, y + -2, z + 14, Block3, 0, 3);
		L.setBlock(world, x + 4, y + -2, z + 14, L.getRandomConcrete(), 0, 3);
		L.setBlock(world, x + 5, y + -2, z + 14, L.getRandomConcrete(), 0, 3);
		L.setBlock(world, x + 6, y + -2, z + 14, L.getRandomConcrete(), 0, 3);
		L.setBlock(world, x + 7, y + -2, z + 14, VB.water, 0, 3);
		L.setBlock(world, x + 8, y + -2, z + 14, VB.water, 0, 3);
		L.setBlock(world, x + 9, y + -2, z + 14, VB.water, 0, 3);
		L.setBlock(world, x + 10, y + -2, z + 14, L.getRandomConcrete(), 0, 3);
		L.setBlock(world, x + 11, y + -2, z + 14, L.getRandomConcrete(), 0, 3);
		L.setBlock(world, x + 12, y + -2, z + 14, L.getRandomConcrete(), 0, 3);
		L.setBlock(world, x + 38, y + -2, z + 14, Block3, 0, 3);
		L.setBlock(world, x + 39, y + -2, z + 14, Block3, 0, 3);
		L.setBlock(world, x + 40, y + -2, z + 14, Block3, 0, 3);
		L.setBlock(world, x + 0, y + -2, z + 15, Block3, 0, 3);
		L.setBlock(world, x + 5, y + -2, z + 15, L.getRandomConcrete(), 0, 3);
		L.setBlock(world, x + 6, y + -2, z + 15, L.getRandomConcrete(), 0, 3);
		L.setBlock(world, x + 7, y + -2, z + 15, L.getRandomConcrete(), 0, 3);
		L.setBlock(world, x + 8, y + -2, z + 15, L.getRandomConcrete(), 0, 3);
		L.setBlock(world, x + 9, y + -2, z + 15, L.getRandomConcrete(), 0, 3);
		L.setBlock(world, x + 10, y + -2, z + 15, L.getRandomConcrete(), 0, 3);
		L.setBlock(world, x + 11, y + -2, z + 15, L.getRandomConcrete(), 0, 3);
		L.setBlock(world, x + 38, y + -2, z + 15, Block3, 0, 3);
		L.setBlock(world, x + 39, y + -2, z + 15, Block3, 0, 3);
		L.setBlock(world, x + 40, y + -2, z + 15, Block3, 0, 3);
		L.setBlock(world, x + 0, y + -2, z + 16, Block3, 0, 3);
		L.setBlock(world, x + 6, y + -2, z + 16, L.getRandomConcrete(), 0, 3);
		L.setBlock(world, x + 7, y + -2, z + 16, L.getRandomConcrete(), 0, 3);
		L.setBlock(world, x + 8, y + -2, z + 16, L.getRandomConcrete(), 0, 3);
		L.setBlock(world, x + 9, y + -2, z + 16, L.getRandomConcrete(), 0, 3);
		L.setBlock(world, x + 10, y + -2, z + 16, L.getRandomConcrete(), 0, 3);
		L.setBlock(world, x + 38, y + -2, z + 16, Block3, 0, 3);
		L.setBlock(world, x + 39, y + -2, z + 16, Block3, 0, 3);
		L.setBlock(world, x + 40, y + -2, z + 16, Block3, 0, 3);
		L.setBlock(world, x + 0, y + -2, z + 17, Block3, 0, 3);
		L.setBlock(world, x + 7, y + -2, z + 17, L.getRandomConcrete(), 0, 3);
		L.setBlock(world, x + 8, y + -2, z + 17, L.getRandomConcrete(), 0, 3);
		L.setBlock(world, x + 9, y + -2, z + 17, L.getRandomConcrete(), 0, 3);
		L.setBlock(world, x + 38, y + -2, z + 17, Block3, 0, 3);
		L.setBlock(world, x + 39, y + -2, z + 17, Block3, 0, 3);
		L.setBlock(world, x + 40, y + -2, z + 17, Block3, 0, 3);
		L.setBlock(world, x + 0, y + -2, z + 18, Block3, 0, 3);
		L.setBlock(world, x + 7, y + -2, z + 18, L.getRandomConcrete(), 0, 3);
		L.setBlock(world, x + 8, y + -2, z + 18, L.getRandomConcrete(), 0, 3);
		L.setBlock(world, x + 9, y + -2, z + 18, L.getRandomConcrete(), 0, 3);
		L.setBlock(world, x + 38, y + -2, z + 18, Block3, 0, 3);
		L.setBlock(world, x + 39, y + -2, z + 18, Block3, 0, 3);
		L.setBlock(world, x + 40, y + -2, z + 18, Block3, 0, 3);
		L.setBlock(world, x + 0, y + -2, z + 19, Block3, 0, 3);
		L.setBlock(world, x + 7, y + -2, z + 19, L.getRandomConcrete(), 0, 3);
		L.setBlock(world, x + 8, y + -2, z + 19, L.getRandomConcrete(), 0, 3);
		L.setBlock(world, x + 9, y + -2, z + 19, L.getRandomConcrete(), 0, 3);
		L.setBlock(world, x + 38, y + -2, z + 19, Block3, 0, 3);
		L.setBlock(world, x + 39, y + -2, z + 19, Block3, 0, 3);
		L.setBlock(world, x + 40, y + -2, z + 19, Block3, 0, 3);
		L.setBlock(world, x + 0, y + -2, z + 20, Block3, 0, 3);
		L.setBlock(world, x + 6, y + -2, z + 20, Block3, 0, 3);
		L.setBlock(world, x + 7, y + -2, z + 20, Block3, 0, 3);
		L.setBlock(world, x + 8, y + -2, z + 20, Block3, 0, 3);
		L.setBlock(world, x + 9, y + -2, z + 20, Block3, 0, 3);
		L.setBlock(world, x + 10, y + -2, z + 20, Block3, 0, 3);
		L.setBlock(world, x + 38, y + -2, z + 20, Block3, 0, 3);
		L.setBlock(world, x + 39, y + -2, z + 20, Block3, 0, 3);
		L.setBlock(world, x + 40, y + -2, z + 20, Block3, 0, 3);
		L.setBlock(world, x + 0, y + -2, z + 21, Block3, 0, 3);
		L.setBlock(world, x + 4, y + -2, z + 21, Block3, 0, 3);
		L.setBlock(world, x + 5, y + -2, z + 21, Block3, 0, 3);
		L.setBlock(world, x + 6, y + -2, z + 21, VB.water, 0, 3);
		L.setBlock(world, x + 7, y + -2, z + 21, VB.water, 0, 3);
		L.setBlock(world, x + 8, y + -2, z + 21, VB.water, 0, 3);
		L.setBlock(world, x + 9, y + -2, z + 21, VB.water, 0, 3);
		L.setBlock(world, x + 10, y + -2, z + 21, VB.water, 0, 3);
		L.setBlock(world, x + 11, y + -2, z + 21, Block3, 0, 3);
		L.setBlock(world, x + 12, y + -2, z + 21, Block3, 0, 3);
		L.setBlock(world, x + 16, y + -2, z + 21, Block3, 0, 3);
		L.setBlock(world, x + 17, y + -2, z + 21, Block3, 0, 3);
		L.setBlock(world, x + 18, y + -2, z + 21, Block3, 0, 3);
		L.setBlock(world, x + 19, y + -2, z + 21, Block3, 0, 3);
		L.setBlock(world, x + 20, y + -2, z + 21, Block3, 0, 3);
		L.setBlock(world, x + 21, y + -2, z + 21, Block3, 0, 3);
		L.setBlock(world, x + 22, y + -2, z + 21, Block3, 0, 3);
		L.setBlock(world, x + 23, y + -2, z + 21, Block3, 0, 3);
		L.setBlock(world, x + 24, y + -2, z + 21, Block3, 0, 3);
		L.setBlock(world, x + 25, y + -2, z + 21, Block3, 0, 3);
		L.setBlock(world, x + 26, y + -2, z + 21, Block3, 0, 3);
		L.setBlock(world, x + 27, y + -2, z + 21, Block3, 0, 3);
		L.setBlock(world, x + 28, y + -2, z + 21, Block3, 0, 3);
		L.setBlock(world, x + 29, y + -2, z + 21, Block3, 0, 3);
		L.setBlock(world, x + 30, y + -2, z + 21, Block3, 0, 3);
		L.setBlock(world, x + 31, y + -2, z + 21, Block3, 0, 3);
		L.setBlock(world, x + 32, y + -2, z + 21, Block3, 0, 3);
		L.setBlock(world, x + 33, y + -2, z + 21, Block3, 0, 3);
		L.setBlock(world, x + 34, y + -2, z + 21, Block3, 0, 3);
		L.setBlock(world, x + 35, y + -2, z + 21, Block3, 0, 3);
		L.setBlock(world, x + 36, y + -2, z + 21, Block3, 0, 3);
		L.setBlock(world, x + 37, y + -2, z + 21, Block3, 0, 3);
		L.setBlock(world, x + 38, y + -2, z + 21, Block3, 0, 3);
		L.setBlock(world, x + 39, y + -2, z + 21, Block3, 0, 3);
		L.setBlock(world, x + 40, y + -2, z + 21, Block3, 0, 3);
		L.setBlock(world, x + 0, y + -2, z + 22, Block3, 0, 3);
		L.setBlock(world, x + 4, y + -2, z + 22, Block3, 0, 3);
		L.setBlock(world, x + 5, y + -2, z + 22, VB.water, 0, 3);
		L.setBlock(world, x + 6, y + -2, z + 22, VB.water, 0, 3);
		L.setBlock(world, x + 7, y + -2, z + 22, VB.water, 0, 3);
		L.setBlock(world, x + 8, y + -2, z + 22, VB.water, 0, 3);
		L.setBlock(world, x + 9, y + -2, z + 22, VB.water, 0, 3);
		L.setBlock(world, x + 10, y + -2, z + 22, VB.water, 0, 3);
		L.setBlock(world, x + 11, y + -2, z + 22, VB.water, 0, 3);
		L.setBlock(world, x + 12, y + -2, z + 22, Block3, 0, 3);
		L.setBlock(world, x + 16, y + -2, z + 22, Block3, 0, 3);
		L.setBlock(world, x + 17, y + -2, z + 22, Block3, 0, 3);
		L.setBlock(world, x + 18, y + -2, z + 22, Block3, 0, 3);
		L.setBlock(world, x + 19, y + -2, z + 22, Block3, 0, 3);
		L.setBlock(world, x + 20, y + -2, z + 22, Block3, 0, 3);
		L.setBlock(world, x + 21, y + -2, z + 22, Block3, 0, 3);
		L.setBlock(world, x + 22, y + -2, z + 22, Block3, 0, 3);
		L.setBlock(world, x + 23, y + -2, z + 22, Block3, 0, 3);
		L.setBlock(world, x + 24, y + -2, z + 22, Block3, 0, 3);
		L.setBlock(world, x + 25, y + -2, z + 22, Block3, 0, 3);
		L.setBlock(world, x + 26, y + -2, z + 22, Block3, 0, 3);
		L.setBlock(world, x + 27, y + -2, z + 22, Block3, 0, 3);
		L.setBlock(world, x + 28, y + -2, z + 22, Block3, 0, 3);
		L.setBlock(world, x + 29, y + -2, z + 22, Block3, 0, 3);
		L.setBlock(world, x + 30, y + -2, z + 22, Block3, 0, 3);
		L.setBlock(world, x + 31, y + -2, z + 22, Block3, 0, 3);
		L.setBlock(world, x + 32, y + -2, z + 22, Block3, 0, 3);
		L.setBlock(world, x + 33, y + -2, z + 22, Block3, 0, 3);
		L.setBlock(world, x + 34, y + -2, z + 22, Block3, 0, 3);
		L.setBlock(world, x + 35, y + -2, z + 22, Block3, 0, 3);
		L.setBlock(world, x + 36, y + -2, z + 22, Block3, 0, 3);
		L.setBlock(world, x + 37, y + -2, z + 22, Block3, 0, 3);
		L.setBlock(world, x + 38, y + -2, z + 22, Block3, 0, 3);
		L.setBlock(world, x + 39, y + -2, z + 22, Block3, 0, 3);
		L.setBlock(world, x + 40, y + -2, z + 22, Block3, 0, 3);
		L.setBlock(world, x + 0, y + -2, z + 23, Block3, 0, 3);
		L.setBlock(world, x + 3, y + -2, z + 23, Block3, 0, 3);
		L.setBlock(world, x + 4, y + -2, z + 23, VB.water, 0, 3);
		L.setBlock(world, x + 5, y + -2, z + 23, VB.water, 0, 3);
		L.setBlock(world, x + 6, y + -2, z + 23, VB.water, 0, 3);
		L.setBlock(world, x + 7, y + -2, z + 23, VB.water, 0, 3);
		L.setBlock(world, x + 8, y + -2, z + 23, VB.water, 0, 3);
		L.setBlock(world, x + 9, y + -2, z + 23, VB.water, 0, 3);
		L.setBlock(world, x + 10, y + -2, z + 23, VB.water, 0, 3);
		L.setBlock(world, x + 11, y + -2, z + 23, VB.water, 0, 3);
		L.setBlock(world, x + 12, y + -2, z + 23, VB.water, 0, 3);
		L.setBlock(world, x + 13, y + -2, z + 23, Block3, 0, 3);
		L.setBlock(world, x + 16, y + -2, z + 23, Block3, 0, 3);
		L.setBlock(world, x + 17, y + -2, z + 23, Block3, 0, 3);
		L.setBlock(world, x + 18, y + -2, z + 23, Block3, 0, 3);
		L.setBlock(world, x + 19, y + -2, z + 23, Block3, 0, 3);
		L.setBlock(world, x + 20, y + -2, z + 23, Block3, 0, 3);
		L.setBlock(world, x + 21, y + -2, z + 23, Block3, 0, 3);
		L.setBlock(world, x + 22, y + -2, z + 23, Block3, 0, 3);
		L.setBlock(world, x + 23, y + -2, z + 23, Block3, 0, 3);
		L.setBlock(world, x + 24, y + -2, z + 23, Block3, 0, 3);
		L.setBlock(world, x + 25, y + -2, z + 23, Block3, 0, 3);
		L.setBlock(world, x + 26, y + -2, z + 23, Block3, 0, 3);
		L.setBlock(world, x + 27, y + -2, z + 23, Block3, 0, 3);
		L.setBlock(world, x + 28, y + -2, z + 23, Block3, 0, 3);
		L.setBlock(world, x + 29, y + -2, z + 23, Block3, 0, 3);
		L.setBlock(world, x + 30, y + -2, z + 23, Block3, 0, 3);
		L.setBlock(world, x + 31, y + -2, z + 23, Block3, 0, 3);
		L.setBlock(world, x + 32, y + -2, z + 23, Block3, 0, 3);
		L.setBlock(world, x + 33, y + -2, z + 23, Block3, 0, 3);
		L.setBlock(world, x + 34, y + -2, z + 23, Block3, 0, 3);
		L.setBlock(world, x + 35, y + -2, z + 23, Block3, 0, 3);
		L.setBlock(world, x + 36, y + -2, z + 23, Block3, 0, 3);
		L.setBlock(world, x + 37, y + -2, z + 23, Block3, 0, 3);
		L.setBlock(world, x + 38, y + -2, z + 23, Block3, 0, 3);
		L.setBlock(world, x + 39, y + -2, z + 23, Block3, 0, 3);
		L.setBlock(world, x + 40, y + -2, z + 23, Block3, 0, 3);
		L.setBlock(world, x + 0, y + -2, z + 24, Block3, 0, 3);
		L.setBlock(world, x + 3, y + -2, z + 24, Block3, 0, 3);
		L.setBlock(world, x + 4, y + -2, z + 24, VB.water, 0, 3);
		L.setBlock(world, x + 5, y + -2, z + 24, VB.water, 0, 3);
		L.setBlock(world, x + 6, y + -2, z + 24, VB.water, 0, 3);
		L.setBlock(world, x + 7, y + -2, z + 24, VB.water, 0, 3);
		L.setBlock(world, x + 8, y + -2, z + 24, VB.water, 0, 3);
		L.setBlock(world, x + 9, y + -2, z + 24, VB.water, 0, 3);
		L.setBlock(world, x + 10, y + -2, z + 24, VB.water, 0, 3);
		L.setBlock(world, x + 11, y + -2, z + 24, VB.water, 0, 3);
		L.setBlock(world, x + 12, y + -2, z + 24, VB.water, 0, 3);
		L.setBlock(world, x + 13, y + -2, z + 24, Block3, 0, 3);
		L.setBlock(world, x + 16, y + -2, z + 24, Block3, 0, 3);
		L.setBlock(world, x + 17, y + -2, z + 24, Block3, 0, 3);
		L.setBlock(world, x + 18, y + -2, z + 24, Block3, 0, 3);
		L.setBlock(world, x + 19, y + -2, z + 24, Block3, 0, 3);
		L.setBlock(world, x + 20, y + -2, z + 24, Block3, 0, 3);
		L.setBlock(world, x + 21, y + -2, z + 24, Block3, 0, 3);
		L.setBlock(world, x + 22, y + -2, z + 24, Block3, 0, 3);
		L.setBlock(world, x + 23, y + -2, z + 24, Block3, 0, 3);
		L.setBlock(world, x + 24, y + -2, z + 24, Block3, 0, 3);
		L.setBlock(world, x + 25, y + -2, z + 24, Block3, 0, 3);
		L.setBlock(world, x + 26, y + -2, z + 24, Block3, 0, 3);
		L.setBlock(world, x + 27, y + -2, z + 24, Block3, 0, 3);
		L.setBlock(world, x + 28, y + -2, z + 24, Block3, 0, 3);
		L.setBlock(world, x + 29, y + -2, z + 24, Block3, 0, 3);
		L.setBlock(world, x + 30, y + -2, z + 24, Block3, 0, 3);
		L.setBlock(world, x + 31, y + -2, z + 24, Block3, 0, 3);
		L.setBlock(world, x + 32, y + -2, z + 24, Block3, 0, 3);
		L.setBlock(world, x + 33, y + -2, z + 24, Block3, 0, 3);
		L.setBlock(world, x + 34, y + -2, z + 24, Block3, 0, 3);
		L.setBlock(world, x + 35, y + -2, z + 24, Block3, 0, 3);
		L.setBlock(world, x + 36, y + -2, z + 24, Block3, 0, 3);
		L.setBlock(world, x + 37, y + -2, z + 24, Block3, 0, 3);
		L.setBlock(world, x + 38, y + -2, z + 24, Block3, 0, 3);
		L.setBlock(world, x + 39, y + -2, z + 24, Block3, 0, 3);
		L.setBlock(world, x + 40, y + -2, z + 24, Block3, 0, 3);
		L.setBlock(world, x + 0, y + -2, z + 25, Block3, 0, 3);
		L.setBlock(world, x + 3, y + -2, z + 25, Block3, 0, 3);
		L.setBlock(world, x + 4, y + -2, z + 25, VB.water, 0, 3);
		L.setBlock(world, x + 5, y + -2, z + 25, VB.water, 0, 3);
		L.setBlock(world, x + 6, y + -2, z + 25, VB.water, 0, 3);
		L.setBlock(world, x + 7, y + -2, z + 25, VB.water, 0, 3);
		L.setBlock(world, x + 8, y + -2, z + 25, VB.water, 0, 3);
		L.setBlock(world, x + 9, y + -2, z + 25, VB.water, 0, 3);
		L.setBlock(world, x + 10, y + -2, z + 25, VB.water, 0, 3);
		L.setBlock(world, x + 11, y + -2, z + 25, VB.water, 0, 3);
		L.setBlock(world, x + 12, y + -2, z + 25, VB.water, 0, 3);
		L.setBlock(world, x + 13, y + -2, z + 25, Block3, 0, 3);
		L.setBlock(world, x + 16, y + -2, z + 25, Block3, 0, 3);
		L.setBlock(world, x + 17, y + -2, z + 25, Block3, 0, 3);
		L.setBlock(world, x + 18, y + -2, z + 25, Block3, 0, 3);
		L.setBlock(world, x + 19, y + -2, z + 25, Block3, 0, 3);
		L.setBlock(world, x + 20, y + -2, z + 25, Block3, 0, 3);
		L.setBlock(world, x + 21, y + -2, z + 25, Block3, 0, 3);
		L.setBlock(world, x + 22, y + -2, z + 25, Block3, 0, 3);
		L.setBlock(world, x + 23, y + -2, z + 25, Block3, 0, 3);
		L.setBlock(world, x + 24, y + -2, z + 25, Block3, 0, 3);
		L.setBlock(world, x + 25, y + -2, z + 25, Block3, 0, 3);
		L.setBlock(world, x + 26, y + -2, z + 25, Block3, 0, 3);
		L.setBlock(world, x + 27, y + -2, z + 25, Block3, 0, 3);
		L.setBlock(world, x + 28, y + -2, z + 25, Block3, 0, 3);
		L.setBlock(world, x + 29, y + -2, z + 25, Block3, 0, 3);
		L.setBlock(world, x + 30, y + -2, z + 25, Block3, 0, 3);
		L.setBlock(world, x + 31, y + -2, z + 25, Block3, 0, 3);
		L.setBlock(world, x + 32, y + -2, z + 25, Block3, 0, 3);
		L.setBlock(world, x + 33, y + -2, z + 25, Block3, 0, 3);
		L.setBlock(world, x + 34, y + -2, z + 25, Block3, 0, 3);
		L.setBlock(world, x + 35, y + -2, z + 25, Block3, 0, 3);
		L.setBlock(world, x + 36, y + -2, z + 25, Block3, 0, 3);
		L.setBlock(world, x + 37, y + -2, z + 25, Block3, 0, 3);
		L.setBlock(world, x + 38, y + -2, z + 25, Block3, 0, 3);
		L.setBlock(world, x + 39, y + -2, z + 25, Block3, 0, 3);
		L.setBlock(world, x + 40, y + -2, z + 25, Block3, 0, 3);
		L.setBlock(world, x + 0, y + -2, z + 26, Block3, 0, 3);
		L.setBlock(world, x + 3, y + -2, z + 26, Block3, 0, 3);
		L.setBlock(world, x + 4, y + -2, z + 26, VB.water, 0, 3);
		L.setBlock(world, x + 5, y + -2, z + 26, VB.water, 0, 3);
		L.setBlock(world, x + 6, y + -2, z + 26, VB.water, 0, 3);
		L.setBlock(world, x + 7, y + -2, z + 26, VB.water, 0, 3);
		L.setBlock(world, x + 8, y + -2, z + 26, VB.water, 0, 3);
		L.setBlock(world, x + 9, y + -2, z + 26, VB.water, 0, 3);
		L.setBlock(world, x + 10, y + -2, z + 26, VB.water, 0, 3);
		L.setBlock(world, x + 11, y + -2, z + 26, VB.water, 0, 3);
		L.setBlock(world, x + 12, y + -2, z + 26, VB.water, 0, 3);
		L.setBlock(world, x + 13, y + -2, z + 26, Block3, 0, 3);
		L.setBlock(world, x + 16, y + -2, z + 26, Block3, 0, 3);
		L.setBlock(world, x + 17, y + -2, z + 26, Block3, 0, 3);
		L.setBlock(world, x + 18, y + -2, z + 26, Block3, 0, 3);
		L.setBlock(world, x + 19, y + -2, z + 26, Block3, 0, 3);
		L.setBlock(world, x + 20, y + -2, z + 26, Block3, 0, 3);
		L.setBlock(world, x + 21, y + -2, z + 26, Block3, 0, 3);
		L.setBlock(world, x + 22, y + -2, z + 26, Block3, 0, 3);
		L.setBlock(world, x + 23, y + -2, z + 26, Block3, 0, 3);
		L.setBlock(world, x + 24, y + -2, z + 26, Block3, 0, 3);
		L.setBlock(world, x + 25, y + -2, z + 26, Block3, 0, 3);
		L.setBlock(world, x + 26, y + -2, z + 26, Block3, 0, 3);
		L.setBlock(world, x + 27, y + -2, z + 26, Block3, 0, 3);
		L.setBlock(world, x + 28, y + -2, z + 26, Block3, 0, 3);
		L.setBlock(world, x + 29, y + -2, z + 26, Block3, 0, 3);
		L.setBlock(world, x + 30, y + -2, z + 26, Block3, 0, 3);
		L.setBlock(world, x + 31, y + -2, z + 26, Block3, 0, 3);
		L.setBlock(world, x + 32, y + -2, z + 26, Block3, 0, 3);
		L.setBlock(world, x + 33, y + -2, z + 26, Block3, 0, 3);
		L.setBlock(world, x + 34, y + -2, z + 26, Block3, 0, 3);
		L.setBlock(world, x + 35, y + -2, z + 26, Block3, 0, 3);
		L.setBlock(world, x + 36, y + -2, z + 26, Block3, 0, 3);
		L.setBlock(world, x + 37, y + -2, z + 26, Block3, 0, 3);
		L.setBlock(world, x + 38, y + -2, z + 26, Block3, 0, 3);
		L.setBlock(world, x + 39, y + -2, z + 26, Block3, 0, 3);
		L.setBlock(world, x + 40, y + -2, z + 26, Block3, 0, 3);
		L.setBlock(world, x + 0, y + -2, z + 27, Block3, 0, 3);
		L.setBlock(world, x + 3, y + -2, z + 27, Block3, 0, 3);
		L.setBlock(world, x + 4, y + -2, z + 27, VB.water, 0, 3);
		L.setBlock(world, x + 5, y + -2, z + 27, VB.water, 0, 3);
		L.setBlock(world, x + 6, y + -2, z + 27, VB.water, 0, 3);
		L.setBlock(world, x + 7, y + -2, z + 27, VB.water, 0, 3);
		L.setBlock(world, x + 8, y + -2, z + 27, VB.water, 0, 3);
		L.setBlock(world, x + 9, y + -2, z + 27, VB.water, 0, 3);
		L.setBlock(world, x + 10, y + -2, z + 27, VB.water, 0, 3);
		L.setBlock(world, x + 11, y + -2, z + 27, VB.water, 0, 3);
		L.setBlock(world, x + 12, y + -2, z + 27, VB.water, 0, 3);
		L.setBlock(world, x + 13, y + -2, z + 27, Block3, 0, 3);
		L.setBlock(world, x + 16, y + -2, z + 27, Block3, 0, 3);
		L.setBlock(world, x + 17, y + -2, z + 27, Block3, 0, 3);
		L.setBlock(world, x + 18, y + -2, z + 27, Block3, 0, 3);
		L.setBlock(world, x + 19, y + -2, z + 27, Block3, 0, 3);
		L.setBlock(world, x + 20, y + -2, z + 27, Block3, 0, 3);
		L.setBlock(world, x + 21, y + -2, z + 27, Block3, 0, 3);
		L.setBlock(world, x + 22, y + -2, z + 27, Block3, 0, 3);
		L.setBlock(world, x + 23, y + -2, z + 27, Block3, 0, 3);
		L.setBlock(world, x + 24, y + -2, z + 27, Block3, 0, 3);
		L.setBlock(world, x + 25, y + -2, z + 27, Block3, 0, 3);
		L.setBlock(world, x + 26, y + -2, z + 27, Block3, 0, 3);
		L.setBlock(world, x + 27, y + -2, z + 27, Block3, 0, 3);
		L.setBlock(world, x + 28, y + -2, z + 27, Block3, 0, 3);
		L.setBlock(world, x + 29, y + -2, z + 27, Block3, 0, 3);
		L.setBlock(world, x + 30, y + -2, z + 27, Block3, 0, 3);
		L.setBlock(world, x + 31, y + -2, z + 27, Block3, 0, 3);
		L.setBlock(world, x + 32, y + -2, z + 27, Block3, 0, 3);
		L.setBlock(world, x + 33, y + -2, z + 27, Block3, 0, 3);
		L.setBlock(world, x + 34, y + -2, z + 27, Block3, 0, 3);
		L.setBlock(world, x + 35, y + -2, z + 27, Block3, 0, 3);
		L.setBlock(world, x + 36, y + -2, z + 27, Block3, 0, 3);
		L.setBlock(world, x + 37, y + -2, z + 27, Block3, 0, 3);
		L.setBlock(world, x + 38, y + -2, z + 27, Block3, 0, 3);
		L.setBlock(world, x + 39, y + -2, z + 27, Block3, 0, 3);
		L.setBlock(world, x + 40, y + -2, z + 27, Block3, 0, 3);
		L.setBlock(world, x + 0, y + -2, z + 28, Block3, 0, 3);
		L.setBlock(world, x + 4, y + -2, z + 28, Block3, 0, 3);
		L.setBlock(world, x + 5, y + -2, z + 28, VB.water, 0, 3);
		L.setBlock(world, x + 6, y + -2, z + 28, VB.water, 0, 3);
		L.setBlock(world, x + 7, y + -2, z + 28, VB.water, 0, 3);
		L.setBlock(world, x + 8, y + -2, z + 28, VB.water, 0, 3);
		L.setBlock(world, x + 9, y + -2, z + 28, VB.water, 0, 3);
		L.setBlock(world, x + 10, y + -2, z + 28, VB.water, 0, 3);
		L.setBlock(world, x + 11, y + -2, z + 28, VB.water, 0, 3);
		L.setBlock(world, x + 12, y + -2, z + 28, Block3, 0, 3);
		L.setBlock(world, x + 16, y + -2, z + 28, Block3, 0, 3);
		L.setBlock(world, x + 17, y + -2, z + 28, Block3, 0, 3);
		L.setBlock(world, x + 18, y + -2, z + 28, Block3, 0, 3);
		L.setBlock(world, x + 19, y + -2, z + 28, Block3, 0, 3);
		L.setBlock(world, x + 20, y + -2, z + 28, Block3, 0, 3);
		L.setBlock(world, x + 21, y + -2, z + 28, Block3, 0, 3);
		L.setBlock(world, x + 22, y + -2, z + 28, Block3, 0, 3);
		L.setBlock(world, x + 23, y + -2, z + 28, Block3, 0, 3);
		L.setBlock(world, x + 24, y + -2, z + 28, Block3, 0, 3);
		L.setBlock(world, x + 25, y + -2, z + 28, Block3, 0, 3);
		L.setBlock(world, x + 26, y + -2, z + 28, Block3, 0, 3);
		L.setBlock(world, x + 27, y + -2, z + 28, Block3, 0, 3);
		L.setBlock(world, x + 28, y + -2, z + 28, Block3, 0, 3);
		L.setBlock(world, x + 29, y + -2, z + 28, Block3, 0, 3);
		L.setBlock(world, x + 30, y + -2, z + 28, Block3, 0, 3);
		L.setBlock(world, x + 31, y + -2, z + 28, Block3, 0, 3);
		L.setBlock(world, x + 32, y + -2, z + 28, Block3, 0, 3);
		L.setBlock(world, x + 33, y + -2, z + 28, Block3, 0, 3);
		L.setBlock(world, x + 34, y + -2, z + 28, Block3, 0, 3);
		L.setBlock(world, x + 35, y + -2, z + 28, Block3, 0, 3);
		L.setBlock(world, x + 36, y + -2, z + 28, Block3, 0, 3);
		L.setBlock(world, x + 37, y + -2, z + 28, Block3, 0, 3);
		L.setBlock(world, x + 38, y + -2, z + 28, Block3, 0, 3);
		L.setBlock(world, x + 39, y + -2, z + 28, Block3, 0, 3);
		L.setBlock(world, x + 40, y + -2, z + 28, Block3, 0, 3);
		L.setBlock(world, x + 0, y + -2, z + 29, Block3, 0, 3);
		L.setBlock(world, x + 4, y + -2, z + 29, Block3, 0, 3);
		L.setBlock(world, x + 5, y + -2, z + 29, Block3, 0, 3);
		L.setBlock(world, x + 6, y + -2, z + 29, VB.water, 0, 3);
		L.setBlock(world, x + 7, y + -2, z + 29, VB.water, 0, 3);
		L.setBlock(world, x + 8, y + -2, z + 29, VB.water, 0, 3);
		L.setBlock(world, x + 9, y + -2, z + 29, VB.water, 0, 3);
		L.setBlock(world, x + 10, y + -2, z + 29, VB.water, 0, 3);
		L.setBlock(world, x + 11, y + -2, z + 29, Block3, 0, 3);
		L.setBlock(world, x + 12, y + -2, z + 29, Block3, 0, 3);
		L.setBlock(world, x + 40, y + -2, z + 29, Block3, 0, 3);
		L.setBlock(world, x + 0, y + -2, z + 30, Block3, 0, 3);
		L.setBlock(world, x + 6, y + -2, z + 30, Block3, 0, 3);
		L.setBlock(world, x + 7, y + -2, z + 30, Block3, 0, 3);
		L.setBlock(world, x + 8, y + -2, z + 30, Block3, 0, 3);
		L.setBlock(world, x + 9, y + -2, z + 30, Block3, 0, 3);
		L.setBlock(world, x + 10, y + -2, z + 30, Block3, 0, 3);
		L.setBlock(world, x + 40, y + -2, z + 30, Block3, 0, 3);
		L.setBlock(world, x + 0, y + -2, z + 31, Block3, 0, 3);
		L.setBlock(world, x + 16, y + -2, z + 31, Block3, 0, 3);
		L.setBlock(world, x + 17, y + -2, z + 31, Block3, 0, 3);
		L.setBlock(world, x + 18, y + -2, z + 31, Block3, 0, 3);
		L.setBlock(world, x + 19, y + -2, z + 31, Block3, 0, 3);
		L.setBlock(world, x + 20, y + -2, z + 31, Block3, 0, 3);
		L.setBlock(world, x + 21, y + -2, z + 31, Block3, 0, 3);
		L.setBlock(world, x + 22, y + -2, z + 31, Block3, 0, 3);
		L.setBlock(world, x + 23, y + -2, z + 31, Block3, 0, 3);
		L.setBlock(world, x + 24, y + -2, z + 31, Block3, 0, 3);
		L.setBlock(world, x + 25, y + -2, z + 31, Block3, 0, 3);
		L.setBlock(world, x + 26, y + -2, z + 31, Block3, 0, 3);
		L.setBlock(world, x + 27, y + -2, z + 31, Block3, 0, 3);
		L.setBlock(world, x + 28, y + -2, z + 31, Block3, 0, 3);
		L.setBlock(world, x + 29, y + -2, z + 31, Block3, 0, 3);
		L.setBlock(world, x + 30, y + -2, z + 31, Block3, 0, 3);
		L.setBlock(world, x + 31, y + -2, z + 31, Block3, 0, 3);
		L.setBlock(world, x + 32, y + -2, z + 31, Block3, 0, 3);
		L.setBlock(world, x + 33, y + -2, z + 31, Block3, 0, 3);
		L.setBlock(world, x + 34, y + -2, z + 31, Block3, 0, 3);
		L.setBlock(world, x + 35, y + -2, z + 31, Block3, 0, 3);
		L.setBlock(world, x + 36, y + -2, z + 31, Block3, 0, 3);
		L.setBlock(world, x + 37, y + -2, z + 31, Block3, 0, 3);
		L.setBlock(world, x + 38, y + -2, z + 31, Block3, 0, 3);
		L.setBlock(world, x + 39, y + -2, z + 31, Block3, 0, 3);
		L.setBlock(world, x + 40, y + -2, z + 31, Block3, 0, 3);
		L.setBlock(world, x + 0, y + -2, z + 32, Block3, 0, 3);
		L.setBlock(world, x + 16, y + -2, z + 32, Block3, 0, 3);
		L.setBlock(world, x + 0, y + -2, z + 33, Block3, 0, 3);
		L.setBlock(world, x + 1, y + -2, z + 33, Block3, 0, 3);
		L.setBlock(world, x + 2, y + -2, z + 33, Block3, 0, 3);
		L.setBlock(world, x + 3, y + -2, z + 33, Block3, 0, 3);
		L.setBlock(world, x + 4, y + -2, z + 33, Block3, 0, 3);
		L.setBlock(world, x + 5, y + -2, z + 33, Block3, 0, 3);
		L.setBlock(world, x + 6, y + -2, z + 33, Block3, 0, 3);
		L.setBlock(world, x + 7, y + -2, z + 33, Block3, 0, 3);
		L.setBlock(world, x + 8, y + -2, z + 33, Block3, 0, 3);
		L.setBlock(world, x + 9, y + -2, z + 33, Block3, 0, 3);
		L.setBlock(world, x + 10, y + -2, z + 33, Block3, 0, 3);
		L.setBlock(world, x + 11, y + -2, z + 33, Block3, 0, 3);
		L.setBlock(world, x + 12, y + -2, z + 33, Block3, 0, 3);
		L.setBlock(world, x + 13, y + -2, z + 33, Block3, 0, 3);
		L.setBlock(world, x + 14, y + -2, z + 33, Block3, 0, 3);
		L.setBlock(world, x + 15, y + -2, z + 33, Block3, 0, 3);
		L.setBlock(world, x + 16, y + -2, z + 33, Block3, 0, 3);
		L.setBlock(world, x + 0, y + -1, z + 0, Block3, 0, 3);
		L.setBlock(world, x + 1, y + -1, z + 0, Block3, 0, 3);
		L.setBlock(world, x + 2, y + -1, z + 0, Block3, 0, 3);
		L.setBlock(world, x + 3, y + -1, z + 0, Block3, 0, 3);
		L.setBlock(world, x + 4, y + -1, z + 0, Block3, 0, 3);
		L.setBlock(world, x + 5, y + -1, z + 0, Block3, 0, 3);
		L.setBlock(world, x + 6, y + -1, z + 0, Block3, 0, 3);

		new DesertAtom002().generate_r00(world, rand, x, y, z);
		return true;

	}
}