//Schematic to java Structure by jajo_11 | inspired by "MITHION'S.SCHEMATIC TO JAVA CONVERTINGTOOL"

package com.hbm_m.world.dungeon;

import java.util.Arrays;
import java.util.List;
import java.util.Random;

import com.hbm_m.config.GeneralConfig;
import com.hbm_m.itempool.ItemPool;
import com.hbm_m.main.MainRegistry;
import com.hbm_m.itempool.ItemPoolsComponent;
import com.hbm_m.itempool.ItemPoolsLegacy;
import com.hbm_m.itempool.ItemPoolsSingle;
import com.hbm_m.itempool.ItemPoolsPile;
import com.hbm_m.world.gen.legacy.L;
import com.hbm_m.world.gen.legacy.LB;
import com.hbm_m.world.gen.legacy.LMaterial;
import com.hbm_m.world.gen.legacy.MB;
import com.hbm_m.world.gen.legacy.MetaBlock;
import com.hbm_m.world.generator.DungeonToolbox;
import com.hbm_m.util.Vec3NT;
import com.hbm_m.world.gen.legacy.VB;

import net.minecraft.world.Container;
import net.minecraft.world.level.LevelAccessor;





/**
 * 1:1 {@code com.hbm.world.dungeon.DesertAtom003} (Original-Weltgen-Klasse, zeilengetreu auf die Port-Hilfen {@code L}/{@code MB}/{@code VB} umgesetzt).
 */
public class DesertAtom003
{
	LB Block2 = MB.yellow_barrel;
	LB Block3 = MB.reinforced_sand;
	LB Block4 = MB.nuke_man;
	LB Block5 = MB.deco_steel;
	LB Block6 = MB.brick_light;
	LB Block7 = MB.deco_tungsten;
	LB Block8 = MB.steel_poles;
	LB Block9 = MB.tape_recorder;
	LB Block10 = MB.machine_electric_furnace_off;
	LB Block11 = MB.reinforced_glass;
	LB Block12 = MB.reinforced_lamp_off;
	LB Block13 = MB.pole_satellite_receiver;
	LB Block14 = MB.pwr_fuel;
	LB Block15 = MB.deco_titanium;
	LB Block16 = MB.block_lead;
	LB Block17 = MB.ore_schrabidium;
	LB Block18 = MB.waste_planks;
	LB Block19 = MB.machine_centrifuge;
	LB Block20 = MB.machine_uf6_tank;
	LB Block21 = MB.machine_puf6_tank;
	LB Block22 = MB.reinforced_brick;
	LB Block23 = MB.waste_earth;
	LB Block24 = MB.deco_lead;
	LB Block25 = MB.red_wire_coated;
	LB Block26 = MB.block_uranium;
	LB Block27 = MB.pole_top;
	LB Block28 = MB.capacitor_copper;
	LB Block29 = MB.machine_electric_furnace_off;
	
	public boolean generate_r00(LevelAccessor world, Random rand, int x, int y, int z)
    {
		L.setBlock(world, x + 21, y + 3, z + 12, Block6, 0, 3);
		L.setBlock(world, x + 22, y + 3, z + 12, Block6, 0, 3);
		L.setBlock(world, x + 23, y + 3, z + 12, Block6, 0, 3);
		L.setBlock(world, x + 24, y + 3, z + 12, Block6, 0, 3);
		L.setBlock(world, x + 25, y + 3, z + 12, Block6, 0, 3);
		L.setBlock(world, x + 26, y + 3, z + 12, Block6, 0, 3);
		L.setBlock(world, x + 27, y + 3, z + 12, Block6, 0, 3);
		L.setBlock(world, x + 28, y + 3, z + 12, Block6, 0, 3);
		L.setBlock(world, x + 29, y + 3, z + 12, Block6, 0, 3);
		L.setBlock(world, x + 30, y + 3, z + 12, Block6, 0, 3);
		L.setBlock(world, x + 31, y + 3, z + 12, Block6, 0, 3);
		L.setBlock(world, x + 32, y + 3, z + 12, Block6, 0, 3);
		L.setBlock(world, x + 33, y + 3, z + 12, Block6, 0, 3);
		L.setBlock(world, x + 34, y + 3, z + 12, Block6, 0, 3);
		L.setBlock(world, x + 35, y + 3, z + 12, Block6, 0, 3);
		L.setBlock(world, x + 36, y + 3, z + 12, Block18, 0, 3);
		L.setBlock(world, x + 37, y + 3, z + 12, L.getRandomConcrete(), 0, 3);
		L.setBlock(world, x + 40, y + 3, z + 12, MB.barbed_wire, 0, 3);
		L.setBlock(world, x + 0, y + 3, z + 13, MB.barbed_wire, 0, 3);
		L.setBlock(world, x + 4, y + 3, z + 13, Block5, 0, 3);
		L.setBlock(world, x + 5, y + 3, z + 13, Block5, 0, 3);
		L.setBlock(world, x + 6, y + 3, z + 13, VB.water, 0, 3);
		L.setBlock(world, x + 7, y + 3, z + 13, Block16, 4, 3);
		L.setBlock(world, x + 8, y + 3, z + 13, Block14, 0, 3);
		L.setBlock(world, x + 9, y + 3, z + 13, Block16, 2, 3);
		L.setBlock(world, x + 10, y + 3, z + 13, VB.water, 0, 3);
		L.setBlock(world, x + 11, y + 3, z + 13, Block5, 0, 3);
		L.setBlock(world, x + 12, y + 3, z + 13, Block5, 0, 3);
		L.setBlock(world, x + 16, y + 3, z + 13, L.getRandomConcrete(), 0, 3);
		L.setBlock(world, x + 19, y + 3, z + 13, Block6, 0, 3);
		L.setBlock(world, x + 20, y + 3, z + 13, Block6, 0, 3);
		L.setBlock(world, x + 21, y + 3, z + 13, Block6, 0, 3);
		L.setBlock(world, x + 22, y + 3, z + 13, Block6, 0, 3);
		L.setBlock(world, x + 23, y + 3, z + 13, Block6, 0, 3);
		L.setBlock(world, x + 24, y + 3, z + 13, Block6, 0, 3);
		L.setBlock(world, x + 25, y + 3, z + 13, Block6, 0, 3);
		L.setBlock(world, x + 26, y + 3, z + 13, Block6, 0, 3);
		L.setBlock(world, x + 27, y + 3, z + 13, Block6, 0, 3);
		L.setBlock(world, x + 28, y + 3, z + 13, Block6, 0, 3);
		L.setBlock(world, x + 29, y + 3, z + 13, Block6, 0, 3);
		L.setBlock(world, x + 30, y + 3, z + 13, Block6, 0, 3);
		L.setBlock(world, x + 31, y + 3, z + 13, Block6, 0, 3);
		L.setBlock(world, x + 32, y + 3, z + 13, Block6, 0, 3);
		L.setBlock(world, x + 33, y + 3, z + 13, Block6, 0, 3);
		L.setBlock(world, x + 34, y + 3, z + 13, Block18, 0, 3);
		L.setBlock(world, x + 35, y + 3, z + 13, Block18, 0, 3);
		L.setBlock(world, x + 36, y + 3, z + 13, Block18, 0, 3);
		L.setBlock(world, x + 37, y + 3, z + 13, L.getRandomConcrete(), 0, 3);
		L.setBlock(world, x + 40, y + 3, z + 13, MB.barbed_wire, 0, 3);
		L.setBlock(world, x + 0, y + 3, z + 14, MB.barbed_wire, 0, 3);
		L.setBlock(world, x + 4, y + 3, z + 14, Block5, 0, 3);
		L.setBlock(world, x + 5, y + 3, z + 14, Block5, 0, 3);
		L.setBlock(world, x + 6, y + 3, z + 14, Block5, 0, 3);
		L.setBlock(world, x + 7, y + 3, z + 14, VB.water, 0, 3);
		L.setBlock(world, x + 8, y + 3, z + 14, Block5, 0, 3);
		L.setBlock(world, x + 9, y + 3, z + 14, VB.water, 0, 3);
		L.setBlock(world, x + 10, y + 3, z + 14, Block5, 0, 3);
		L.setBlock(world, x + 11, y + 3, z + 14, Block5, 0, 3);
		L.setBlock(world, x + 12, y + 3, z + 14, Block5, 0, 3);
		L.setBlock(world, x + 16, y + 3, z + 14, L.getRandomConcrete(), 0, 3);
		L.setBlock(world, x + 17, y + 3, z + 14, VB.vine, 2, 3);
		L.setBlock(world, x + 19, y + 3, z + 14, Block6, 0, 3);
		L.setBlock(world, x + 20, y + 3, z + 14, Block6, 0, 3);
		L.setBlock(world, x + 21, y + 3, z + 14, Block6, 0, 3);
		L.setBlock(world, x + 22, y + 3, z + 14, Block6, 0, 3);
		L.setBlock(world, x + 23, y + 3, z + 14, Block6, 0, 3);
		L.setBlock(world, x + 24, y + 3, z + 14, Block6, 0, 3);
		L.setBlock(world, x + 25, y + 3, z + 14, Block6, 0, 3);
		L.setBlock(world, x + 26, y + 3, z + 14, Block6, 0, 3);
		L.setBlock(world, x + 27, y + 3, z + 14, Block6, 0, 3);
		L.setBlock(world, x + 28, y + 3, z + 14, Block6, 0, 3);
		L.setBlock(world, x + 29, y + 3, z + 14, Block6, 0, 3);
		L.setBlock(world, x + 30, y + 3, z + 14, Block6, 0, 3);
		L.setBlock(world, x + 31, y + 3, z + 14, Block6, 0, 3);
		L.setBlock(world, x + 32, y + 3, z + 14, Block6, 0, 3);
		L.setBlock(world, x + 33, y + 3, z + 14, Block18, 0, 3);
		L.setBlock(world, x + 34, y + 3, z + 14, Block18, 0, 3);
		L.setBlock(world, x + 35, y + 3, z + 14, Block18, 0, 3);
		L.setBlock(world, x + 36, y + 3, z + 14, Block18, 0, 3);
		L.setBlock(world, x + 37, y + 3, z + 14, L.getRandomConcrete(), 0, 3);
		L.setBlock(world, x + 40, y + 3, z + 14, MB.barbed_wire, 0, 3);
		L.setBlock(world, x + 0, y + 3, z + 15, MB.barbed_wire, 0, 3);
		L.setBlock(world, x + 5, y + 3, z + 15, Block5, 0, 3);
		L.setBlock(world, x + 6, y + 3, z + 15, Block5, 0, 3);
		L.setBlock(world, x + 7, y + 3, z + 15, Block5, 0, 3);
		L.setBlock(world, x + 8, y + 3, z + 15, Block5, 0, 3);
		L.setBlock(world, x + 9, y + 3, z + 15, Block5, 0, 3);
		L.setBlock(world, x + 10, y + 3, z + 15, Block5, 0, 3);
		L.setBlock(world, x + 11, y + 3, z + 15, Block5, 0, 3);
		L.setBlock(world, x + 16, y + 3, z + 15, L.getRandomConcrete(), 0, 3);
		L.setBlock(world, x + 17, y + 3, z + 15, VB.stone_stairs, 2, 3);
		L.setBlock(world, x + 18, y + 3, z + 15, VB.stone_stairs, 2, 3);
		L.setBlock(world, x + 19, y + 3, z + 15, Block6, 0, 3);
		L.setBlock(world, x + 20, y + 3, z + 15, Block6, 0, 3);
		L.setBlock(world, x + 21, y + 3, z + 15, Block6, 0, 3);
		L.setBlock(world, x + 22, y + 3, z + 15, Block6, 0, 3);
		L.setBlock(world, x + 23, y + 3, z + 15, Block6, 0, 3);
		L.setBlock(world, x + 24, y + 3, z + 15, Block6, 0, 3);
		L.setBlock(world, x + 25, y + 3, z + 15, Block6, 0, 3);
		L.setBlock(world, x + 26, y + 3, z + 15, Block6, 0, 3);
		L.setBlock(world, x + 27, y + 3, z + 15, Block6, 0, 3);
		L.setBlock(world, x + 28, y + 3, z + 15, Block6, 0, 3);
		L.setBlock(world, x + 29, y + 3, z + 15, Block6, 0, 3);
		L.setBlock(world, x + 30, y + 3, z + 15, Block6, 0, 3);
		L.setBlock(world, x + 31, y + 3, z + 15, Block6, 0, 3);
		L.setBlock(world, x + 32, y + 3, z + 15, Block18, 0, 3);
		L.setBlock(world, x + 33, y + 3, z + 15, Block18, 0, 3);
		L.setBlock(world, x + 34, y + 3, z + 15, Block18, 0, 3);
		L.setBlock(world, x + 35, y + 3, z + 15, Block18, 0, 3);
		L.setBlock(world, x + 37, y + 3, z + 15, L.getRandomConcrete(), 0, 3);
		L.setBlock(world, x + 40, y + 3, z + 15, MB.barbed_wire, 0, 3);
		L.setBlock(world, x + 0, y + 3, z + 16, MB.barbed_wire, 0, 3);
		L.setBlock(world, x + 6, y + 3, z + 16, Block5, 0, 3);
		L.setBlock(world, x + 7, y + 3, z + 16, Block5, 0, 3);
		L.setBlock(world, x + 8, y + 3, z + 16, Block5, 0, 3);
		L.setBlock(world, x + 9, y + 3, z + 16, Block5, 0, 3);
		L.setBlock(world, x + 10, y + 3, z + 16, Block5, 0, 3);
		L.setBlock(world, x + 16, y + 3, z + 16, L.getRandomConcrete(), 0, 3);
		L.setBlock(world, x + 17, y + 3, z + 16, Block6, 0, 3);
		L.setBlock(world, x + 18, y + 3, z + 16, Block6, 0, 3);
		L.setBlock(world, x + 19, y + 3, z + 16, Block6, 0, 3);
		L.setBlock(world, x + 20, y + 3, z + 16, Block6, 0, 3);
		L.setBlock(world, x + 21, y + 3, z + 16, Block6, 0, 3);
		L.setBlock(world, x + 22, y + 3, z + 16, Block6, 0, 3);
		L.setBlock(world, x + 23, y + 3, z + 16, Block6, 0, 3);
		L.setBlock(world, x + 24, y + 3, z + 16, Block6, 0, 3);
		L.setBlock(world, x + 25, y + 3, z + 16, Block6, 0, 3);
		L.setBlock(world, x + 26, y + 3, z + 16, Block6, 0, 3);
		L.setBlock(world, x + 27, y + 3, z + 16, Block6, 0, 3);
		L.setBlock(world, x + 28, y + 3, z + 16, Block6, 0, 3);
		L.setBlock(world, x + 29, y + 3, z + 16, Block6, 0, 3);
		L.setBlock(world, x + 30, y + 3, z + 16, Block6, 0, 3);
		L.setBlock(world, x + 31, y + 3, z + 16, Block6, 0, 3);
		L.setBlock(world, x + 32, y + 3, z + 16, Block18, 0, 3);
		L.setBlock(world, x + 33, y + 3, z + 16, Block18, 0, 3);
		L.setBlock(world, x + 34, y + 3, z + 16, VB.vine, 4, 3);
		L.setBlock(world, x + 37, y + 3, z + 16, L.getRandomConcrete(), 0, 3);
		L.setBlock(world, x + 40, y + 3, z + 16, MB.barbed_wire, 0, 3);
		L.setBlock(world, x + 0, y + 3, z + 17, MB.barbed_wire, 0, 3);
		L.setBlock(world, x + 16, y + 3, z + 17, L.getRandomConcrete(), 0, 3);
		L.setBlock(world, x + 17, y + 3, z + 17, Block6, 0, 3);
		L.setBlock(world, x + 18, y + 3, z + 17, Block6, 0, 3);
		L.setBlock(world, x + 19, y + 3, z + 17, Block6, 0, 3);
		L.setBlock(world, x + 20, y + 3, z + 17, Block6, 0, 3);
		L.setBlock(world, x + 21, y + 3, z + 17, Block6, 0, 3);
		L.setBlock(world, x + 22, y + 3, z + 17, Block6, 0, 3);
		L.setBlock(world, x + 23, y + 3, z + 17, Block6, 0, 3);
		L.setBlock(world, x + 24, y + 3, z + 17, Block6, 0, 3);
		L.setBlock(world, x + 25, y + 3, z + 17, Block6, 0, 3);
		L.setBlock(world, x + 26, y + 3, z + 17, Block6, 0, 3);
		L.setBlock(world, x + 27, y + 3, z + 17, Block6, 0, 3);
		L.setBlock(world, x + 28, y + 3, z + 17, Block6, 0, 3);
		L.setBlock(world, x + 29, y + 3, z + 17, Block6, 0, 3);
		L.setBlock(world, x + 30, y + 3, z + 17, Block6, 0, 3);
		L.setBlock(world, x + 31, y + 3, z + 17, Block6, 0, 3);
		L.setBlock(world, x + 32, y + 3, z + 17, Block18, 0, 3);
		L.setBlock(world, x + 33, y + 3, z + 17, Block18, 0, 3);
		L.setBlock(world, x + 34, y + 3, z + 17, Block18, 0, 3);
		L.setBlock(world, x + 35, y + 3, z + 17, VB.vine, 2, 3);
		L.setBlock(world, x + 40, y + 3, z + 17, MB.barbed_wire, 0, 3);
		L.setBlock(world, x + 0, y + 3, z + 18, MB.barbed_wire, 0, 3);
		L.setBlock(world, x + 16, y + 3, z + 18, L.getRandomConcrete(), 0, 3);
		L.setBlock(world, x + 17, y + 3, z + 18, L.getRandomConcrete(), 0, 3);
		L.setBlock(world, x + 18, y + 3, z + 18, L.getRandomConcrete(), 0, 3);
		L.setBlock(world, x + 19, y + 3, z + 18, L.getRandomConcrete(), 0, 3);
		L.setBlock(world, x + 20, y + 3, z + 18, L.getRandomConcrete(), 0, 3);
		L.setBlock(world, x + 21, y + 3, z + 18, L.getRandomConcrete(), 0, 3);
		L.setBlock(world, x + 22, y + 3, z + 18, L.getRandomConcrete(), 0, 3);
		L.setBlock(world, x + 23, y + 3, z + 18, L.getRandomConcrete(), 0, 3);
		L.setBlock(world, x + 24, y + 3, z + 18, L.getRandomConcrete(), 0, 3);
		L.setBlock(world, x + 25, y + 3, z + 18, L.getRandomConcrete(), 0, 3);
		L.setBlock(world, x + 26, y + 3, z + 18, L.getRandomConcrete(), 0, 3);
		L.setBlock(world, x + 27, y + 3, z + 18, L.getRandomConcrete(), 0, 3);
		L.setBlock(world, x + 28, y + 3, z + 18, L.getRandomConcrete(), 0, 3);
		L.setBlock(world, x + 29, y + 3, z + 18, L.getRandomConcrete(), 0, 3);
		L.setBlock(world, x + 30, y + 3, z + 18, L.getRandomConcrete(), 0, 3);
		L.setBlock(world, x + 31, y + 3, z + 18, L.getRandomConcrete(), 0, 3);
		L.setBlock(world, x + 32, y + 3, z + 18, L.getRandomConcrete(), 0, 3);
		L.setBlock(world, x + 33, y + 3, z + 18, L.getRandomConcrete(), 0, 3);
		L.setBlock(world, x + 34, y + 3, z + 18, L.getRandomConcrete(), 0, 3);
		L.setBlock(world, x + 35, y + 3, z + 18, VB.gravel, 0, 3);
		L.setBlock(world, x + 36, y + 3, z + 18, VB.gravel, 0, 3);
		L.setBlock(world, x + 40, y + 3, z + 18, MB.barbed_wire, 0, 3);
		L.setBlock(world, x + 0, y + 3, z + 19, MB.barbed_wire, 0, 3);
		L.setBlock(world, x + 40, y + 3, z + 19, MB.barbed_wire, 0, 3);
		L.setBlock(world, x + 0, y + 3, z + 20, MB.barbed_wire, 0, 3);
		L.setBlock(world, x + 6, y + 3, z + 20, Block15, 0, 3);
		L.setBlock(world, x + 7, y + 3, z + 20, Block15, 0, 3);
		L.setBlock(world, x + 8, y + 3, z + 20, Block15, 0, 3);
		L.setBlock(world, x + 9, y + 3, z + 20, Block15, 0, 3);
		L.setBlock(world, x + 10, y + 3, z + 20, Block15, 0, 3);
		L.setBlock(world, x + 40, y + 3, z + 20, MB.barbed_wire, 0, 3);
		L.setBlock(world, x + 0, y + 3, z + 21, MB.barbed_wire, 0, 3);
		L.setBlock(world, x + 4, y + 3, z + 21, Block15, 0, 3);
		L.setBlock(world, x + 5, y + 3, z + 21, Block15, 0, 3);
		L.setBlock(world, x + 11, y + 3, z + 21, Block15, 0, 3);
		L.setBlock(world, x + 12, y + 3, z + 21, Block15, 0, 3);
		L.setBlock(world, x + 40, y + 3, z + 21, MB.barbed_wire, 0, 3);
		L.setBlock(world, x + 0, y + 3, z + 22, MB.barbed_wire, 0, 3);
		L.setBlock(world, x + 4, y + 3, z + 22, Block15, 0, 3);
		L.setBlock(world, x + 12, y + 3, z + 22, Block15, 0, 3);
		L.setBlock(world, x + 40, y + 3, z + 22, MB.barbed_wire, 0, 3);
		L.setBlock(world, x + 0, y + 3, z + 23, MB.barbed_wire, 0, 3);
		L.setBlock(world, x + 3, y + 3, z + 23, Block15, 0, 3);
		L.setBlock(world, x + 13, y + 3, z + 23, Block15, 0, 3);
		L.setBlock(world, x + 40, y + 3, z + 23, MB.barbed_wire, 0, 3);
		L.setBlock(world, x + 0, y + 3, z + 24, MB.barbed_wire, 0, 3);
		L.setBlock(world, x + 3, y + 3, z + 24, Block15, 0, 3);
		L.setBlock(world, x + 13, y + 3, z + 24, Block15, 0, 3);
		L.setBlock(world, x + 40, y + 3, z + 24, MB.barbed_wire, 0, 3);
		L.setBlock(world, x + 0, y + 3, z + 25, MB.barbed_wire, 0, 3);
		L.setBlock(world, x + 3, y + 3, z + 25, Block15, 0, 3);
		L.setBlock(world, x + 13, y + 3, z + 25, Block15, 0, 3);
		L.setBlock(world, x + 40, y + 3, z + 25, MB.barbed_wire, 0, 3);
		L.setBlock(world, x + 0, y + 3, z + 26, MB.barbed_wire, 0, 3);
		L.setBlock(world, x + 3, y + 3, z + 26, Block15, 0, 3);
		L.setBlock(world, x + 13, y + 3, z + 26, Block15, 0, 3);
		L.setBlock(world, x + 40, y + 3, z + 26, MB.barbed_wire, 0, 3);
		L.setBlock(world, x + 0, y + 3, z + 27, MB.barbed_wire, 0, 3);
		L.setBlock(world, x + 3, y + 3, z + 27, Block15, 0, 3);
		L.setBlock(world, x + 13, y + 3, z + 27, Block15, 0, 3);
		L.setBlock(world, x + 40, y + 3, z + 27, MB.barbed_wire, 0, 3);
		L.setBlock(world, x + 0, y + 3, z + 28, MB.barbed_wire, 0, 3);
		L.setBlock(world, x + 4, y + 3, z + 28, Block15, 0, 3);
		L.setBlock(world, x + 12, y + 3, z + 28, Block15, 0, 3);
		L.setBlock(world, x + 40, y + 3, z + 28, MB.barbed_wire, 0, 3);
		L.setBlock(world, x + 0, y + 3, z + 29, MB.barbed_wire, 0, 3);
		L.setBlock(world, x + 4, y + 3, z + 29, Block15, 0, 3);
		L.setBlock(world, x + 5, y + 3, z + 29, Block15, 0, 3);
		L.setBlock(world, x + 11, y + 3, z + 29, Block15, 0, 3);
		L.setBlock(world, x + 12, y + 3, z + 29, Block15, 0, 3);
		L.setBlock(world, x + 40, y + 3, z + 29, MB.barbed_wire, 0, 3);
		L.setBlock(world, x + 0, y + 3, z + 30, MB.barbed_wire, 0, 3);
		L.setBlock(world, x + 6, y + 3, z + 30, Block15, 0, 3);
		L.setBlock(world, x + 7, y + 3, z + 30, Block15, 0, 3);
		L.setBlock(world, x + 8, y + 3, z + 30, Block15, 0, 3);
		L.setBlock(world, x + 9, y + 3, z + 30, Block15, 0, 3);
		L.setBlock(world, x + 10, y + 3, z + 30, Block15, 0, 3);
		L.setBlock(world, x + 40, y + 3, z + 30, MB.barbed_wire, 0, 3);
		L.setBlock(world, x + 0, y + 3, z + 31, MB.barbed_wire, 0, 3);
		L.setBlock(world, x + 16, y + 3, z + 31, Block5, 0, 3);
		L.setBlock(world, x + 17, y + 3, z + 31, MB.barbed_wire, 0, 3);
		L.setBlock(world, x + 18, y + 3, z + 31, MB.barbed_wire, 0, 3);
		L.setBlock(world, x + 19, y + 3, z + 31, MB.barbed_wire, 0, 3);
		L.setBlock(world, x + 20, y + 3, z + 31, MB.barbed_wire, 0, 3);
		L.setBlock(world, x + 21, y + 3, z + 31, MB.barbed_wire, 0, 3);
		L.setBlock(world, x + 22, y + 3, z + 31, MB.barbed_wire, 0, 3);
		L.setBlock(world, x + 23, y + 3, z + 31, MB.barbed_wire, 0, 3);
		L.setBlock(world, x + 24, y + 3, z + 31, MB.barbed_wire, 0, 3);
		L.setBlock(world, x + 25, y + 3, z + 31, MB.barbed_wire, 0, 3);
		L.setBlock(world, x + 26, y + 3, z + 31, MB.barbed_wire, 0, 3);
		L.setBlock(world, x + 27, y + 3, z + 31, MB.barbed_wire, 0, 3);
		L.setBlock(world, x + 28, y + 3, z + 31, MB.barbed_wire, 0, 3);
		L.setBlock(world, x + 29, y + 3, z + 31, MB.barbed_wire, 0, 3);
		L.setBlock(world, x + 30, y + 3, z + 31, MB.barbed_wire, 0, 3);
		L.setBlock(world, x + 31, y + 3, z + 31, MB.barbed_wire, 0, 3);
		L.setBlock(world, x + 32, y + 3, z + 31, MB.barbed_wire, 0, 3);
		L.setBlock(world, x + 33, y + 3, z + 31, MB.barbed_wire, 0, 3);
		L.setBlock(world, x + 34, y + 3, z + 31, MB.barbed_wire, 0, 3);
		L.setBlock(world, x + 35, y + 3, z + 31, MB.barbed_wire, 0, 3);
		L.setBlock(world, x + 36, y + 3, z + 31, MB.barbed_wire, 0, 3);
		L.setBlock(world, x + 37, y + 3, z + 31, MB.barbed_wire, 0, 3);
		L.setBlock(world, x + 38, y + 3, z + 31, MB.barbed_wire, 0, 3);
		L.setBlock(world, x + 39, y + 3, z + 31, MB.barbed_wire, 0, 3);
		L.setBlock(world, x + 40, y + 3, z + 31, Block5, 0, 3);
		L.setBlock(world, x + 0, y + 3, z + 32, MB.barbed_wire, 0, 3);
		L.setBlock(world, x + 16, y + 3, z + 32, MB.barbed_wire, 0, 3);
		L.setBlock(world, x + 0, y + 3, z + 33, Block5, 0, 3);
		L.setBlock(world, x + 1, y + 3, z + 33, MB.barbed_wire, 0, 3);
		L.setBlock(world, x + 2, y + 3, z + 33, MB.barbed_wire, 0, 3);
		L.setBlock(world, x + 3, y + 3, z + 33, MB.barbed_wire, 0, 3);
		L.setBlock(world, x + 4, y + 3, z + 33, MB.barbed_wire, 0, 3);
		L.setBlock(world, x + 5, y + 3, z + 33, MB.barbed_wire, 0, 3);
		L.setBlock(world, x + 6, y + 3, z + 33, MB.barbed_wire, 0, 3);
		L.setBlock(world, x + 7, y + 3, z + 33, MB.barbed_wire, 0, 3);
		L.setBlock(world, x + 8, y + 3, z + 33, MB.barbed_wire, 0, 3);
		L.setBlock(world, x + 9, y + 3, z + 33, MB.barbed_wire, 0, 3);
		L.setBlock(world, x + 10, y + 3, z + 33, MB.barbed_wire, 0, 3);
		L.setBlock(world, x + 11, y + 3, z + 33, MB.barbed_wire, 0, 3);
		L.setBlock(world, x + 12, y + 3, z + 33, MB.barbed_wire, 0, 3);
		L.setBlock(world, x + 13, y + 3, z + 33, MB.barbed_wire, 0, 3);
		L.setBlock(world, x + 14, y + 3, z + 33, MB.barbed_wire, 0, 3);
		L.setBlock(world, x + 15, y + 3, z + 33, MB.barbed_wire, 0, 3);
		L.setBlock(world, x + 16, y + 3, z + 33, Block5, 0, 3);
		L.setBlock(world, x + 16, y + 4, z + 6, L.getRandomConcrete(), 0, 3);
		L.setBlock(world, x + 17, y + 4, z + 6, L.getRandomConcrete(), 0, 3);
		L.setBlock(world, x + 18, y + 4, z + 6, L.getRandomConcrete(), 0, 3);
		L.setBlock(world, x + 19, y + 4, z + 6, L.getRandomConcrete(), 0, 3);
		L.setBlock(world, x + 20, y + 4, z + 6, L.getRandomConcrete(), 0, 3);
		L.setBlock(world, x + 21, y + 4, z + 6, L.getRandomConcrete(), 0, 3);
		L.setBlock(world, x + 22, y + 4, z + 6, L.getRandomConcrete(), 0, 3);
		L.setBlock(world, x + 23, y + 4, z + 6, L.getRandomConcrete(), 0, 3);
		L.setBlock(world, x + 24, y + 4, z + 6, L.getRandomConcrete(), 0, 3);
		L.setBlock(world, x + 25, y + 4, z + 6, L.getRandomConcrete(), 0, 3);
		L.setBlock(world, x + 26, y + 4, z + 6, L.getRandomConcrete(), 0, 3);
		L.setBlock(world, x + 27, y + 4, z + 6, L.getRandomConcrete(), 0, 3);
		L.setBlock(world, x + 28, y + 4, z + 6, L.getRandomConcrete(), 0, 3);
		L.setBlock(world, x + 29, y + 4, z + 6, L.getRandomConcrete(), 0, 3);
		L.setBlock(world, x + 30, y + 4, z + 6, L.getRandomConcrete(), 0, 3);
		L.setBlock(world, x + 31, y + 4, z + 6, L.getRandomConcrete(), 0, 3);
		L.setBlock(world, x + 32, y + 4, z + 6, L.getRandomConcrete(), 0, 3);
		L.setBlock(world, x + 33, y + 4, z + 6, L.getRandomConcrete(), 0, 3);
		L.setBlock(world, x + 34, y + 4, z + 6, L.getRandomConcrete(), 0, 3);
		L.setBlock(world, x + 35, y + 4, z + 6, L.getRandomConcrete(), 0, 3);
		L.setBlock(world, x + 36, y + 4, z + 6, L.getRandomConcrete(), 0, 3);
		L.setBlock(world, x + 37, y + 4, z + 6, L.getRandomConcrete(), 0, 3);
		L.setBlock(world, x + 7, y + 4, z + 7, Block8, 2, 3);
		L.setBlock(world, x + 9, y + 4, z + 7, Block8, 2, 3);
		L.setBlock(world, x + 16, y + 4, z + 7, L.getRandomConcrete(), 0, 3);
		L.setBlock(world, x + 18, y + 4, z + 7, VB.vine, 4, 3);
		L.setBlock(world, x + 19, y + 4, z + 7, VB.vine, 4, 3);
		L.setBlock(world, x + 20, y + 4, z + 7, VB.vine, 4, 3);
		L.setBlock(world, x + 23, y + 4, z + 7, L.getRandomConcrete(), 0, 3);
		L.setBlock(world, x + 25, y + 4, z + 7, Block8, 3, 3);
		L.setBlock(world, x + 26, y + 4, z + 7, Block19, 12, 3);
		L.setBlock(world, x + 27, y + 4, z + 7, Block19, 12, 3);
		L.setBlock(world, x + 28, y + 4, z + 7, Block20, 3, 3);
		net.minecraft.world.level.block.entity.BlockEntity tank0 = L.getTileEntity(world, x + 28, y + 4, z + 7);
		L.setBlock(world, x + 29, y + 4, z + 7, Block20, 3, 3);
		L.getTileEntity(world, x + 29, y + 4, z + 7);
		L.setBlock(world, x + 30, y + 4, z + 7, Block21, 3, 3);
		L.getTileEntity(world, x + 30, y + 4, z + 7);
		L.setBlock(world, x + 31, y + 4, z + 7, Block21, 3, 3);
		net.minecraft.world.level.block.entity.BlockEntity tank3 = L.getTileEntity(world, x + 31, y + 4, z + 7);
		L.setBlock(world, x + 32, y + 4, z + 7, Block2, 0, 3);
		L.setBlock(world, x + 33, y + 4, z + 7, Block22, 0, 3);
		L.setBlock(world, x + 34, y + 4, z + 7, Block23, 0, 3);
		L.setBlock(world, x + 35, y + 4, z + 7, Block23, 0, 3);
		L.setBlock(world, x + 36, y + 4, z + 7, Block23, 0, 3);
		L.setBlock(world, x + 37, y + 4, z + 7, L.getRandomConcrete(), 0, 3);
		L.setBlock(world, x + 40, y + 4, z + 7, Block5, 0, 3);
		L.setBlock(world, x + 6, y + 4, z + 8, Block5, 0, 3);
		L.setBlock(world, x + 7, y + 4, z + 8, Block5, 0, 3);
		//L.setBlock(world, x + 8, y + 4, z + 8, VB.iron_door, 1, 3);
        L.placeDoorBlock(world, x + 8, y + 4, z + 8, 1, VB.iron_door);
		L.setBlock(world, x + 9, y + 4, z + 8, Block5, 0, 3);
		L.setBlock(world, x + 10, y + 4, z + 8, Block5, 0, 3);
		L.setBlock(world, x + 16, y + 4, z + 8, L.getRandomConcrete(), 0, 3);
		L.setBlock(world, x + 19, y + 4, z + 8, MB.fence_metal, 0, 3);
		L.setBlock(world, x + 23, y + 4, z + 8, L.getRandomConcrete(), 0, 3);
		L.setBlock(world, x + 24, y + 4, z + 8, Block12, 0, 3);
		L.setBlock(world, x + 26, y + 4, z + 8, VB.unpowered_repeater, 0, 3);
		L.setBlock(world, x + 27, y + 4, z + 8, VB.unpowered_repeater, 0, 3);
		L.setBlock(world, x + 31, y + 4, z + 8, VB.unpowered_repeater, 0, 3);
		L.setBlock(world, x + 32, y + 4, z + 8, Block2, 0, 3);
		L.setBlock(world, x + 33, y + 4, z + 8, Block22, 0, 3);
		L.setBlock(world, x + 34, y + 4, z + 8, Block22, 0, 3);
		L.setBlock(world, x + 35, y + 4, z + 8, Block22, 0, 3);
		L.setBlock(world, x + 36, y + 4, z + 8, Block22, 0, 3);
		L.setBlock(world, x + 37, y + 4, z + 8, L.getRandomConcrete(), 0, 3);
		L.setBlock(world, x + 40, y + 4, z + 8, Block5, 0, 3);
		L.setBlock(world, x + 5, y + 4, z + 9, Block5, 0, 3);
		L.setBlock(world, x + 6, y + 4, z + 9, Block2, 0, 3);
		L.setBlock(world, x + 7, y + 4, z + 9, Block2, 0, 3);
		L.setBlock(world, x + 10, y + 4, z + 9, Block2, 0, 3);
		L.setBlock(world, x + 11, y + 4, z + 9, Block5, 0, 3);
		L.setBlock(world, x + 16, y + 4, z + 9, L.getRandomConcrete(), 0, 3);
		L.setBlock(world, x + 17, y + 4, z + 9, VB.stone_stairs, 2, 3);
		L.setBlock(world, x + 18, y + 4, z + 9, VB.stone_stairs, 2, 3);
		L.setBlock(world, x + 19, y + 4, z + 9, MB.fence_metal, 0, 3);
		L.setBlock(world, x + 23, y + 4, z + 9, L.getRandomConcrete(), 0, 3);
		L.setBlock(world, x + 24, y + 4, z + 9, VB.redstone_wire, 0, 3);
		L.setBlock(world, x + 26, y + 4, z + 9, VB.redstone_wire, 0, 3);
		L.setBlock(world, x + 27, y + 4, z + 9, VB.redstone_wire, 0, 3);
		L.setBlock(world, x + 28, y + 4, z + 9, VB.redstone_wire, 0, 3);
		L.setBlock(world, x + 30, y + 4, z + 9, VB.redstone_wire, 0, 3);
		L.setBlock(world, x + 31, y + 4, z + 9, VB.redstone_wire, 0, 3);
		L.setBlock(world, x + 32, y + 4, z + 9, VB.unpowered_repeater, 1, 3);
		L.setBlock(world, x + 33, y + 4, z + 9, VB.redstone_wire, 0, 3);
		L.setBlock(world, x + 34, y + 4, z + 9, VB.redstone_wire, 0, 3);
		L.setBlock(world, x + 35, y + 4, z + 9, Block12, 0, 3);
		L.setBlock(world, x + 35, y + 5, z + 9, MB.geiger, 2, 3);
		L.setBlock(world, x + 36, y + 4, z + 9, VB.chest, 2, 3);
		if(L.getBlock(world, x + 36, y + 4, z + 9) == VB.chest)
		{
			ItemPool.generateChestContents(rand, ItemPool.getPool(ItemPoolsLegacy.POOL_NUKE_MISC), L.getTileEntity(world, x + 36, y + 4, z + 9), 12);
		}
        L.setBlock(world, x + 37, y + 4, z + 9, L.getRandomConcrete(), 0, 3);
		L.setBlock(world, x + 40, y + 4, z + 9, Block5, 0, 3);
		L.setBlock(world, x + 4, y + 4, z + 10, Block5, 0, 3);
		L.setBlock(world, x + 5, y + 4, z + 10, Block2, 0, 3);
		L.setBlock(world, x + 11, y + 4, z + 10, Block2, 0, 3);
		L.setBlock(world, x + 12, y + 4, z + 10, Block5, 0, 3);
		L.setBlock(world, x + 16, y + 4, z + 10, L.getRandomConcrete(), 0, 3);
		L.setBlock(world, x + 17, y + 4, z + 10, VB.stone_stairs, 7, 3);
		L.setBlock(world, x + 18, y + 4, z + 10, VB.stone_stairs, 7, 3);
		L.setBlock(world, x + 19, y + 4, z + 10, MB.fence_metal, 0, 3);
		L.setBlock(world, x + 20, y + 4, z + 10, VB.web, 0, 3);
		L.setBlock(world, x + 23, y + 4, z + 10, L.getRandomConcrete(), 0, 3);
		L.setBlock(world, x + 24, y + 4, z + 10, VB.redstone_wire, 0, 3);
		L.setBlock(world, x + 25, y + 4, z + 10, VB.redstone_wire, 0, 3);
		L.setBlock(world, x + 26, y + 4, z + 10, VB.redstone_wire, 0, 3);
		L.setBlock(world, x + 28, y + 4, z + 10, VB.redstone_wire, 0, 3);
		L.setBlock(world, x + 29, y + 4, z + 10, VB.redstone_wire, 0, 3);
		L.setBlock(world, x + 30, y + 4, z + 10, VB.redstone_wire, 0, 3);
		L.setBlock(world, x + 35, y + 4, z + 10, VB.redstone_wire, 0, 3);
		L.setBlock(world, x + 37, y + 4, z + 10, L.getRandomConcrete(), 0, 3);
		L.setBlock(world, x + 40, y + 4, z + 10, Block5, 0, 3);
		L.setBlock(world, x + 4, y + 4, z + 11, Block5, 0, 3);
		L.setBlock(world, x + 5, y + 4, z + 11, Block2, 0, 3);
		L.setBlock(world, x + 11, y + 4, z + 11, Block2, 0, 3);
		L.setBlock(world, x + 12, y + 4, z + 11, Block5, 0, 3);
		L.setBlock(world, x + 16, y + 4, z + 11, L.getRandomConcrete(), 0, 3);
		L.setBlock(world, x + 22, y + 4, z + 11, VB.vine, 8, 3);
		L.setBlock(world, x + 23, y + 4, z + 11, L.getRandomConcrete(), 0, 3);
		L.setBlock(world, x + 24, y + 4, z + 11, VB.redstone_wire, 0, 3);
		L.setBlock(world, x + 27, y + 4, z + 11, VB.redstone_wire, 0, 3);
		L.setBlock(world, x + 28, y + 4, z + 11, Block24, 0, 3);
		L.setBlock(world, x + 29, y + 4, z + 11, Block24, 0, 3);
		L.setBlock(world, x + 30, y + 4, z + 11, Block24, 0, 3);
		L.setBlock(world, x + 34, y + 4, z + 11, VB.redstone_wire, 0, 3);
		L.setBlock(world, x + 37, y + 4, z + 11, L.getRandomConcrete(), 0, 3);
		L.setBlock(world, x + 4, y + 4, z + 12, Block5, 0, 3);
		L.setBlock(world, x + 8, y + 4, z + 12, Block14, 0, 3);
		L.setBlock(world, x + 11, y + 4, z + 12, Block2, 0, 3);
		L.setBlock(world, x + 12, y + 4, z + 12, Block5, 0, 3);
		L.setBlock(world, x + 16, y + 4, z + 12, L.getRandomConcrete(), 0, 3);
		L.setBlock(world, x + 19, y + 4, z + 12, MB.fence_metal, 0, 3);
		L.setBlock(world, x + 22, y + 4, z + 12, VB.vine, 8, 3);
		L.setBlock(world, x + 23, y + 4, z + 12, L.getRandomConcrete(), 0, 3);
		L.setBlock(world, x + 24, y + 4, z + 12, VB.redstone_wire, 0, 3);
		L.setBlock(world, x + 27, y + 4, z + 12, VB.vine, 8, 3);
		L.setBlock(world, x + 28, y + 4, z + 12, Block24, 0, 3);
		L.setBlock(world, x + 29, y + 4, z + 12, Block24, 0, 3);
		L.setBlock(world, x + 30, y + 4, z + 12, Block24, 0, 3);
		L.setBlock(world, x + 31, y + 4, z + 12, VB.vine, 2, 3);
		L.setBlock(world, x + 32, y + 4, z + 12, VB.redstone_wire, 0, 3);
		L.setBlock(world, x + 36, y + 4, z + 12, VB.vine, 8, 3);
		L.setBlock(world, x + 37, y + 4, z + 12, L.getRandomConcrete(), 0, 3);
		L.setBlock(world, x + 4, y + 4, z + 13, Block5, 0, 3);
		L.setBlock(world, x + 5, y + 4, z + 13, Block2, 0, 3);
		L.setBlock(world, x + 12, y + 4, z + 13, Block5, 0, 3);
		L.setBlock(world, x + 16, y + 4, z + 13, L.getRandomConcrete(), 0, 3);
		L.setBlock(world, x + 17, y + 4, z + 13, VB.vine, 2, 3);
		L.setBlock(world, x + 19, y + 4, z + 13, MB.fence_metal, 0, 3);
		L.setBlock(world, x + 22, y + 4, z + 13, VB.vine, 8, 3);
		L.setBlock(world, x + 23, y + 4, z + 13, L.getRandomConcrete(), 0, 3);
		L.setBlock(world, x + 24, y + 4, z + 13, VB.redstone_wire, 0, 3);
		L.setBlock(world, x + 25, y + 4, z + 13, VB.redstone_wire, 0, 3);
		L.setBlock(world, x + 26, y + 4, z + 13, VB.redstone_wire, 0, 3);
		L.setBlock(world, x + 28, y + 4, z + 13, Block24, 0, 3);
		L.setBlock(world, x + 29, y + 4, z + 13, Block24, 0, 3);
		L.setBlock(world, x + 30, y + 4, z + 13, Block24, 0, 3);
		L.setBlock(world, x + 31, y + 4, z + 13, VB.web, 0, 3);
		L.setBlock(world, x + 36, y + 4, z + 13, VB.vine, 8, 3);
		L.setBlock(world, x + 37, y + 4, z + 13, L.getRandomConcrete(), 0, 3);
		L.setBlock(world, x + 4, y + 4, z + 14, Block5, 0, 3);
		L.setBlock(world, x + 12, y + 4, z + 14, Block5, 0, 3);
		L.setBlock(world, x + 16, y + 4, z + 14, L.getRandomConcrete(), 0, 3);
		L.setBlock(world, x + 17, y + 4, z + 14, VB.vine, 2, 3);
		L.setBlock(world, x + 19, y + 4, z + 14, MB.fence_metal, 0, 3);
		L.setBlock(world, x + 23, y + 4, z + 14, L.getRandomConcrete(), 0, 3);
		L.setBlock(world, x + 24, y + 4, z + 14, Block12, 0, 3);
		L.setBlock(world, x + 26, y + 4, z + 14, VB.redstone_wire, 0, 3);
		L.setBlock(world, x + 27, y + 4, z + 14, VB.redstone_wire, 0, 3);
		L.setBlock(world, x + 28, y + 4, z + 14, VB.redstone_wire, 0, 3);
		L.setBlock(world, x + 29, y + 4, z + 14, Block25, 0, 3);
		L.setBlock(world, x + 30, y + 4, z + 14, VB.web, 0, 3);
		L.setBlock(world, x + 31, y + 4, z + 14, VB.redstone_wire, 0, 3);
		L.setBlock(world, x + 37, y + 4, z + 14, L.getRandomConcrete(), 0, 3);
		L.setBlock(world, x + 5, y + 4, z + 15, Block5, 0, 3);
		L.setBlock(world, x + 8, y + 4, z + 15, Block2, 0, 3);
		L.setBlock(world, x + 9, y + 4, z + 15, Block2, 0, 3);
		L.setBlock(world, x + 10, y + 4, z + 15, Block2, 0, 3);
		L.setBlock(world, x + 11, y + 4, z + 15, Block5, 0, 3);
		L.setBlock(world, x + 16, y + 4, z + 15, L.getRandomConcrete(), 0, 3);
		L.setBlock(world, x + 19, y + 4, z + 15, MB.fence_metal, 0, 3);
		L.setBlock(world, x + 23, y + 4, z + 15, VB.iron_door, 0, 3);
        L.placeDoorBlock(world, x + 23, y + 4, z + 15, 0, VB.iron_door);
		L.setBlock(world, x + 24, y + 4, z + 15, VB.vine, 2, 3);
		L.setBlock(world, x + 27, y + 4, z + 15, VB.redstone_wire, 0, 3);
		L.setBlock(world, x + 30, y + 4, z + 15, VB.redstone_wire, 0, 3);
		L.setBlock(world, x + 31, y + 4, z + 15, VB.redstone_wire, 0, 3);
		L.setBlock(world, x + 37, y + 4, z + 15, L.getRandomConcrete(), 0, 3);
		L.setBlock(world, x + 6, y + 4, z + 16, Block5, 0, 3);
		L.setBlock(world, x + 7, y + 4, z + 16, Block5, 0, 3);
		L.setBlock(world, x + 8, y + 4, z + 16, Block5, 0, 3);
		L.setBlock(world, x + 9, y + 4, z + 16, Block5, 0, 3);
		L.setBlock(world, x + 10, y + 4, z + 16, Block5, 0, 3);
		L.setBlock(world, x + 16, y + 4, z + 16, L.getRandomConcrete(), 0, 3);
		L.setBlock(world, x + 22, y + 4, z + 16, VB.vine, 8, 3);
		//L.setBlock(world, x + 23, y + 4, z + 16, VB.iron_door, 3, 3);
        L.placeDoorBlock(world, x + 23, y + 4, z + 16, 3, VB.iron_door);
		L.setBlock(world, x + 26, y + 4, z + 16, VB.redstone_wire, 0, 3);
		L.setBlock(world, x + 29, y + 4, z + 16, VB.unpowered_repeater, 2, 3);
		L.setBlock(world, x + 37, y + 4, z + 16, VB.gravel, 0, 3);
		L.setBlock(world, x + 16, y + 4, z + 17, L.getRandomConcrete(), 0, 3);
		L.setBlock(world, x + 21, y + 4, z + 17, VB.vine, 1, 3);
		L.setBlock(world, x + 22, y + 4, z + 17, VB.vine, 8, 3);
		L.setBlock(world, x + 23, y + 4, z + 17, L.getRandomConcrete(), 0, 3);
		L.setBlock(world, x + 27, y + 4, z + 17, VB.vine, 1, 3);
		L.setBlock(world, x + 28, y + 4, z + 17, VB.vine, 9, 3);
		L.setBlock(world, x + 29, y + 4, z + 17, Block12, 0, 3);
		L.setBlock(world, x + 33, y + 4, z + 17, VB.vine, 3, 3);
		L.setBlock(world, x + 16, y + 4, z + 18, L.getRandomConcrete(), 0, 3);
		L.setBlock(world, x + 17, y + 4, z + 18, L.getRandomConcrete(), 0, 3);
		L.setBlock(world, x + 18, y + 4, z + 18, L.getRandomConcrete(), 0, 3);
		L.setBlock(world, x + 19, y + 4, z + 18, L.getRandomConcrete(), 0, 3);
		L.setBlock(world, x + 20, y + 4, z + 18, L.getRandomConcrete(), 0, 3);
		L.setBlock(world, x + 21, y + 4, z + 18, L.getRandomConcrete(), 0, 3);
		L.setBlock(world, x + 22, y + 4, z + 18, L.getRandomConcrete(), 0, 3);
		L.setBlock(world, x + 23, y + 4, z + 18, L.getRandomConcrete(), 0, 3);
		L.setBlock(world, x + 24, y + 4, z + 18, L.getRandomConcrete(), 0, 3);
		L.setBlock(world, x + 25, y + 4, z + 18, L.getRandomConcrete(), 0, 3);
		L.setBlock(world, x + 26, y + 4, z + 18, L.getRandomConcrete(), 0, 3);
		L.setBlock(world, x + 27, y + 4, z + 18, L.getRandomConcrete(), 0, 3);
		L.setBlock(world, x + 28, y + 4, z + 18, L.getRandomConcrete(), 0, 3);
		L.setBlock(world, x + 29, y + 4, z + 18, L.getRandomConcrete(), 0, 3);
		L.setBlock(world, x + 30, y + 4, z + 18, L.getRandomConcrete(), 0, 3);
		L.setBlock(world, x + 31, y + 4, z + 18, L.getRandomConcrete(), 0, 3);
		L.setBlock(world, x + 32, y + 4, z + 18, L.getRandomConcrete(), 0, 3);
		L.setBlock(world, x + 33, y + 4, z + 18, L.getRandomConcrete(), 0, 3);
		L.setBlock(world, x + 34, y + 4, z + 18, L.getRandomConcrete(), 0, 3);
		L.setBlock(world, x + 6, y + 4, z + 20, Block15, 0, 3);
		L.setBlock(world, x + 7, y + 4, z + 20, Block15, 0, 3);
		L.setBlock(world, x + 8, y + 4, z + 20, Block15, 0, 3);
		L.setBlock(world, x + 9, y + 4, z + 20, Block15, 0, 3);
		L.setBlock(world, x + 10, y + 4, z + 20, Block15, 0, 3);
		L.setBlock(world, x + 4, y + 4, z + 21, Block15, 0, 3);
		L.setBlock(world, x + 5, y + 4, z + 21, Block15, 0, 3);
		L.setBlock(world, x + 6, y + 4, z + 21, Block7, 0, 3);
		L.setBlock(world, x + 7, y + 4, z + 21, Block7, 0, 3);
		L.setBlock(world, x + 8, y + 4, z + 21, Block7, 0, 3);
		L.setBlock(world, x + 9, y + 4, z + 21, Block7, 0, 3);
		L.setBlock(world, x + 10, y + 4, z + 21, Block7, 0, 3);
		L.setBlock(world, x + 11, y + 4, z + 21, Block15, 0, 3);
		L.setBlock(world, x + 12, y + 4, z + 21, Block15, 0, 3);
		L.setBlock(world, x + 4, y + 4, z + 22, Block15, 0, 3);
		L.setBlock(world, x + 5, y + 4, z + 22, Block7, 0, 3);
		L.setBlock(world, x + 11, y + 4, z + 22, Block7, 0, 3);
		L.setBlock(world, x + 12, y + 4, z + 22, Block15, 0, 3);
		L.setBlock(world, x + 3, y + 4, z + 23, Block15, 0, 3);
		L.setBlock(world, x + 4, y + 4, z + 23, Block7, 0, 3);
		L.setBlock(world, x + 12, y + 4, z + 23, Block7, 0, 3);
		L.setBlock(world, x + 13, y + 4, z + 23, Block15, 0, 3);
		L.setBlock(world, x + 3, y + 4, z + 24, Block15, 0, 3);
		L.setBlock(world, x + 4, y + 4, z + 24, Block7, 0, 3);
		L.setBlock(world, x + 12, y + 4, z + 24, Block7, 0, 3);
		L.setBlock(world, x + 13, y + 4, z + 24, Block15, 0, 3);
		L.setBlock(world, x + 3, y + 4, z + 25, Block15, 0, 3);
		L.setBlock(world, x + 4, y + 4, z + 25, Block7, 0, 3);
		L.setBlock(world, x + 12, y + 4, z + 25, Block7, 0, 3);
		L.setBlock(world, x + 13, y + 4, z + 25, Block15, 0, 3);
		L.setBlock(world, x + 3, y + 4, z + 26, Block15, 0, 3);
		L.setBlock(world, x + 4, y + 4, z + 26, Block7, 0, 3);
		L.setBlock(world, x + 12, y + 4, z + 26, Block7, 0, 3);
		L.setBlock(world, x + 13, y + 4, z + 26, Block15, 0, 3);
		L.setBlock(world, x + 3, y + 4, z + 27, Block15, 0, 3);
		L.setBlock(world, x + 4, y + 4, z + 27, Block7, 0, 3);
		L.setBlock(world, x + 12, y + 4, z + 27, Block7, 0, 3);
		L.setBlock(world, x + 13, y + 4, z + 27, Block15, 0, 3);
		L.setBlock(world, x + 4, y + 4, z + 28, Block15, 0, 3);
		L.setBlock(world, x + 5, y + 4, z + 28, Block7, 0, 3);
		L.setBlock(world, x + 11, y + 4, z + 28, Block7, 0, 3);
		L.setBlock(world, x + 12, y + 4, z + 28, Block15, 0, 3);
		L.setBlock(world, x + 4, y + 4, z + 29, Block15, 0, 3);
		L.setBlock(world, x + 5, y + 4, z + 29, Block15, 0, 3);
		L.setBlock(world, x + 6, y + 4, z + 29, Block7, 0, 3);
		L.setBlock(world, x + 7, y + 4, z + 29, Block7, 0, 3);
		L.setBlock(world, x + 8, y + 4, z + 29, Block7, 0, 3);
		L.setBlock(world, x + 9, y + 4, z + 29, Block7, 0, 3);
		L.setBlock(world, x + 10, y + 4, z + 29, Block7, 0, 3);
		L.setBlock(world, x + 11, y + 4, z + 29, Block15, 0, 3);
		L.setBlock(world, x + 12, y + 4, z + 29, Block15, 0, 3);
		L.setBlock(world, x + 6, y + 4, z + 30, Block15, 0, 3);
		L.setBlock(world, x + 7, y + 4, z + 30, Block15, 0, 3);
		L.setBlock(world, x + 8, y + 4, z + 30, Block15, 0, 3);
		L.setBlock(world, x + 9, y + 4, z + 30, Block15, 0, 3);
		L.setBlock(world, x + 10, y + 4, z + 30, Block15, 0, 3);
		L.setBlock(world, x + 16, y + 5, z + 6, L.getRandomConcrete(), 0, 3);
		L.setBlock(world, x + 17, y + 5, z + 6, L.getRandomConcrete(), 0, 3);
		L.setBlock(world, x + 18, y + 5, z + 6, Block11, 0, 3);
		L.setBlock(world, x + 19, y + 5, z + 6, Block11, 0, 3);
		L.setBlock(world, x + 20, y + 5, z + 6, L.getRandomConcrete(), 0, 3);
		L.setBlock(world, x + 21, y + 5, z + 6, L.getRandomConcrete(), 0, 3);
		L.setBlock(world, x + 22, y + 5, z + 6, L.getRandomConcrete(), 0, 3);
		L.setBlock(world, x + 23, y + 5, z + 6, L.getRandomConcrete(), 0, 3);
		L.setBlock(world, x + 24, y + 5, z + 6, L.getRandomConcrete(), 0, 3);
		L.setBlock(world, x + 25, y + 5, z + 6, L.getRandomConcrete(), 0, 3);
		L.setBlock(world, x + 26, y + 5, z + 6, L.getRandomConcrete(), 0, 3);
		L.setBlock(world, x + 27, y + 5, z + 6, L.getRandomConcrete(), 0, 3);
		L.setBlock(world, x + 28, y + 5, z + 6, L.getRandomConcrete(), 0, 3);
		L.setBlock(world, x + 29, y + 5, z + 6, L.getRandomConcrete(), 0, 3);
		L.setBlock(world, x + 30, y + 5, z + 6, L.getRandomConcrete(), 0, 3);
		L.setBlock(world, x + 31, y + 5, z + 6, L.getRandomConcrete(), 0, 3);
		L.setBlock(world, x + 32, y + 5, z + 6, L.getRandomConcrete(), 0, 3);
		L.setBlock(world, x + 33, y + 5, z + 6, L.getRandomConcrete(), 0, 3);
		L.setBlock(world, x + 34, y + 5, z + 6, L.getRandomConcrete(), 0, 3);
		L.setBlock(world, x + 35, y + 5, z + 6, L.getRandomConcrete(), 0, 3);
		L.setBlock(world, x + 36, y + 5, z + 6, L.getRandomConcrete(), 0, 3);
		L.setBlock(world, x + 37, y + 5, z + 6, L.getRandomConcrete(), 0, 3);
		L.setBlock(world, x + 7, y + 5, z + 7, Block8, 2, 3);
		L.setBlock(world, x + 9, y + 5, z + 7, Block8, 2, 3);
		L.setBlock(world, x + 16, y + 5, z + 7, L.getRandomConcrete(), 0, 3);
		L.setBlock(world, x + 18, y + 5, z + 7, VB.vine, 4, 3);
		L.setBlock(world, x + 19, y + 5, z + 7, VB.vine, 4, 3);
		L.setBlock(world, x + 20, y + 5, z + 7, VB.vine, 4, 3);
		L.setBlock(world, x + 22, y + 5, z + 7, VB.web, 0, 3);
		L.setBlock(world, x + 23, y + 5, z + 7, L.getRandomConcrete(), 0, 3);
		L.setBlock(world, x + 25, y + 5, z + 7, Block8, 3, 3);
		L.setBlock(world, x + 30, y + 5, z + 7, VB.vine, 4, 3);
		L.setBlock(world, x + 32, y + 5, z + 7, Block2, 0, 3);
		L.setBlock(world, x + 33, y + 5, z + 7, Block11, 0, 3);
		L.setBlock(world, x + 37, y + 5, z + 7, L.getRandomConcrete(), 0, 3);
		L.setBlock(world, x + 6, y + 5, z + 8, Block5, 0, 3);
		L.setBlock(world, x + 7, y + 5, z + 8, Block5, 0, 3);
		//L.setBlock(world, x + 8, y + 5, z + 8, VB.iron_door, 8, 3);
		L.setBlock(world, x + 9, y + 5, z + 8, Block5, 0, 3);
		L.setBlock(world, x + 10, y + 5, z + 8, Block5, 0, 3);
		L.setBlock(world, x + 16, y + 5, z + 8, Block11, 0, 3);
		L.setBlock(world, x + 23, y + 5, z + 8, Block11, 0, 3);
		L.setBlock(world, x + 33, y + 5, z + 8, Block11, 0, 3);
		L.setBlock(world, x + 34, y + 5, z + 8, Block11, 0, 3);
		L.setBlock(world, x + 35, y + 5, z + 8, Block11, 0, 3);
		L.setBlock(world, x + 36, y + 5, z + 8, Block11, 0, 3);
		L.setBlock(world, x + 37, y + 5, z + 8, L.getRandomConcrete(), 0, 3);
		L.setBlock(world, x + 5, y + 5, z + 9, Block5, 0, 3);
		L.setBlock(world, x + 11, y + 5, z + 9, Block5, 0, 3);
		L.setBlock(world, x + 16, y + 5, z + 9, Block11, 0, 3);
		L.setBlock(world, x + 19, y + 5, z + 9, MB.fence_metal, 0, 3);
		L.setBlock(world, x + 23, y + 5, z + 9, Block11, 0, 3);
		L.setBlock(world, x + 33, y + 5, z + 9, VB.vine, 4, 3);
		L.setBlock(world, x + 37, y + 5, z + 9, L.getRandomConcrete(), 0, 3);
		L.setBlock(world, x + 4, y + 5, z + 10, Block5, 0, 3);
		L.setBlock(world, x + 12, y + 5, z + 10, Block5, 0, 3);
		L.setBlock(world, x + 16, y + 5, z + 10, L.getRandomConcrete(), 0, 3);
		L.setBlock(world, x + 17, y + 5, z + 10, VB.stone_stairs, 2, 3);
		L.setBlock(world, x + 18, y + 5, z + 10, VB.stone_stairs, 2, 3);
		L.setBlock(world, x + 19, y + 5, z + 10, MB.fence_metal, 0, 3);
		L.setBlock(world, x + 23, y + 5, z + 10, VB.web, 0, 3);
		L.setBlock(world, x + 37, y + 5, z + 10, L.getRandomConcrete(), 0, 3);
		L.setBlock(world, x + 4, y + 5, z + 11, Block5, 0, 3);
		L.setBlock(world, x + 12, y + 5, z + 11, Block5, 0, 3);
		L.setBlock(world, x + 16, y + 5, z + 11, L.getRandomConcrete(), 0, 3);
		L.setBlock(world, x + 17, y + 5, z + 11, VB.stone_stairs, 7, 3);
		L.setBlock(world, x + 18, y + 5, z + 11, VB.stone_stairs, 7, 3);
		L.setBlock(world, x + 19, y + 5, z + 11, MB.fence_metal, 0, 3);
		L.setBlock(world, x + 20, y + 5, z + 11, VB.web, 0, 3);
		L.setBlock(world, x + 23, y + 5, z + 11, Block11, 0, 3);
		L.setBlock(world, x + 27, y + 5, z + 11, VB.vine, 8, 3);
		L.setBlock(world, x + 28, y + 5, z + 11, Block16, 4, 3);
		L.setBlock(world, x + 29, y + 5, z + 11, Block16, 2, 3);
		L.setBlock(world, x + 30, y + 5, z + 11, Block16, 3, 3);
		L.setBlock(world, x + 37, y + 5, z + 11, L.getRandomConcrete(), 0, 3);
		L.setBlock(world, x + 4, y + 5, z + 12, Block5, 0, 3);
		L.setBlock(world, x + 8, y + 5, z + 12, Block25, 0, 3);
		L.setBlock(world, x + 12, y + 5, z + 12, Block5, 0, 3);
		L.setBlock(world, x + 16, y + 5, z + 12, L.getRandomConcrete(), 0, 3);
		L.setBlock(world, x + 17, y + 5, z + 12, VB.web, 0, 3);
		L.setBlock(world, x + 19, y + 5, z + 12, MB.fence_metal, 0, 3);
		L.setBlock(world, x + 22, y + 5, z + 12, VB.vine, 8, 3);
		L.setBlock(world, x + 24, y + 5, z + 12, VB.vine, 2, 3);
		L.setBlock(world, x + 27, y + 5, z + 12, VB.vine, 8, 3);
		L.setBlock(world, x + 28, y + 5, z + 12, Block16, 4, 3);
		L.setBlock(world, x + 29, y + 5, z + 12, Block26, 0, 3);
		L.setBlock(world, x + 30, y + 5, z + 12, Block16, 3, 3);
		L.setBlock(world, x + 31, y + 5, z + 12, VB.vine, 2, 3);
		L.setBlock(world, x + 36, y + 5, z + 12, VB.vine, 8, 3);
		L.setBlock(world, x + 37, y + 5, z + 12, L.getRandomConcrete(), 0, 3);
		L.setBlock(world, x + 4, y + 5, z + 13, Block5, 0, 3);
		L.setBlock(world, x + 12, y + 5, z + 13, Block5, 0, 3);
		L.setBlock(world, x + 16, y + 5, z + 13, L.getRandomConcrete(), 0, 3);
		L.setBlock(world, x + 17, y + 5, z + 13, VB.vine, 2, 3);
		L.setBlock(world, x + 19, y + 5, z + 13, MB.fence_metal, 0, 3);
		L.setBlock(world, x + 23, y + 5, z + 13, Block11, 0, 3);
		L.setBlock(world, x + 28, y + 5, z + 13, Block16, 3, 3);
		L.setBlock(world, x + 29, y + 5, z + 13, Block16, 3, 3);
		L.setBlock(world, x + 30, y + 5, z + 13, Block16, 3, 3);
		L.setBlock(world, x + 31, y + 5, z + 13, VB.web, 0, 3);
		L.setBlock(world, x + 35, y + 5, z + 13, VB.vine, 4, 3);
		L.setBlock(world, x + 36, y + 5, z + 13, VB.vine, 8, 3);
		L.setBlock(world, x + 37, y + 5, z + 13, L.getRandomConcrete(), 0, 3);
		L.setBlock(world, x + 4, y + 5, z + 14, Block5, 0, 3);
		L.setBlock(world, x + 12, y + 5, z + 14, Block5, 0, 3);
		L.setBlock(world, x + 16, y + 5, z + 14, L.getRandomConcrete(), 0, 3);
		L.setBlock(world, x + 17, y + 5, z + 14, VB.vine, 2, 3);
		L.setBlock(world, x + 23, y + 5, z + 14, L.getRandomConcrete(), 0, 3);
		L.setBlock(world, x + 24, y + 5, z + 14, VB.redstone_wire, 0, 3);
		L.setBlock(world, x + 27, y + 5, z + 14, VB.web, 0, 3);
		L.setBlock(world, x + 29, y + 5, z + 14, Block25, 0, 3);
		L.setBlock(world, x + 37, y + 5, z + 14, VB.gravel, 0, 3);
		L.setBlock(world, x + 5, y + 5, z + 15, Block5, 0, 3);
		L.setBlock(world, x + 11, y + 5, z + 15, Block5, 0, 3);
		L.setBlock(world, x + 16, y + 5, z + 15, Block11, 0, 3);
		L.setBlock(world, x + 17, y + 5, z + 15, VB.vine, 2, 3);
		//L.setBlock(world, x + 23, y + 5, z + 15, VB.iron_door, 8, 3);
		L.setBlock(world, x + 24, y + 5, z + 15, VB.vine, 2, 3);
		L.setBlock(world, x + 34, y + 5, z + 15, VB.vine, 2, 3);
		L.setBlock(world, x + 37, y + 5, z + 15, VB.gravel, 0, 3);
		L.setBlock(world, x + 6, y + 5, z + 16, Block5, 0, 3);
		L.setBlock(world, x + 7, y + 5, z + 16, Block5, 0, 3);
		L.setBlock(world, x + 8, y + 5, z + 16, Block5, 0, 3);
		L.setBlock(world, x + 9, y + 5, z + 16, Block5, 0, 3);
		L.setBlock(world, x + 10, y + 5, z + 16, Block5, 0, 3);
		L.setBlock(world, x + 16, y + 5, z + 16, Block11, 0, 3);
		L.setBlock(world, x + 22, y + 5, z + 16, VB.vine, 8, 3);
		//L.setBlock(world, x + 23, y + 5, z + 16, VB.iron_door, 8, 3);
		L.setBlock(world, x + 34, y + 5, z + 16, VB.vine, 2, 3);
		L.setBlock(world, x + 16, y + 5, z + 17, L.getRandomConcrete(), 0, 3);
		L.setBlock(world, x + 21, y + 5, z + 17, VB.vine, 1, 3);
		L.setBlock(world, x + 22, y + 5, z + 17, VB.vine, 8, 3);
		L.setBlock(world, x + 23, y + 5, z + 17, L.getRandomConcrete(), 0, 3);
		L.setBlock(world, x + 24, y + 5, z + 17, VB.web, 0, 3);
		L.setBlock(world, x + 27, y + 5, z + 17, VB.vine, 1, 3);
		L.setBlock(world, x + 28, y + 5, z + 17, VB.vine, 1, 3);
		L.setBlock(world, x + 33, y + 5, z + 17, VB.vine, 3, 3);
		L.setBlock(world, x + 16, y + 5, z + 18, L.getRandomConcrete(), 0, 3);
		L.setBlock(world, x + 17, y + 5, z + 18, L.getRandomConcrete(), 0, 3);
		L.setBlock(world, x + 18, y + 5, z + 18, L.getRandomConcrete(), 0, 3);
		L.setBlock(world, x + 19, y + 5, z + 18, L.getRandomConcrete(), 0, 3);
		L.setBlock(world, x + 20, y + 5, z + 18, L.getRandomConcrete(), 0, 3);
		L.setBlock(world, x + 21, y + 5, z + 18, L.getRandomConcrete(), 0, 3);
		L.setBlock(world, x + 22, y + 5, z + 18, L.getRandomConcrete(), 0, 3);
		L.setBlock(world, x + 23, y + 5, z + 18, L.getRandomConcrete(), 0, 3);
		L.setBlock(world, x + 24, y + 5, z + 18, L.getRandomConcrete(), 0, 3);
		L.setBlock(world, x + 25, y + 5, z + 18, L.getRandomConcrete(), 0, 3);
		L.setBlock(world, x + 26, y + 5, z + 18, L.getRandomConcrete(), 0, 3);
		L.setBlock(world, x + 27, y + 5, z + 18, L.getRandomConcrete(), 0, 3);
		L.setBlock(world, x + 28, y + 5, z + 18, L.getRandomConcrete(), 0, 3);
		L.setBlock(world, x + 29, y + 5, z + 18, L.getRandomConcrete(), 0, 3);
		L.setBlock(world, x + 30, y + 5, z + 18, L.getRandomConcrete(), 0, 3);
		L.setBlock(world, x + 31, y + 5, z + 18, L.getRandomConcrete(), 0, 3);
		L.setBlock(world, x + 32, y + 5, z + 18, L.getRandomConcrete(), 0, 3);
		L.setBlock(world, x + 33, y + 5, z + 18, L.getRandomConcrete(), 0, 3);
		L.setBlock(world, x + 34, y + 5, z + 18, L.getRandomConcrete(), 0, 3);
		L.setBlock(world, x + 6, y + 5, z + 21, Block15, 0, 3);
		L.setBlock(world, x + 7, y + 5, z + 21, Block15, 0, 3);
		L.setBlock(world, x + 8, y + 5, z + 21, Block15, 0, 3);
		L.setBlock(world, x + 9, y + 5, z + 21, Block15, 0, 3);
		L.setBlock(world, x + 10, y + 5, z + 21, Block15, 0, 3);
		L.setBlock(world, x + 5, y + 5, z + 22, Block15, 0, 3);
		L.setBlock(world, x + 11, y + 5, z + 22, Block15, 0, 3);
		L.setBlock(world, x + 4, y + 5, z + 23, Block15, 0, 3);
		L.setBlock(world, x + 12, y + 5, z + 23, Block15, 0, 3);
		L.setBlock(world, x + 4, y + 5, z + 24, Block15, 0, 3);
		L.setBlock(world, x + 12, y + 5, z + 24, Block15, 0, 3);
		L.setBlock(world, x + 4, y + 5, z + 25, Block15, 0, 3);
		L.setBlock(world, x + 12, y + 5, z + 25, Block15, 0, 3);
		L.setBlock(world, x + 4, y + 5, z + 26, Block15, 0, 3);
		L.setBlock(world, x + 12, y + 5, z + 26, Block15, 0, 3);
		L.setBlock(world, x + 4, y + 5, z + 27, Block15, 0, 3);
		L.setBlock(world, x + 12, y + 5, z + 27, Block15, 0, 3);
		L.setBlock(world, x + 5, y + 5, z + 28, Block15, 0, 3);
		L.setBlock(world, x + 11, y + 5, z + 28, Block15, 0, 3);
		L.setBlock(world, x + 6, y + 5, z + 29, Block15, 0, 3);
		L.setBlock(world, x + 7, y + 5, z + 29, Block15, 0, 3);
		L.setBlock(world, x + 8, y + 5, z + 29, Block15, 0, 3);
		L.setBlock(world, x + 9, y + 5, z + 29, Block15, 0, 3);
		L.setBlock(world, x + 10, y + 5, z + 29, Block15, 0, 3);
		L.setBlock(world, x + 16, y + 6, z + 6, L.getRandomConcrete(), 0, 3);
		L.setBlock(world, x + 17, y + 6, z + 6, L.getRandomConcrete(), 0, 3);
		L.setBlock(world, x + 18, y + 6, z + 6, L.getRandomConcrete(), 0, 3);
		L.setBlock(world, x + 19, y + 6, z + 6, L.getRandomConcrete(), 0, 3);
		L.setBlock(world, x + 20, y + 6, z + 6, L.getRandomConcrete(), 0, 3);
		L.setBlock(world, x + 21, y + 6, z + 6, L.getRandomConcrete(), 0, 3);
		L.setBlock(world, x + 22, y + 6, z + 6, L.getRandomConcrete(), 0, 3);
		L.setBlock(world, x + 23, y + 6, z + 6, L.getRandomConcrete(), 0, 3);
		L.setBlock(world, x + 24, y + 6, z + 6, L.getRandomConcrete(), 0, 3);
		L.setBlock(world, x + 25, y + 6, z + 6, L.getRandomConcrete(), 0, 3);
		L.setBlock(world, x + 26, y + 6, z + 6, L.getRandomConcrete(), 0, 3);
		L.setBlock(world, x + 27, y + 6, z + 6, L.getRandomConcrete(), 0, 3);
		L.setBlock(world, x + 28, y + 6, z + 6, L.getRandomConcrete(), 0, 3);
		L.setBlock(world, x + 29, y + 6, z + 6, L.getRandomConcrete(), 0, 3);
		L.setBlock(world, x + 30, y + 6, z + 6, L.getRandomConcrete(), 0, 3);
		L.setBlock(world, x + 31, y + 6, z + 6, L.getRandomConcrete(), 0, 3);
		L.setBlock(world, x + 32, y + 6, z + 6, L.getRandomConcrete(), 0, 3);
		L.setBlock(world, x + 33, y + 6, z + 6, L.getRandomConcrete(), 0, 3);
		L.setBlock(world, x + 34, y + 6, z + 6, L.getRandomConcrete(), 0, 3);
		L.setBlock(world, x + 35, y + 6, z + 6, L.getRandomConcrete(), 0, 3);
		L.setBlock(world, x + 36, y + 6, z + 6, L.getRandomConcrete(), 0, 3);
		L.setBlock(world, x + 37, y + 6, z + 6, L.getRandomConcrete(), 0, 3);
		L.setBlock(world, x + 7, y + 6, z + 7, Block5, 0, 3);
		L.setBlock(world, x + 8, y + 6, z + 7, Block5, 0, 3);
		L.setBlock(world, x + 9, y + 6, z + 7, Block5, 0, 3);
		L.setBlock(world, x + 16, y + 6, z + 7, L.getRandomConcrete(), 0, 3);
		L.setBlock(world, x + 18, y + 6, z + 7, VB.vine, 4, 3);
		L.setBlock(world, x + 19, y + 6, z + 7, VB.vine, 4, 3);
		L.setBlock(world, x + 20, y + 6, z + 7, VB.vine, 4, 3);
		L.setBlock(world, x + 21, y + 6, z + 7, VB.web, 0, 3);
		L.setBlock(world, x + 22, y + 6, z + 7, VB.web, 0, 3);
		L.setBlock(world, x + 23, y + 6, z + 7, L.getRandomConcrete(), 0, 3);
		L.setBlock(world, x + 24, y + 6, z + 7, VB.web, 0, 3);
		L.setBlock(world, x + 25, y + 6, z + 7, Block8, 3, 3);
		L.setBlock(world, x + 26, y + 6, z + 7, VB.web, 0, 3);
		L.setBlock(world, x + 27, y + 6, z + 7, VB.web, 0, 3);
		L.setBlock(world, x + 29, y + 6, z + 7, VB.web, 0, 3);
		L.setBlock(world, x + 30, y + 6, z + 7, VB.vine, 4, 3);
		L.setBlock(world, x + 31, y + 6, z + 7, VB.web, 0, 3);
		L.setBlock(world, x + 33, y + 6, z + 7, Block22, 0, 3);
		L.setBlock(world, x + 34, y + 6, z + 7, Block22, 0, 3);
		L.setBlock(world, x + 35, y + 6, z + 7, Block22, 0, 3);
		L.setBlock(world, x + 36, y + 6, z + 7, Block22, 0, 3);
		L.setBlock(world, x + 37, y + 6, z + 7, L.getRandomConcrete(), 0, 3);
		L.setBlock(world, x + 6, y + 6, z + 8, Block5, 0, 3);
		L.setBlock(world, x + 7, y + 6, z + 8, Block5, 0, 3);
		L.setBlock(world, x + 8, y + 6, z + 8, Block5, 0, 3);
		L.setBlock(world, x + 9, y + 6, z + 8, Block5, 0, 3);
		L.setBlock(world, x + 10, y + 6, z + 8, Block5, 0, 3);
		L.setBlock(world, x + 16, y + 6, z + 8, L.getRandomConcrete(), 0, 3);
		L.setBlock(world, x + 22, y + 6, z + 8, VB.web, 0, 3);
		L.setBlock(world, x + 23, y + 6, z + 8, L.getRandomConcrete(), 0, 3);
		L.setBlock(world, x + 26, y + 6, z + 8, VB.web, 0, 3);
		L.setBlock(world, x + 32, y + 6, z + 8, VB.web, 0, 3);
		L.setBlock(world, x + 33, y + 6, z + 8, Block22, 0, 3);
		L.setBlock(world, x + 34, y + 6, z + 8, Block22, 0, 3);
		L.setBlock(world, x + 35, y + 6, z + 8, Block22, 0, 3);
		L.setBlock(world, x + 36, y + 6, z + 8, Block22, 0, 3);
		L.setBlock(world, x + 37, y + 6, z + 8, L.getRandomConcrete(), 0, 3);
		L.setBlock(world, x + 5, y + 6, z + 9, Block5, 0, 3);
		L.setBlock(world, x + 6, y + 6, z + 9, Block5, 0, 3);
		L.setBlock(world, x + 7, y + 6, z + 9, Block5, 0, 3);
		L.setBlock(world, x + 8, y + 6, z + 9, Block5, 0, 3);
		L.setBlock(world, x + 9, y + 6, z + 9, Block5, 0, 3);
		L.setBlock(world, x + 10, y + 6, z + 9, Block5, 0, 3);
		L.setBlock(world, x + 11, y + 6, z + 9, Block5, 0, 3);
		L.setBlock(world, x + 16, y + 6, z + 9, L.getRandomConcrete(), 0, 3);
		L.setBlock(world, x + 23, y + 6, z + 9, L.getRandomConcrete(), 0, 3);
		L.setBlock(world, x + 25, y + 6, z + 9, VB.web, 0, 3);
		L.setBlock(world, x + 30, y + 6, z + 9, VB.web, 0, 3);
		L.setBlock(world, x + 33, y + 6, z + 9, VB.vine, 4, 3);
		L.setBlock(world, x + 35, y + 6, z + 9, VB.web, 0, 3);
		L.setBlock(world, x + 36, y + 6, z + 9, VB.web, 0, 3);
		L.setBlock(world, x + 37, y + 6, z + 9, L.getRandomConcrete(), 0, 3);
		L.setBlock(world, x + 4, y + 6, z + 10, Block5, 0, 3);
		L.setBlock(world, x + 5, y + 6, z + 10, Block5, 0, 3);
		L.setBlock(world, x + 6, y + 6, z + 10, Block5, 0, 3);
		L.setBlock(world, x + 10, y + 6, z + 10, Block5, 0, 3);
		L.setBlock(world, x + 11, y + 6, z + 10, Block5, 0, 3);
		L.setBlock(world, x + 12, y + 6, z + 10, Block5, 0, 3);
		L.setBlock(world, x + 16, y + 6, z + 10, L.getRandomConcrete(), 0, 3);
		L.setBlock(world, x + 19, y + 6, z + 10, MB.fence_metal, 0, 3);
		L.setBlock(world, x + 23, y + 6, z + 10, L.getRandomConcrete(), 0, 3);
		L.setBlock(world, x + 24, y + 6, z + 10, VB.web, 0, 3);
		L.setBlock(world, x + 30, y + 6, z + 10, VB.web, 0, 3);
		L.setBlock(world, x + 36, y + 6, z + 10, VB.web, 0, 3);
		L.setBlock(world, x + 37, y + 6, z + 10, L.getRandomConcrete(), 0, 3);
		L.setBlock(world, x + 4, y + 6, z + 11, Block5, 0, 3);
		L.setBlock(world, x + 5, y + 6, z + 11, Block5, 0, 3);
		L.setBlock(world, x + 11, y + 6, z + 11, Block5, 0, 3);
		L.setBlock(world, x + 12, y + 6, z + 11, Block5, 0, 3);
		L.setBlock(world, x + 16, y + 6, z + 11, L.getRandomConcrete(), 0, 3);
		L.setBlock(world, x + 17, y + 6, z + 11, VB.stone_stairs, 2, 3);
		L.setBlock(world, x + 18, y + 6, z + 11, VB.stone_stairs, 2, 3);
		L.setBlock(world, x + 19, y + 6, z + 11, MB.fence_metal, 0, 3);
		L.setBlock(world, x + 20, y + 6, z + 11, VB.web, 0, 3);
		L.setBlock(world, x + 23, y + 6, z + 11, L.getRandomConcrete(), 0, 3);
		L.setBlock(world, x + 27, y + 6, z + 11, VB.vine, 8, 3);
		L.setBlock(world, x + 28, y + 6, z + 11, Block24, 0, 3);
		L.setBlock(world, x + 29, y + 6, z + 11, Block24, 0, 3);
		L.setBlock(world, x + 30, y + 6, z + 11, Block24, 0, 3);
		L.setBlock(world, x + 31, y + 6, z + 11, VB.web, 0, 3);
		L.setBlock(world, x + 37, y + 6, z + 11, L.getRandomConcrete(), 0, 3);
		L.setBlock(world, x + 4, y + 6, z + 12, Block5, 0, 3);
		L.setBlock(world, x + 5, y + 6, z + 12, Block5, 0, 3);
		L.setBlock(world, x + 8, y + 6, z + 12, Block25, 0, 3);
		L.setBlock(world, x + 11, y + 6, z + 12, Block5, 0, 3);
		L.setBlock(world, x + 12, y + 6, z + 12, Block5, 0, 3);
		L.setBlock(world, x + 16, y + 6, z + 12, L.getRandomConcrete(), 0, 3);
		L.setBlock(world, x + 17, y + 6, z + 12, VB.stone_stairs, 7, 3);
		L.setBlock(world, x + 18, y + 6, z + 12, VB.stone_stairs, 7, 3);
		L.setBlock(world, x + 19, y + 6, z + 12, MB.fence_metal, 0, 3);
		L.setBlock(world, x + 20, y + 6, z + 12, VB.web, 0, 3);
		L.setBlock(world, x + 22, y + 6, z + 12, VB.vine, 8, 3);
		L.setBlock(world, x + 23, y + 6, z + 12, L.getRandomConcrete(), 0, 3);
		L.setBlock(world, x + 24, y + 6, z + 12, VB.vine, 2, 3);
		L.setBlock(world, x + 27, y + 6, z + 12, VB.vine, 8, 3);
		L.setBlock(world, x + 28, y + 6, z + 12, Block24, 0, 3);
		L.setBlock(world, x + 29, y + 6, z + 12, Block24, 0, 3);
		L.setBlock(world, x + 30, y + 6, z + 12, Block24, 0, 3);
		L.setBlock(world, x + 31, y + 6, z + 12, VB.vine, 2, 3);
		L.setBlock(world, x + 36, y + 6, z + 12, VB.vine, 8, 3);
		L.setBlock(world, x + 37, y + 6, z + 12, L.getRandomConcrete(), 0, 3);
		L.setBlock(world, x + 4, y + 6, z + 13, Block5, 0, 3);
		L.setBlock(world, x + 5, y + 6, z + 13, Block5, 0, 3);
		L.setBlock(world, x + 11, y + 6, z + 13, Block5, 0, 3);
		L.setBlock(world, x + 12, y + 6, z + 13, Block5, 0, 3);
		L.setBlock(world, x + 16, y + 6, z + 13, L.getRandomConcrete(), 0, 3);
		L.setBlock(world, x + 17, y + 6, z + 13, VB.web, 0, 3);
		L.setBlock(world, x + 23, y + 6, z + 13, L.getRandomConcrete(), 0, 3);
		L.setBlock(world, x + 27, y + 6, z + 13, VB.web, 0, 3);
		L.setBlock(world, x + 28, y + 6, z + 13, Block24, 0, 3);
		L.setBlock(world, x + 29, y + 6, z + 13, Block24, 0, 3);
		L.setBlock(world, x + 30, y + 6, z + 13, Block24, 0, 3);
		L.setBlock(world, x + 31, y + 6, z + 13, VB.vine, 2, 3);
		L.setBlock(world, x + 35, y + 6, z + 13, VB.vine, 4, 3);
		L.setBlock(world, x + 36, y + 6, z + 13, VB.vine, 8, 3);
		L.setBlock(world, x + 37, y + 6, z + 13, VB.gravel, 0, 3);
		L.setBlock(world, x + 4, y + 6, z + 14, Block5, 0, 3);
		L.setBlock(world, x + 5, y + 6, z + 14, Block5, 0, 3);
		L.setBlock(world, x + 6, y + 6, z + 14, Block5, 0, 3);
		L.setBlock(world, x + 10, y + 6, z + 14, Block5, 0, 3);
		L.setBlock(world, x + 11, y + 6, z + 14, Block5, 0, 3);
		L.setBlock(world, x + 12, y + 6, z + 14, Block5, 0, 3);
		L.setBlock(world, x + 16, y + 6, z + 14, L.getRandomConcrete(), 0, 3);
		L.setBlock(world, x + 17, y + 6, z + 14, VB.vine, 2, 3);
		L.setBlock(world, x + 23, y + 6, z + 14, L.getRandomConcrete(), 0, 3);
		L.setBlock(world, x + 24, y + 6, z + 14, VB.vine, 2, 3);
		L.setBlock(world, x + 26, y + 6, z + 14, VB.web, 0, 3);
		L.setBlock(world, x + 28, y + 6, z + 14, VB.web, 0, 3);
		L.setBlock(world, x + 29, y + 6, z + 14, Block25, 0, 3);
		L.setBlock(world, x + 5, y + 6, z + 15, Block5, 0, 3);
		L.setBlock(world, x + 6, y + 6, z + 15, Block5, 0, 3);
		L.setBlock(world, x + 7, y + 6, z + 15, Block5, 0, 3);
		L.setBlock(world, x + 8, y + 6, z + 15, Block5, 0, 3);
		L.setBlock(world, x + 9, y + 6, z + 15, Block5, 0, 3);
		L.setBlock(world, x + 10, y + 6, z + 15, Block5, 0, 3);
		L.setBlock(world, x + 11, y + 6, z + 15, Block5, 0, 3);
		L.setBlock(world, x + 16, y + 6, z + 15, L.getRandomConcrete(), 0, 3);
		L.setBlock(world, x + 17, y + 6, z + 15, VB.vine, 2, 3);
		L.setBlock(world, x + 23, y + 6, z + 15, L.getRandomConcrete(), 0, 3);
		L.setBlock(world, x + 24, y + 6, z + 15, VB.vine, 2, 3);
		L.setBlock(world, x + 27, y + 6, z + 15, VB.web, 0, 3);
		L.setBlock(world, x + 34, y + 6, z + 15, VB.vine, 2, 3);
		L.setBlock(world, x + 6, y + 6, z + 16, Block5, 0, 3);
		L.setBlock(world, x + 7, y + 6, z + 16, Block5, 0, 3);
		L.setBlock(world, x + 8, y + 6, z + 16, Block5, 0, 3);
		L.setBlock(world, x + 9, y + 6, z + 16, Block5, 0, 3);
		L.setBlock(world, x + 10, y + 6, z + 16, Block5, 0, 3);
		L.setBlock(world, x + 16, y + 6, z + 16, L.getRandomConcrete(), 0, 3);
		L.setBlock(world, x + 17, y + 6, z + 16, VB.web, 0, 3);
		L.setBlock(world, x + 22, y + 6, z + 16, VB.vine, 8, 3);
		L.setBlock(world, x + 23, y + 6, z + 16, L.getRandomConcrete(), 0, 3);
		L.setBlock(world, x + 24, y + 6, z + 16, VB.web, 0, 3);
		L.setBlock(world, x + 29, y + 6, z + 16, VB.web, 0, 3);
		L.setBlock(world, x + 34, y + 6, z + 16, VB.vine, 2, 3);
		L.setBlock(world, x + 16, y + 6, z + 17, L.getRandomConcrete(), 0, 3);
		L.setBlock(world, x + 17, y + 6, z + 17, VB.web, 0, 3);
		L.setBlock(world, x + 18, y + 6, z + 17, VB.web, 0, 3);
		L.setBlock(world, x + 20, y + 6, z + 17, VB.web, 0, 3);
		L.setBlock(world, x + 21, y + 6, z + 17, VB.vine, 1, 3);
		L.setBlock(world, x + 22, y + 6, z + 17, VB.vine, 8, 3);
		L.setBlock(world, x + 23, y + 6, z + 17, L.getRandomConcrete(), 0, 3);
		L.setBlock(world, x + 25, y + 6, z + 17, VB.web, 0, 3);
		L.setBlock(world, x + 27, y + 6, z + 17, VB.vine, 1, 3);
		L.setBlock(world, x + 28, y + 6, z + 17, VB.web, 0, 3);
		L.setBlock(world, x + 30, y + 6, z + 17, VB.web, 0, 3);
		L.setBlock(world, x + 33, y + 6, z + 17, VB.vine, 3, 3);
		L.setBlock(world, x + 16, y + 6, z + 18, L.getRandomConcrete(), 0, 3);
		L.setBlock(world, x + 17, y + 6, z + 18, L.getRandomConcrete(), 0, 3);
		L.setBlock(world, x + 18, y + 6, z + 18, L.getRandomConcrete(), 0, 3);
		L.setBlock(world, x + 19, y + 6, z + 18, L.getRandomConcrete(), 0, 3);
		L.setBlock(world, x + 20, y + 6, z + 18, L.getRandomConcrete(), 0, 3);
		L.setBlock(world, x + 21, y + 6, z + 18, L.getRandomConcrete(), 0, 3);
		L.setBlock(world, x + 22, y + 6, z + 18, L.getRandomConcrete(), 0, 3);
		L.setBlock(world, x + 23, y + 6, z + 18, L.getRandomConcrete(), 0, 3);
		L.setBlock(world, x + 24, y + 6, z + 18, L.getRandomConcrete(), 0, 3);
		L.setBlock(world, x + 25, y + 6, z + 18, L.getRandomConcrete(), 0, 3);
		L.setBlock(world, x + 26, y + 6, z + 18, L.getRandomConcrete(), 0, 3);
		L.setBlock(world, x + 27, y + 6, z + 18, L.getRandomConcrete(), 0, 3);
		L.setBlock(world, x + 28, y + 6, z + 18, L.getRandomConcrete(), 0, 3);
		L.setBlock(world, x + 29, y + 6, z + 18, L.getRandomConcrete(), 0, 3);
		L.setBlock(world, x + 30, y + 6, z + 18, L.getRandomConcrete(), 0, 3);
		L.setBlock(world, x + 31, y + 6, z + 18, L.getRandomConcrete(), 0, 3);
		L.setBlock(world, x + 32, y + 6, z + 18, L.getRandomConcrete(), 0, 3);
		L.setBlock(world, x + 33, y + 6, z + 18, L.getRandomConcrete(), 0, 3);
		L.setBlock(world, x + 34, y + 6, z + 18, VB.gravel, 0, 3);
		L.setBlock(world, x + 6, y + 6, z + 21, Block15, 0, 3);
		L.setBlock(world, x + 7, y + 6, z + 21, Block15, 0, 3);
		L.setBlock(world, x + 8, y + 6, z + 21, Block15, 0, 3);
		L.setBlock(world, x + 9, y + 6, z + 21, Block15, 0, 3);
		L.setBlock(world, x + 10, y + 6, z + 21, Block15, 0, 3);
		L.setBlock(world, x + 5, y + 6, z + 22, Block15, 0, 3);
		L.setBlock(world, x + 11, y + 6, z + 22, Block15, 0, 3);
		L.setBlock(world, x + 4, y + 6, z + 23, Block15, 0, 3);
		L.setBlock(world, x + 12, y + 6, z + 23, Block15, 0, 3);
		L.setBlock(world, x + 4, y + 6, z + 24, Block15, 0, 3);
		L.setBlock(world, x + 12, y + 6, z + 24, Block15, 0, 3);
		L.setBlock(world, x + 4, y + 6, z + 25, Block15, 0, 3);
		L.setBlock(world, x + 12, y + 6, z + 25, Block15, 0, 3);
		L.setBlock(world, x + 4, y + 6, z + 26, Block15, 0, 3);
		L.setBlock(world, x + 12, y + 6, z + 26, Block15, 0, 3);
		L.setBlock(world, x + 4, y + 6, z + 27, Block15, 0, 3);
		L.setBlock(world, x + 12, y + 6, z + 27, Block15, 0, 3);
		L.setBlock(world, x + 5, y + 6, z + 28, Block15, 0, 3);
		L.setBlock(world, x + 11, y + 6, z + 28, Block15, 0, 3);
		L.setBlock(world, x + 6, y + 6, z + 29, Block15, 0, 3);
		L.setBlock(world, x + 7, y + 6, z + 29, Block15, 0, 3);
		L.setBlock(world, x + 8, y + 6, z + 29, Block15, 0, 3);
		L.setBlock(world, x + 9, y + 6, z + 29, Block15, 0, 3);
		L.setBlock(world, x + 10, y + 6, z + 29, Block15, 0, 3);
		L.setBlock(world, x + 16, y + 7, z + 6, L.getRandomConcrete(), 0, 3);
		L.setBlock(world, x + 17, y + 7, z + 6, L.getRandomConcrete(), 0, 3);
		L.setBlock(world, x + 18, y + 7, z + 6, L.getRandomConcrete(), 0, 3);
		L.setBlock(world, x + 19, y + 7, z + 6, L.getRandomConcrete(), 0, 3);
		L.setBlock(world, x + 20, y + 7, z + 6, L.getRandomConcrete(), 0, 3);
		L.setBlock(world, x + 21, y + 7, z + 6, L.getRandomConcrete(), 0, 3);
		L.setBlock(world, x + 22, y + 7, z + 6, L.getRandomConcrete(), 0, 3);
		L.setBlock(world, x + 23, y + 7, z + 6, L.getRandomConcrete(), 0, 3);
		L.setBlock(world, x + 24, y + 7, z + 6, L.getRandomConcrete(), 0, 3);
		L.setBlock(world, x + 25, y + 7, z + 6, L.getRandomConcrete(), 0, 3);
		L.setBlock(world, x + 26, y + 7, z + 6, L.getRandomConcrete(), 0, 3);
		L.setBlock(world, x + 27, y + 7, z + 6, L.getRandomConcrete(), 0, 3);
		L.setBlock(world, x + 28, y + 7, z + 6, L.getRandomConcrete(), 0, 3);
		L.setBlock(world, x + 29, y + 7, z + 6, L.getRandomConcrete(), 0, 3);
		L.setBlock(world, x + 30, y + 7, z + 6, L.getRandomConcrete(), 0, 3);
		L.setBlock(world, x + 31, y + 7, z + 6, L.getRandomConcrete(), 0, 3);
		L.setBlock(world, x + 32, y + 7, z + 6, L.getRandomConcrete(), 0, 3);
		L.setBlock(world, x + 33, y + 7, z + 6, L.getRandomConcrete(), 0, 3);
		L.setBlock(world, x + 34, y + 7, z + 6, L.getRandomConcrete(), 0, 3);
		L.setBlock(world, x + 35, y + 7, z + 6, L.getRandomConcrete(), 0, 3);
		L.setBlock(world, x + 36, y + 7, z + 6, L.getRandomConcrete(), 0, 3);
		L.setBlock(world, x + 16, y + 7, z + 7, L.getRandomConcrete(), 0, 3);
		L.setBlock(world, x + 19, y + 7, z + 7, Block6, 0, 3);
		L.setBlock(world, x + 20, y + 7, z + 7, Block6, 0, 3);
		L.setBlock(world, x + 21, y + 7, z + 7, Block6, 0, 3);
		L.setBlock(world, x + 22, y + 7, z + 7, Block6, 0, 3);
		L.setBlock(world, x + 23, y + 7, z + 7, Block6, 0, 3);
		L.setBlock(world, x + 24, y + 7, z + 7, Block6, 0, 3);
		L.setBlock(world, x + 25, y + 7, z + 7, Block6, 0, 3);
		L.setBlock(world, x + 26, y + 7, z + 7, Block6, 0, 3);
		L.setBlock(world, x + 27, y + 7, z + 7, Block6, 0, 3);
		L.setBlock(world, x + 28, y + 7, z + 7, Block6, 0, 3);
		L.setBlock(world, x + 29, y + 7, z + 7, Block6, 0, 3);
		L.setBlock(world, x + 30, y + 7, z + 7, Block6, 0, 3);
		L.setBlock(world, x + 31, y + 7, z + 7, Block6, 0, 3);
		L.setBlock(world, x + 32, y + 7, z + 7, Block6, 0, 3);
		L.setBlock(world, x + 33, y + 7, z + 7, Block6, 0, 3);
		L.setBlock(world, x + 34, y + 7, z + 7, Block6, 0, 3);
		L.setBlock(world, x + 35, y + 7, z + 7, Block6, 0, 3);
		L.setBlock(world, x + 36, y + 7, z + 7, Block6, 0, 3);
		L.setBlock(world, x + 37, y + 7, z + 7, L.getRandomConcrete(), 0, 3);
		L.setBlock(world, x + 16, y + 7, z + 8, L.getRandomConcrete(), 0, 3);
		L.setBlock(world, x + 19, y + 7, z + 8, Block6, 0, 3);
		L.setBlock(world, x + 20, y + 7, z + 8, Block6, 0, 3);
		L.setBlock(world, x + 21, y + 7, z + 8, Block6, 0, 3);
		L.setBlock(world, x + 22, y + 7, z + 8, Block6, 0, 3);
		L.setBlock(world, x + 23, y + 7, z + 8, Block6, 0, 3);
		L.setBlock(world, x + 24, y + 7, z + 8, Block6, 0, 3);
		L.setBlock(world, x + 25, y + 7, z + 8, Block6, 0, 3);
		L.setBlock(world, x + 26, y + 7, z + 8, Block6, 0, 3);
		L.setBlock(world, x + 27, y + 7, z + 8, Block6, 0, 3);
		L.setBlock(world, x + 28, y + 7, z + 8, Block6, 0, 3);
		L.setBlock(world, x + 29, y + 7, z + 8, Block6, 0, 3);
		L.setBlock(world, x + 30, y + 7, z + 8, Block6, 0, 3);
		L.setBlock(world, x + 31, y + 7, z + 8, Block6, 0, 3);
		L.setBlock(world, x + 32, y + 7, z + 8, Block6, 0, 3);
		L.setBlock(world, x + 33, y + 7, z + 8, Block6, 0, 3);
		L.setBlock(world, x + 34, y + 7, z + 8, Block6, 0, 3);
		L.setBlock(world, x + 35, y + 7, z + 8, Block6, 0, 3);
		L.setBlock(world, x + 36, y + 7, z + 8, Block6, 0, 3);
		L.setBlock(world, x + 37, y + 7, z + 8, L.getRandomConcrete(), 0, 3);
		L.setBlock(world, x + 6, y + 7, z + 9, Block5, 0, 3);
		L.setBlock(world, x + 7, y + 7, z + 9, Block5, 0, 3);
		L.setBlock(world, x + 8, y + 7, z + 9, Block5, 0, 3);
		L.setBlock(world, x + 9, y + 7, z + 9, Block5, 0, 3);
		L.setBlock(world, x + 10, y + 7, z + 9, Block5, 0, 3);
		L.setBlock(world, x + 16, y + 7, z + 9, L.getRandomConcrete(), 0, 3);
		L.setBlock(world, x + 19, y + 7, z + 9, Block6, 0, 3);
		L.setBlock(world, x + 20, y + 7, z + 9, Block25, 0, 3);
		L.setBlock(world, x + 21, y + 7, z + 9, Block25, 0, 3);
		L.setBlock(world, x + 22, y + 7, z + 9, Block25, 0, 3);
		L.setBlock(world, x + 23, y + 7, z + 9, Block25, 0, 3);
		L.setBlock(world, x + 24, y + 7, z + 9, Block6, 0, 3);
		L.setBlock(world, x + 25, y + 7, z + 9, Block6, 0, 3);
		L.setBlock(world, x + 26, y + 7, z + 9, Block6, 0, 3);
		L.setBlock(world, x + 27, y + 7, z + 9, Block6, 0, 3);
		L.setBlock(world, x + 28, y + 7, z + 9, Block6, 0, 3);
		L.setBlock(world, x + 29, y + 7, z + 9, Block6, 0, 3);
		L.setBlock(world, x + 30, y + 7, z + 9, Block6, 0, 3);
		L.setBlock(world, x + 31, y + 7, z + 9, Block6, 0, 3);
		L.setBlock(world, x + 32, y + 7, z + 9, Block6, 0, 3);
		L.setBlock(world, x + 33, y + 7, z + 9, Block6, 0, 3);
		L.setBlock(world, x + 34, y + 7, z + 9, Block6, 0, 3);
		L.setBlock(world, x + 35, y + 7, z + 9, Block6, 0, 3);
		L.setBlock(world, x + 36, y + 7, z + 9, Block6, 0, 3);
		L.setBlock(world, x + 37, y + 7, z + 9, L.getRandomConcrete(), 0, 3);
		L.setBlock(world, x + 5, y + 7, z + 10, Block5, 0, 3);
		L.setBlock(world, x + 6, y + 7, z + 10, Block5, 0, 3);
		L.setBlock(world, x + 10, y + 7, z + 10, Block5, 0, 3);
		L.setBlock(world, x + 11, y + 7, z + 10, Block5, 0, 3);
		L.setBlock(world, x + 16, y + 7, z + 10, L.getRandomConcrete(), 0, 3);
		L.setBlock(world, x + 19, y + 7, z + 10, Block6, 0, 3);
		L.setBlock(world, x + 20, y + 7, z + 10, Block25, 0, 3);
		L.setBlock(world, x + 21, y + 7, z + 10, Block6, 0, 3);
		L.setBlock(world, x + 22, y + 7, z + 10, Block6, 0, 3);
		L.setBlock(world, x + 23, y + 7, z + 10, Block6, 0, 3);
		L.setBlock(world, x + 24, y + 7, z + 10, Block6, 0, 3);
		L.setBlock(world, x + 25, y + 7, z + 10, Block6, 0, 3);
		L.setBlock(world, x + 26, y + 7, z + 10, Block6, 0, 3);
		L.setBlock(world, x + 27, y + 7, z + 10, Block6, 0, 3);
		L.setBlock(world, x + 28, y + 7, z + 10, Block6, 0, 3);
		L.setBlock(world, x + 29, y + 7, z + 10, Block6, 0, 3);
		L.setBlock(world, x + 30, y + 7, z + 10, Block6, 0, 3);
		L.setBlock(world, x + 31, y + 7, z + 10, Block6, 0, 3);
		L.setBlock(world, x + 32, y + 7, z + 10, Block6, 0, 3);
		L.setBlock(world, x + 33, y + 7, z + 10, Block6, 0, 3);
		L.setBlock(world, x + 34, y + 7, z + 10, Block6, 0, 3);
		L.setBlock(world, x + 35, y + 7, z + 10, Block6, 0, 3);
		L.setBlock(world, x + 36, y + 7, z + 10, Block18, 0, 3);
		L.setBlock(world, x + 37, y + 7, z + 10, L.getRandomConcrete(), 0, 3);
		L.setBlock(world, x + 5, y + 7, z + 11, Block5, 0, 3);
		L.setBlock(world, x + 11, y + 7, z + 11, Block5, 0, 3);
		L.setBlock(world, x + 16, y + 7, z + 11, L.getRandomConcrete(), 0, 3);
		L.setBlock(world, x + 19, y + 7, z + 11, Block6, 0, 3);
		L.setBlock(world, x + 20, y + 7, z + 11, Block25, 0, 3);
		L.setBlock(world, x + 21, y + 7, z + 11, Block6, 0, 3);
		L.setBlock(world, x + 22, y + 7, z + 11, Block6, 0, 3);
		L.setBlock(world, x + 23, y + 7, z + 11, Block6, 0, 3);
		L.setBlock(world, x + 24, y + 7, z + 11, Block6, 0, 3);
		L.setBlock(world, x + 25, y + 7, z + 11, Block6, 0, 3);
		L.setBlock(world, x + 26, y + 7, z + 11, Block6, 0, 3);
		L.setBlock(world, x + 27, y + 7, z + 11, Block6, 0, 3);
		L.setBlock(world, x + 28, y + 7, z + 11, Block6, 0, 3);
		L.setBlock(world, x + 29, y + 7, z + 11, Block6, 0, 3);
		L.setBlock(world, x + 30, y + 7, z + 11, Block6, 0, 3);
		L.setBlock(world, x + 31, y + 7, z + 11, Block6, 0, 3);
		L.setBlock(world, x + 32, y + 7, z + 11, Block6, 0, 3);
		L.setBlock(world, x + 33, y + 7, z + 11, Block6, 0, 3);
		L.setBlock(world, x + 34, y + 7, z + 11, Block6, 0, 3);
		L.setBlock(world, x + 35, y + 7, z + 11, Block18, 0, 3);
		L.setBlock(world, x + 36, y + 7, z + 11, Block18, 0, 3);
		L.setBlock(world, x + 37, y + 7, z + 11, L.getRandomConcrete(), 0, 3);
		L.setBlock(world, x + 5, y + 7, z + 12, Block5, 0, 3);
		L.setBlock(world, x + 8, y + 7, z + 12, Block25, 0, 3);
		L.setBlock(world, x + 9, y + 7, z + 12, Block25, 0, 3);
		L.setBlock(world, x + 10, y + 7, z + 12, Block25, 0, 3);
		L.setBlock(world, x + 11, y + 7, z + 12, Block25, 0, 3);
		L.setBlock(world, x + 12, y + 7, z + 12, Block25, 0, 3);
		L.setBlock(world, x + 13, y + 7, z + 12, Block25, 0, 3);
		L.setBlock(world, x + 14, y + 7, z + 12, Block25, 0, 3);
		L.setBlock(world, x + 15, y + 7, z + 12, Block25, 0, 3);
		L.setBlock(world, x + 16, y + 7, z + 12, Block25, 0, 3);
		L.setBlock(world, x + 17, y + 7, z + 12, VB.stone_stairs, 2, 3);
		L.setBlock(world, x + 18, y + 7, z + 12, VB.stone_stairs, 2, 3);
		L.setBlock(world, x + 19, y + 7, z + 12, Block6, 0, 3);
		L.setBlock(world, x + 20, y + 7, z + 12, Block25, 0, 3);
		L.setBlock(world, x + 21, y + 7, z + 12, Block6, 0, 3);
		L.setBlock(world, x + 22, y + 7, z + 12, Block6, 0, 3);
		L.setBlock(world, x + 23, y + 7, z + 12, Block6, 0, 3);
		L.setBlock(world, x + 24, y + 7, z + 12, Block6, 0, 3);
		L.setBlock(world, x + 25, y + 7, z + 12, Block6, 0, 3);
		L.setBlock(world, x + 26, y + 7, z + 12, Block6, 0, 3);
		L.setBlock(world, x + 27, y + 7, z + 12, Block6, 0, 3);
		L.setBlock(world, x + 28, y + 7, z + 12, Block6, 0, 3);
		L.setBlock(world, x + 29, y + 7, z + 12, Block6, 0, 3);
		L.setBlock(world, x + 30, y + 7, z + 12, Block6, 0, 3);
		L.setBlock(world, x + 31, y + 7, z + 12, Block6, 0, 3);
		L.setBlock(world, x + 32, y + 7, z + 12, Block6, 0, 3);
		L.setBlock(world, x + 33, y + 7, z + 12, Block18, 0, 3);
		L.setBlock(world, x + 34, y + 7, z + 12, Block18, 0, 3);
		L.setBlock(world, x + 35, y + 7, z + 12, Block18, 0, 3);
		L.setBlock(world, x + 37, y + 7, z + 12, VB.gravel, 0, 3);
		L.setBlock(world, x + 5, y + 7, z + 13, Block5, 0, 3);
		L.setBlock(world, x + 11, y + 7, z + 13, Block5, 0, 3);
		L.setBlock(world, x + 16, y + 7, z + 13, Block25, 0, 3);
		L.setBlock(world, x + 17, y + 7, z + 13, Block6, 0, 3);
		L.setBlock(world, x + 18, y + 7, z + 13, Block6, 0, 3);
		L.setBlock(world, x + 19, y + 7, z + 13, Block6, 0, 3);
		L.setBlock(world, x + 20, y + 7, z + 13, Block25, 0, 3);
		L.setBlock(world, x + 21, y + 7, z + 13, Block6, 0, 3);
		L.setBlock(world, x + 22, y + 7, z + 13, Block6, 0, 3);
		L.setBlock(world, x + 23, y + 7, z + 13, Block6, 0, 3);
		L.setBlock(world, x + 24, y + 7, z + 13, Block6, 0, 3);
		L.setBlock(world, x + 25, y + 7, z + 13, Block6, 0, 3);
		L.setBlock(world, x + 26, y + 7, z + 13, Block6, 0, 3);
		L.setBlock(world, x + 27, y + 7, z + 13, Block6, 0, 3);
		L.setBlock(world, x + 28, y + 7, z + 13, Block6, 0, 3);
		L.setBlock(world, x + 29, y + 7, z + 13, Block6, 0, 3);
		L.setBlock(world, x + 30, y + 7, z + 13, Block6, 0, 3);
		L.setBlock(world, x + 31, y + 7, z + 13, Block6, 0, 3);
		L.setBlock(world, x + 32, y + 7, z + 13, Block6, 0, 3);
		L.setBlock(world, x + 33, y + 7, z + 13, Block18, 0, 3);
		L.setBlock(world, x + 34, y + 7, z + 13, Block18, 0, 3);
		L.setBlock(world, x + 35, y + 7, z + 13, VB.vine, 4, 3);
		L.setBlock(world, x + 5, y + 7, z + 14, Block5, 0, 3);
		L.setBlock(world, x + 6, y + 7, z + 14, Block5, 0, 3);
		L.setBlock(world, x + 10, y + 7, z + 14, Block5, 0, 3);
		L.setBlock(world, x + 11, y + 7, z + 14, Block5, 0, 3);
		L.setBlock(world, x + 16, y + 7, z + 14, Block25, 0, 3);
		L.setBlock(world, x + 17, y + 7, z + 14, Block25, 0, 3);
		L.setBlock(world, x + 18, y + 7, z + 14, Block25, 0, 3);
		L.setBlock(world, x + 19, y + 7, z + 14, Block25, 0, 3);
		L.setBlock(world, x + 20, y + 7, z + 14, Block25, 0, 3);
		L.setBlock(world, x + 21, y + 7, z + 14, Block25, 0, 3);
		L.setBlock(world, x + 22, y + 7, z + 14, Block25, 0, 3);
		L.setBlock(world, x + 23, y + 7, z + 14, Block25, 0, 3);
		L.setBlock(world, x + 24, y + 7, z + 14, Block25, 0, 3);
		L.setBlock(world, x + 25, y + 7, z + 14, Block25, 0, 3);
		L.setBlock(world, x + 26, y + 7, z + 14, Block25, 0, 3);
		L.setBlock(world, x + 27, y + 7, z + 14, Block25, 0, 3);
		L.setBlock(world, x + 28, y + 7, z + 14, Block25, 0, 3);
		L.setBlock(world, x + 29, y + 7, z + 14, Block25, 0, 3);
		L.setBlock(world, x + 30, y + 7, z + 14, Block6, 0, 3);
		L.setBlock(world, x + 31, y + 7, z + 14, Block6, 0, 3);
		L.setBlock(world, x + 32, y + 7, z + 14, Block18, 0, 3);
		L.setBlock(world, x + 33, y + 7, z + 14, Block18, 0, 3);
		L.setBlock(world, x + 34, y + 7, z + 14, Block18, 0, 3);
		L.setBlock(world, x + 6, y + 7, z + 15, Block5, 0, 3);
		L.setBlock(world, x + 7, y + 7, z + 15, Block5, 0, 3);
		L.setBlock(world, x + 8, y + 7, z + 15, Block5, 0, 3);
		L.setBlock(world, x + 9, y + 7, z + 15, Block5, 0, 3);
		L.setBlock(world, x + 10, y + 7, z + 15, Block5, 0, 3);
		L.setBlock(world, x + 16, y + 7, z + 15, L.getRandomConcrete(), 0, 3);
		L.setBlock(world, x + 17, y + 7, z + 15, Block6, 0, 3);
		L.setBlock(world, x + 18, y + 7, z + 15, Block6, 0, 3);
		L.setBlock(world, x + 19, y + 7, z + 15, Block6, 0, 3);
		L.setBlock(world, x + 20, y + 7, z + 15, Block6, 0, 3);
		L.setBlock(world, x + 21, y + 7, z + 15, Block6, 0, 3);
		L.setBlock(world, x + 22, y + 7, z + 15, Block6, 0, 3);
		L.setBlock(world, x + 23, y + 7, z + 15, Block6, 0, 3);
		L.setBlock(world, x + 24, y + 7, z + 15, Block6, 0, 3);
		L.setBlock(world, x + 25, y + 7, z + 15, Block6, 0, 3);
		L.setBlock(world, x + 26, y + 7, z + 15, Block6, 0, 3);
		L.setBlock(world, x + 27, y + 7, z + 15, Block6, 0, 3);
		L.setBlock(world, x + 28, y + 7, z + 15, Block6, 0, 3);
		L.setBlock(world, x + 29, y + 7, z + 15, Block6, 0, 3);
		L.setBlock(world, x + 30, y + 7, z + 15, Block6, 0, 3);
		L.setBlock(world, x + 31, y + 7, z + 15, Block6, 0, 3);
		L.setBlock(world, x + 32, y + 7, z + 15, Block18, 0, 3);
		L.setBlock(world, x + 33, y + 7, z + 15, Block18, 0, 3);
		L.setBlock(world, x + 34, y + 7, z + 15, VB.vine, 2, 3);
		L.setBlock(world, x + 8, y + 7, z + 16, Block5, 0, 3);
		L.setBlock(world, x + 16, y + 7, z + 16, L.getRandomConcrete(), 0, 3);
		L.setBlock(world, x + 17, y + 7, z + 16, Block6, 0, 3);
		L.setBlock(world, x + 18, y + 7, z + 16, Block6, 0, 3);
		L.setBlock(world, x + 19, y + 7, z + 16, Block6, 0, 3);
		L.setBlock(world, x + 20, y + 7, z + 16, Block6, 0, 3);
		L.setBlock(world, x + 21, y + 7, z + 16, Block6, 0, 3);
		L.setBlock(world, x + 22, y + 7, z + 16, Block6, 0, 3);
		L.setBlock(world, x + 23, y + 7, z + 16, Block6, 0, 3);
		L.setBlock(world, x + 24, y + 7, z + 16, Block6, 0, 3);
		L.setBlock(world, x + 25, y + 7, z + 16, Block6, 0, 3);
		L.setBlock(world, x + 26, y + 7, z + 16, Block6, 0, 3);
		L.setBlock(world, x + 27, y + 7, z + 16, Block6, 0, 3);
		L.setBlock(world, x + 28, y + 7, z + 16, Block6, 0, 3);
		L.setBlock(world, x + 29, y + 7, z + 16, Block6, 0, 3);
		L.setBlock(world, x + 30, y + 7, z + 16, Block6, 0, 3);
		L.setBlock(world, x + 31, y + 7, z + 16, Block18, 0, 3);
		L.setBlock(world, x + 32, y + 7, z + 16, Block18, 0, 3);
		L.setBlock(world, x + 33, y + 7, z + 16, Block18, 0, 3);
		L.setBlock(world, x + 34, y + 7, z + 16, VB.vine, 2, 3);
		L.setBlock(world, x + 8, y + 7, z + 17, Block5, 0, 3);
		L.setBlock(world, x + 16, y + 7, z + 17, L.getRandomConcrete(), 0, 3);
		L.setBlock(world, x + 17, y + 7, z + 17, Block6, 0, 3);
		L.setBlock(world, x + 18, y + 7, z + 17, Block6, 0, 3);
		L.setBlock(world, x + 19, y + 7, z + 17, Block6, 0, 3);
		L.setBlock(world, x + 20, y + 7, z + 17, Block6, 0, 3);
		L.setBlock(world, x + 21, y + 7, z + 17, Block6, 0, 3);
		L.setBlock(world, x + 22, y + 7, z + 17, Block6, 0, 3);
		L.setBlock(world, x + 23, y + 7, z + 17, Block6, 0, 3);
		L.setBlock(world, x + 24, y + 7, z + 17, Block6, 0, 3);
		L.setBlock(world, x + 25, y + 7, z + 17, Block6, 0, 3);
		L.setBlock(world, x + 26, y + 7, z + 17, Block6, 0, 3);
		L.setBlock(world, x + 27, y + 7, z + 17, Block6, 0, 3);
		L.setBlock(world, x + 28, y + 7, z + 17, Block6, 0, 3);
		L.setBlock(world, x + 29, y + 7, z + 17, Block6, 0, 3);
		L.setBlock(world, x + 30, y + 7, z + 17, Block6, 0, 3);
		L.setBlock(world, x + 31, y + 7, z + 17, Block18, 0, 3);
		L.setBlock(world, x + 32, y + 7, z + 17, Block18, 0, 3);
		L.setBlock(world, x + 33, y + 7, z + 17, VB.vine, 2, 3);
		L.setBlock(world, x + 8, y + 7, z + 18, Block5, 0, 3);
		L.setBlock(world, x + 16, y + 7, z + 18, L.getRandomConcrete(), 0, 3);
		L.setBlock(world, x + 17, y + 7, z + 18, L.getRandomConcrete(), 0, 3);
		L.setBlock(world, x + 18, y + 7, z + 18, L.getRandomConcrete(), 0, 3);
		L.setBlock(world, x + 19, y + 7, z + 18, L.getRandomConcrete(), 0, 3);
		L.setBlock(world, x + 20, y + 7, z + 18, L.getRandomConcrete(), 0, 3);
		L.setBlock(world, x + 21, y + 7, z + 18, L.getRandomConcrete(), 0, 3);
		L.setBlock(world, x + 22, y + 7, z + 18, L.getRandomConcrete(), 0, 3);
		L.setBlock(world, x + 23, y + 7, z + 18, L.getRandomConcrete(), 0, 3);
		L.setBlock(world, x + 24, y + 7, z + 18, L.getRandomConcrete(), 0, 3);
		L.setBlock(world, x + 25, y + 7, z + 18, L.getRandomConcrete(), 0, 3);
		L.setBlock(world, x + 26, y + 7, z + 18, L.getRandomConcrete(), 0, 3);
		L.setBlock(world, x + 27, y + 7, z + 18, L.getRandomConcrete(), 0, 3);
		L.setBlock(world, x + 28, y + 7, z + 18, L.getRandomConcrete(), 0, 3);
		L.setBlock(world, x + 29, y + 7, z + 18, L.getRandomConcrete(), 0, 3);
		L.setBlock(world, x + 30, y + 7, z + 18, L.getRandomConcrete(), 0, 3);
		L.setBlock(world, x + 31, y + 7, z + 18, L.getRandomConcrete(), 0, 3);
		L.setBlock(world, x + 32, y + 7, z + 18, L.getRandomConcrete(), 0, 3);
		L.setBlock(world, x + 33, y + 7, z + 18, L.getRandomConcrete(), 0, 3);
		L.setBlock(world, x + 8, y + 7, z + 19, Block5, 0, 3);
		L.setBlock(world, x + 8, y + 7, z + 20, Block5, 0, 3);
		L.setBlock(world, x + 6, y + 7, z + 21, Block15, 0, 3);
		L.setBlock(world, x + 7, y + 7, z + 21, Block15, 0, 3);
		L.setBlock(world, x + 8, y + 7, z + 21, Block15, 0, 3);
		L.setBlock(world, x + 9, y + 7, z + 21, Block15, 0, 3);
		L.setBlock(world, x + 10, y + 7, z + 21, Block15, 0, 3);
		L.setBlock(world, x + 5, y + 7, z + 22, Block15, 0, 3);
		L.setBlock(world, x + 6, y + 7, z + 22, Block7, 0, 3);
		L.setBlock(world, x + 7, y + 7, z + 22, Block7, 0, 3);
		L.setBlock(world, x + 8, y + 7, z + 22, Block7, 0, 3);
		L.setBlock(world, x + 9, y + 7, z + 22, Block7, 0, 3);
		L.setBlock(world, x + 10, y + 7, z + 22, Block7, 0, 3);
		L.setBlock(world, x + 11, y + 7, z + 22, Block15, 0, 3);
		L.setBlock(world, x + 4, y + 7, z + 23, Block15, 0, 3);
		L.setBlock(world, x + 5, y + 7, z + 23, Block7, 0, 3);
		L.setBlock(world, x + 7, y + 7, z + 23, MB.fence_metal, 0, 3);
		L.setBlock(world, x + 8, y + 7, z + 23, Block7, 0, 3);
		L.setBlock(world, x + 11, y + 7, z + 23, Block7, 0, 3);
		L.setBlock(world, x + 12, y + 7, z + 23, Block15, 0, 3);
		L.setBlock(world, x + 4, y + 7, z + 24, Block15, 0, 3);
		L.setBlock(world, x + 5, y + 7, z + 24, Block7, 0, 3);
		L.setBlock(world, x + 8, y + 7, z + 24, Block7, 0, 3);
		L.setBlock(world, x + 9, y + 7, z + 24, MB.fence_metal, 0, 3);
		L.setBlock(world, x + 11, y + 7, z + 24, Block7, 0, 3);
		L.setBlock(world, x + 12, y + 7, z + 24, Block15, 0, 3);
		L.setBlock(world, x + 4, y + 7, z + 25, Block15, 0, 3);
		L.setBlock(world, x + 5, y + 7, z + 25, Block7, 0, 3);
		L.setBlock(world, x + 7, y + 7, z + 25, MB.fence_metal, 0, 3);
		L.setBlock(world, x + 8, y + 7, z + 25, Block7, 0, 3);
		L.setBlock(world, x + 9, y + 7, z + 25, MB.fence_metal, 0, 3);
		L.setBlock(world, x + 11, y + 7, z + 25, Block7, 0, 3);
		L.setBlock(world, x + 12, y + 7, z + 25, Block15, 0, 3);
		L.setBlock(world, x + 4, y + 7, z + 26, Block15, 0, 3);
		L.setBlock(world, x + 5, y + 7, z + 26, Block7, 0, 3);
		L.setBlock(world, x + 8, y + 7, z + 26, Block7, 0, 3);
		L.setBlock(world, x + 11, y + 7, z + 26, Block7, 0, 3);
		L.setBlock(world, x + 12, y + 7, z + 26, Block15, 0, 3);
		L.setBlock(world, x + 4, y + 7, z + 27, Block15, 0, 3);
		L.setBlock(world, x + 5, y + 7, z + 27, Block7, 0, 3);
		L.setBlock(world, x + 7, y + 7, z + 27, MB.fence_metal, 0, 3);
		L.setBlock(world, x + 8, y + 7, z + 27, Block7, 0, 3);
		L.setBlock(world, x + 9, y + 7, z + 27, MB.fence_metal, 0, 3);
		L.setBlock(world, x + 11, y + 7, z + 27, Block7, 0, 3);
		L.setBlock(world, x + 12, y + 7, z + 27, Block15, 0, 3);
		L.setBlock(world, x + 5, y + 7, z + 28, Block15, 0, 3);
		L.setBlock(world, x + 6, y + 7, z + 28, Block7, 0, 3);
		L.setBlock(world, x + 7, y + 7, z + 28, Block7, 0, 3);
		L.setBlock(world, x + 8, y + 7, z + 28, Block7, 0, 3);
		L.setBlock(world, x + 9, y + 7, z + 28, Block7, 0, 3);
		L.setBlock(world, x + 10, y + 7, z + 28, Block7, 0, 3);
		L.setBlock(world, x + 11, y + 7, z + 28, Block15, 0, 3);
		L.setBlock(world, x + 6, y + 7, z + 29, Block15, 0, 3);
		L.setBlock(world, x + 7, y + 7, z + 29, Block15, 0, 3);
		L.setBlock(world, x + 8, y + 7, z + 29, Block15, 0, 3);
		L.setBlock(world, x + 9, y + 7, z + 29, Block15, 0, 3);
		L.setBlock(world, x + 10, y + 7, z + 29, Block15, 0, 3);
		L.setBlock(world, x + 16, y + 8, z + 6, L.getRandomConcrete(), 0, 3);
		L.setBlock(world, x + 17, y + 8, z + 6, L.getRandomConcrete(), 0, 3);
		L.setBlock(world, x + 18, y + 8, z + 6, L.getRandomConcrete(), 0, 3);
		L.setBlock(world, x + 19, y + 8, z + 6, L.getRandomConcrete(), 0, 3);
		L.setBlock(world, x + 20, y + 8, z + 6, L.getRandomConcrete(), 0, 3);
		L.setBlock(world, x + 21, y + 8, z + 6, L.getRandomConcrete(), 0, 3);
		L.setBlock(world, x + 23, y + 8, z + 6, L.getRandomConcrete(), 0, 3);
		L.setBlock(world, x + 25, y + 8, z + 6, L.getRandomConcrete(), 0, 3);
		L.setBlock(world, x + 26, y + 8, z + 6, L.getRandomConcrete(), 0, 3);
		L.setBlock(world, x + 27, y + 8, z + 6, L.getRandomConcrete(), 0, 3);
		L.setBlock(world, x + 28, y + 8, z + 6, L.getRandomConcrete(), 0, 3);
		L.setBlock(world, x + 29, y + 8, z + 6, L.getRandomConcrete(), 0, 3);
		L.setBlock(world, x + 30, y + 8, z + 6, L.getRandomConcrete(), 0, 3);
		L.setBlock(world, x + 31, y + 8, z + 6, L.getRandomConcrete(), 0, 3);
		L.setBlock(world, x + 32, y + 8, z + 6, L.getRandomConcrete(), 0, 3);
		L.setBlock(world, x + 33, y + 8, z + 6, L.getRandomConcrete(), 0, 3);
		L.setBlock(world, x + 34, y + 8, z + 6, L.getRandomConcrete(), 0, 3);
		L.setBlock(world, x + 35, y + 8, z + 6, L.getRandomConcrete(), 0, 3);
		L.setBlock(world, x + 36, y + 8, z + 6, L.getRandomConcrete(), 0, 3);
		L.setBlock(world, x + 16, y + 8, z + 7, L.getRandomConcrete(), 0, 3);
		L.setBlock(world, x + 19, y + 8, z + 7, MB.fence_metal, 0, 3);
		L.setBlock(world, x + 16, y + 8, z + 8, L.getRandomConcrete(), 0, 3);
		L.setBlock(world, x + 19, y + 8, z + 8, MB.fence_metal, 0, 3);
		L.setBlock(world, x + 37, y + 8, z + 8, L.getRandomConcrete(), 0, 3);
		L.setBlock(world, x + 6, y + 8, z + 9, Block5, 0, 3);
		L.setBlock(world, x + 7, y + 8, z + 9, Block5, 0, 3);
		L.setBlock(world, x + 8, y + 8, z + 9, Block5, 0, 3);
		L.setBlock(world, x + 9, y + 8, z + 9, Block5, 0, 3);
		L.setBlock(world, x + 10, y + 8, z + 9, Block5, 0, 3);
		L.setBlock(world, x + 16, y + 8, z + 9, L.getRandomConcrete(), 0, 3);
		L.setBlock(world, x + 19, y + 8, z + 9, MB.fence_metal, 0, 3);
		L.setBlock(world, x + 23, y + 8, z + 9, Block25, 0, 3);
		L.setBlock(world, x + 24, y + 8, z + 9, Block25, 0, 3);
		L.setBlock(world, x + 25, y + 8, z + 9, Block28, 0, 3);
		L.setBlock(world, x + 26, y + 8, z + 9, Block25, 0, 3);
		L.setBlock(world, x + 27, y + 8, z + 9, Block25, 0, 3);
		L.setBlock(world, x + 28, y + 8, z + 9, Block28, 0, 3);
		L.setBlock(world, x + 29, y + 8, z + 9, Block25, 0, 3);
		L.setBlock(world, x + 30, y + 8, z + 9, Block25, 0, 3);
		L.setBlock(world, x + 31, y + 8, z + 9, Block29, 3, 3);
		L.setBlock(world, x + 37, y + 8, z + 9, L.getRandomConcrete(), 0, 3);
		L.setBlock(world, x + 5, y + 8, z + 10, Block5, 0, 3);
		L.setBlock(world, x + 6, y + 8, z + 10, Block5, 0, 3);
		L.setBlock(world, x + 7, y + 8, z + 10, Block11, 0, 3);
		L.setBlock(world, x + 8, y + 8, z + 10, Block5, 0, 3);
		L.setBlock(world, x + 9, y + 8, z + 10, Block11, 0, 3);
		L.setBlock(world, x + 10, y + 8, z + 10, Block5, 0, 3);
		L.setBlock(world, x + 11, y + 8, z + 10, Block5, 0, 3);
		L.setBlock(world, x + 16, y + 8, z + 10, L.getRandomConcrete(), 0, 3);
		L.setBlock(world, x + 37, y + 8, z + 10, L.getRandomConcrete(), 0, 3);
		L.setBlock(world, x + 5, y + 8, z + 11, Block5, 0, 3);
		L.setBlock(world, x + 6, y + 8, z + 11, Block11, 0, 3);
		L.setBlock(world, x + 10, y + 8, z + 11, Block11, 0, 3);
		L.setBlock(world, x + 11, y + 8, z + 11, Block5, 0, 3);
		L.setBlock(world, x + 12, y + 8, z + 11, MB.fence_metal, 0, 3);
		L.setBlock(world, x + 14, y + 8, z + 11, MB.fence_metal, 0, 3);
		L.setBlock(world, x + 15, y + 8, z + 11, MB.fence_metal, 0, 3);
		L.setBlock(world, x + 16, y + 8, z + 11, L.getRandomConcrete(), 0, 3);
		L.setBlock(world, x + 19, y + 8, z + 11, MB.fence_metal, 0, 3);
		L.setBlock(world, x + 37, y + 8, z + 11, VB.gravel, 0, 3);
		L.setBlock(world, x + 5, y + 8, z + 12, Block5, 0, 3);
		L.setBlock(world, x + 6, y + 8, z + 12, Block5, 0, 3);
		L.setBlock(world, x + 8, y + 8, z + 12, Block25, 0, 3);
		L.setBlock(world, x + 10, y + 8, z + 12, Block5, 0, 3);
		L.setBlock(world, x + 11, y + 8, z + 12, Block5, 0, 3);
		L.setBlock(world, x + 16, y + 8, z + 12, L.getRandomConcrete(), 0, 3);
		L.setBlock(world, x + 19, y + 8, z + 12, MB.fence_metal, 0, 3);
		L.setBlock(world, x + 5, y + 8, z + 13, Block5, 0, 3);
		L.setBlock(world, x + 6, y + 8, z + 13, Block11, 0, 3);
		L.setBlock(world, x + 10, y + 8, z + 13, Block11, 0, 3);
		L.setBlock(world, x + 11, y + 8, z + 13, Block5, 0, 3);
		L.setBlock(world, x + 12, y + 8, z + 13, MB.fence_metal, 0, 3);
		L.setBlock(world, x + 13, y + 8, z + 13, MB.fence_metal, 0, 3);
		L.setBlock(world, x + 14, y + 8, z + 13, MB.fence_metal, 0, 3);
		L.setBlock(world, x + 16, y + 8, z + 13, L.getRandomConcrete(), 0, 3);
		L.setBlock(world, x + 33, y + 8, z + 13, Block13, 5, 3);
		L.setBlock(world, x + 5, y + 8, z + 14, Block5, 0, 3);
		L.setBlock(world, x + 6, y + 8, z + 14, Block5, 0, 3);
		L.setBlock(world, x + 7, y + 8, z + 14, Block11, 0, 3);
		L.setBlock(world, x + 8, y + 8, z + 14, Block5, 0, 3);
		L.setBlock(world, x + 9, y + 8, z + 14, Block11, 0, 3);
		L.setBlock(world, x + 10, y + 8, z + 14, Block5, 0, 3);
		L.setBlock(world, x + 11, y + 8, z + 14, Block5, 0, 3);
		L.setBlock(world, x + 16, y + 8, z + 14, L.getRandomConcrete(), 0, 3);
		L.setBlock(world, x + 22, y + 8, z + 14, Block5, 0, 3);
		L.setBlock(world, x + 23, y + 8, z + 14, Block25, 0, 3);
		L.setBlock(world, x + 27, y + 8, z + 14, Block5, 0, 3);
		L.setBlock(world, x + 28, y + 8, z + 14, Block25, 0, 3);
		L.setBlock(world, x + 29, y + 8, z + 14, Block5, 0, 3);
		L.setBlock(world, x + 32, y + 8, z + 14, Block8, 5, 3);
		L.setBlock(world, x + 6, y + 8, z + 15, Block5, 0, 3);
		L.setBlock(world, x + 7, y + 8, z + 15, Block5, 0, 3);
		L.setBlock(world, x + 8, y + 8, z + 15, Block5, 0, 3);
		L.setBlock(world, x + 9, y + 8, z + 15, Block5, 0, 3);
		L.setBlock(world, x + 10, y + 8, z + 15, Block5, 0, 3);
		L.setBlock(world, x + 16, y + 8, z + 15, L.getRandomConcrete(), 0, 3);
		L.setBlock(world, x + 22, y + 8, z + 15, Block5, 0, 3);
		L.setBlock(world, x + 23, y + 8, z + 15, Block5, 0, 3);
		L.setBlock(world, x + 24, y + 8, z + 15, Block5, 0, 3);
		L.setBlock(world, x + 27, y + 8, z + 15, Block5, 0, 3);
		L.setBlock(world, x + 28, y + 8, z + 15, Block5, 0, 3);
		L.setBlock(world, x + 29, y + 8, z + 15, Block5, 0, 3);
		L.setBlock(world, x + 30, y + 8, z + 15, Block8, 2, 3);
		L.setBlock(world, x + 31, y + 8, z + 15, Block8, 3, 3);
		L.setBlock(world, x + 7, y + 8, z + 16, MB.fence_metal, 0, 3);
		L.setBlock(world, x + 9, y + 8, z + 16, MB.fence_metal, 0, 3);
		L.setBlock(world, x + 16, y + 8, z + 16, L.getRandomConcrete(), 0, 3);
		L.setBlock(world, x + 22, y + 8, z + 16, Block5, 0, 3);
		L.setBlock(world, x + 23, y + 8, z + 16, Block5, 0, 3);
		L.setBlock(world, x + 24, y + 8, z + 16, Block5, 0, 3);
		L.setBlock(world, x + 27, y + 8, z + 16, Block5, 0, 3);
		L.setBlock(world, x + 28, y + 8, z + 16, Block5, 0, 3);
		L.setBlock(world, x + 29, y + 8, z + 16, Block5, 0, 3);
		L.setBlock(world, x + 7, y + 8, z + 17, MB.fence_metal, 0, 3);
		L.setBlock(world, x + 16, y + 8, z + 17, L.getRandomConcrete(), 0, 3);
		L.setBlock(world, x + 7, y + 8, z + 18, MB.fence_metal, 0, 3);
		L.setBlock(world, x + 9, y + 8, z + 18, MB.fence_metal, 0, 3);
		L.setBlock(world, x + 16, y + 8, z + 18, L.getRandomConcrete(), 0, 3);
		L.setBlock(world, x + 17, y + 8, z + 18, L.getRandomConcrete(), 0, 3);
		L.setBlock(world, x + 18, y + 8, z + 18, L.getRandomConcrete(), 0, 3);
		L.setBlock(world, x + 19, y + 8, z + 18, L.getRandomConcrete(), 0, 3);
		L.setBlock(world, x + 20, y + 8, z + 18, L.getRandomConcrete(), 0, 3);
		L.setBlock(world, x + 21, y + 8, z + 18, L.getRandomConcrete(), 0, 3);
		L.setBlock(world, x + 22, y + 8, z + 18, L.getRandomConcrete(), 0, 3);
		L.setBlock(world, x + 23, y + 8, z + 18, L.getRandomConcrete(), 0, 3);
		L.setBlock(world, x + 24, y + 8, z + 18, L.getRandomConcrete(), 0, 3);
		L.setBlock(world, x + 25, y + 8, z + 18, L.getRandomConcrete(), 0, 3);
		L.setBlock(world, x + 26, y + 8, z + 18, L.getRandomConcrete(), 0, 3);
		L.setBlock(world, x + 27, y + 8, z + 18, L.getRandomConcrete(), 0, 3);
		L.setBlock(world, x + 28, y + 8, z + 18, L.getRandomConcrete(), 0, 3);
		L.setBlock(world, x + 29, y + 8, z + 18, L.getRandomConcrete(), 0, 3);
		L.setBlock(world, x + 30, y + 8, z + 18, L.getRandomConcrete(), 0, 3);
		L.setBlock(world, x + 31, y + 8, z + 18, L.getRandomConcrete(), 0, 3);
		L.setBlock(world, x + 32, y + 8, z + 18, L.getRandomConcrete(), 0, 3);
		L.setBlock(world, x + 33, y + 8, z + 18, VB.gravel, 0, 3);
		L.setBlock(world, x + 9, y + 8, z + 19, MB.fence_metal, 0, 3);
		L.setBlock(world, x + 7, y + 8, z + 21, MB.fence_metal, 0, 3);
		L.setBlock(world, x + 9, y + 8, z + 21, MB.fence_metal, 0, 3);
		L.setBlock(world, x + 6, y + 8, z + 22, Block15, 0, 3);
		L.setBlock(world, x + 7, y + 8, z + 22, Block15, 0, 3);
		L.setBlock(world, x + 8, y + 8, z + 22, VB.iron_door, 1, 3);
        L.placeDoorBlock(world, x + 8, y + 8, z + 22, 1, VB.iron_door);
		L.setBlock(world, x + 9, y + 8, z + 22, Block15, 0, 3);
		L.setBlock(world, x + 10, y + 8, z + 22, Block15, 0, 3);
		L.setBlock(world, x + 5, y + 8, z + 23, Block15, 0, 3);
		L.setBlock(world, x + 7, y + 8, z + 23, MB.fence_metal, 0, 3);
		L.setBlock(world, x + 11, y + 8, z + 23, Block15, 0, 3);
		L.setBlock(world, x + 5, y + 8, z + 24, Block15, 0, 3);
		L.setBlock(world, x + 9, y + 8, z + 24, MB.fence_metal, 0, 3);
		L.setBlock(world, x + 11, y + 8, z + 24, Block15, 0, 3);
		L.setBlock(world, x + 5, y + 8, z + 25, Block15, 0, 3);
		L.setBlock(world, x + 9, y + 8, z + 25, MB.fence_metal, 0, 3);
		L.setBlock(world, x + 11, y + 8, z + 25, Block15, 0, 3);
		L.setBlock(world, x + 5, y + 8, z + 26, Block15, 0, 3);
		L.setBlock(world, x + 11, y + 8, z + 26, Block15, 0, 3);
		L.setBlock(world, x + 5, y + 8, z + 27, Block15, 0, 3);
		L.setBlock(world, x + 7, y + 8, z + 27, MB.fence_metal, 0, 3);
		L.setBlock(world, x + 9, y + 8, z + 27, MB.fence_metal, 0, 3);
		L.setBlock(world, x + 11, y + 8, z + 27, Block15, 0, 3);
		L.setBlock(world, x + 6, y + 8, z + 28, Block15, 0, 3);
		L.setBlock(world, x + 7, y + 8, z + 28, Block15, 0, 3);
		L.setBlock(world, x + 8, y + 8, z + 28, Block15, 0, 3);
		L.setBlock(world, x + 9, y + 8, z + 28, Block15, 0, 3);
		L.setBlock(world, x + 10, y + 8, z + 28, Block15, 0, 3);
		L.setBlock(world, x + 7, y + 9, z + 10, Block11, 0, 3);
		L.setBlock(world, x + 8, y + 9, z + 10, Block5, 0, 3);
		L.setBlock(world, x + 9, y + 9, z + 10, Block11, 0, 3);
		L.setBlock(world, x + 6, y + 9, z + 11, Block11, 0, 3);
		L.setBlock(world, x + 7, y + 9, z + 11, Block11, 0, 3);
		L.setBlock(world, x + 8, y + 9, z + 11, Block5, 0, 3);
		L.setBlock(world, x + 9, y + 9, z + 11, Block11, 0, 3);
		L.setBlock(world, x + 10, y + 9, z + 11, Block11, 0, 3);
		L.setBlock(world, x + 6, y + 9, z + 12, Block5, 0, 3);
		L.setBlock(world, x + 7, y + 9, z + 12, Block5, 0, 3);
		L.setBlock(world, x + 8, y + 9, z + 12, Block5, 0, 3);
		L.setBlock(world, x + 9, y + 9, z + 12, Block5, 0, 3);
		L.setBlock(world, x + 10, y + 9, z + 12, Block5, 0, 3);
		L.setBlock(world, x + 6, y + 9, z + 13, Block11, 0, 3);
		L.setBlock(world, x + 7, y + 9, z + 13, Block11, 0, 3);
		L.setBlock(world, x + 8, y + 9, z + 13, Block5, 0, 3);
		L.setBlock(world, x + 9, y + 9, z + 13, Block11, 0, 3);
		L.setBlock(world, x + 10, y + 9, z + 13, Block11, 0, 3);
		L.setBlock(world, x + 7, y + 9, z + 14, Block11, 0, 3);

		generate_r01(world, rand, x, y, z);
		return true;

	}
	public boolean generate_r01(LevelAccessor world, Random rand, int x, int y, int z)
	{

		L.setBlock(world, x + 8, y + 9, z + 14, Block5, 0, 3);
		L.setBlock(world, x + 9, y + 9, z + 14, Block11, 0, 3);
		L.setBlock(world, x + 23, y + 9, z + 15, Block5, 0, 3);
		L.setBlock(world, x + 28, y + 9, z + 15, Block5, 0, 3);
		L.setBlock(world, x + 29, y + 9, z + 15, Block8, 5, 3);
		L.setBlock(world, x + 6, y + 9, z + 22, Block15, 0, 3);
		L.setBlock(world, x + 7, y + 9, z + 22, Block15, 0, 3);
		//L.setBlock(world, x + 8, y + 9, z + 22, VB.iron_door, 8, 3);
		L.setBlock(world, x + 9, y + 9, z + 22, Block15, 0, 3);
		L.setBlock(world, x + 10, y + 9, z + 22, Block15, 0, 3);
		L.setBlock(world, x + 5, y + 9, z + 23, Block15, 0, 3);
		L.setBlock(world, x + 11, y + 9, z + 23, Block15, 0, 3);
		L.setBlock(world, x + 5, y + 9, z + 24, Block15, 0, 3);
		L.setBlock(world, x + 11, y + 9, z + 24, Block15, 0, 3);
		L.setBlock(world, x + 5, y + 9, z + 25, Block15, 0, 3);
		L.setBlock(world, x + 11, y + 9, z + 25, Block15, 0, 3);
		L.setBlock(world, x + 5, y + 9, z + 26, Block15, 0, 3);
		L.setBlock(world, x + 11, y + 9, z + 26, Block15, 0, 3);
		L.setBlock(world, x + 5, y + 9, z + 27, Block15, 0, 3);
		L.setBlock(world, x + 11, y + 9, z + 27, Block15, 0, 3);
		L.setBlock(world, x + 6, y + 9, z + 28, Block15, 0, 3);
		L.setBlock(world, x + 7, y + 9, z + 28, Block15, 0, 3);
		L.setBlock(world, x + 8, y + 9, z + 28, Block15, 0, 3);
		L.setBlock(world, x + 9, y + 9, z + 28, Block15, 0, 3);
		L.setBlock(world, x + 10, y + 9, z + 28, Block15, 0, 3);
		L.setBlock(world, x + 7, y + 10, z + 11, Block11, 0, 3);
		L.setBlock(world, x + 8, y + 10, z + 11, Block5, 0, 3);
		L.setBlock(world, x + 9, y + 10, z + 11, Block11, 0, 3);
		L.setBlock(world, x + 7, y + 10, z + 12, Block5, 0, 3);
		L.setBlock(world, x + 8, y + 10, z + 12, Block5, 0, 3);
		L.setBlock(world, x + 9, y + 10, z + 12, Block5, 0, 3);
		L.setBlock(world, x + 7, y + 10, z + 13, Block11, 0, 3);
		L.setBlock(world, x + 8, y + 10, z + 13, Block5, 0, 3);
		L.setBlock(world, x + 9, y + 10, z + 13, Block11, 0, 3);
		L.setBlock(world, x + 23, y + 10, z + 15, Block8, 5, 3);
		L.setBlock(world, x + 28, y + 10, z + 15, Block8, 5, 3);
		L.setBlock(world, x + 6, y + 10, z + 22, Block15, 0, 3);
		L.setBlock(world, x + 7, y + 10, z + 22, Block15, 0, 3);
		L.setBlock(world, x + 8, y + 10, z + 22, Block15, 0, 3);
		L.setBlock(world, x + 9, y + 10, z + 22, Block15, 0, 3);
		L.setBlock(world, x + 10, y + 10, z + 22, Block15, 0, 3);
		L.setBlock(world, x + 5, y + 10, z + 23, Block15, 0, 3);
		L.setBlock(world, x + 11, y + 10, z + 23, Block15, 0, 3);
		L.setBlock(world, x + 5, y + 10, z + 24, Block15, 0, 3);
		L.setBlock(world, x + 11, y + 10, z + 24, Block15, 0, 3);
		L.setBlock(world, x + 5, y + 10, z + 25, Block15, 0, 3);
		L.setBlock(world, x + 11, y + 10, z + 25, Block15, 0, 3);
		L.setBlock(world, x + 5, y + 10, z + 26, Block15, 0, 3);
		L.setBlock(world, x + 11, y + 10, z + 26, Block15, 0, 3);
		L.setBlock(world, x + 5, y + 10, z + 27, Block15, 0, 3);
		L.setBlock(world, x + 11, y + 10, z + 27, Block15, 0, 3);
		L.setBlock(world, x + 6, y + 10, z + 28, Block15, 0, 3);
		L.setBlock(world, x + 7, y + 10, z + 28, Block15, 0, 3);
		L.setBlock(world, x + 8, y + 10, z + 28, Block15, 0, 3);
		L.setBlock(world, x + 9, y + 10, z + 28, Block15, 0, 3);
		L.setBlock(world, x + 10, y + 10, z + 28, Block15, 0, 3);
		L.setBlock(world, x + 8, y + 11, z + 12, Block5, 0, 3);
		L.setBlock(world, x + 23, y + 11, z + 15, Block8, 5, 3);
		L.setBlock(world, x + 28, y + 11, z + 15, Block8, 5, 3);
		L.setBlock(world, x + 6, y + 11, z + 21, Block15, 0, 3);
		L.setBlock(world, x + 7, y + 11, z + 21, Block15, 0, 3);
		L.setBlock(world, x + 8, y + 11, z + 21, Block15, 0, 3);
		L.setBlock(world, x + 9, y + 11, z + 21, Block15, 0, 3);
		L.setBlock(world, x + 10, y + 11, z + 21, Block15, 0, 3);
		L.setBlock(world, x + 5, y + 11, z + 22, Block15, 0, 3);
